Workbook

Sheet БИПЦ_НДС
A1: Совпадение ключей названия | B1: Новое название | C1: Старое основное название | D1: Итог | E1: Базовая ставка | F1: Примечания
A2: =EXACT(B2,C2) -> TRUE | B2: Говядина (кроме бескостного мяса), кг | C2: Говядина (кроме бескостного мяса), кг | D2: 10 | E2: =IF(D2=20,1,0) -> 0 | F2: https://base.garant.ru/12138471/#block_1000 | G2: https://normativ.kontur.ru/document?moduleId=1&documentId=422375&ysclid=l59k44nnc9669497702&promocode=0957&utm_source=yandex&utm_medium=organic&utm_campaign=content-link-buhonline&utm_content=tag-nds&utm_term=forum729121&utm_referrer=https%3A%2F%2Fyandex.ru#h2259
A3: =EXACT(B3,C3) -> TRUE | B3: Говядина бескостная, кг | C3: Говядина бескостная, кг | D3: 10 | E3: =IF(D3=20,1,0) -> 0
A4: =EXACT(B4,C4) -> TRUE | B4: Свинина (кроме бескостного мяса), кг | C4: Свинина (кроме бескостного мяса), кг | D4: 10 | E4: =IF(D4=20,1,0) -> 0
A5: =EXACT(B5,C5) -> TRUE | B5: Свинина бескостная, кг | C5: Свинина бескостная, кг | D5: 10 | E5: =IF(D5=20,1,0) -> 0
A6: =EXACT(B6,C6) -> TRUE | B6: Баранина (кроме бескостного мяса), кг | C6: Баранина (кроме бескостного мяса), кг | D6: 10 | E6: =IF(D6=20,1,0) -> 0
A7: =EXACT(B7,C7) -> TRUE | B7: Куры охлажденные и мороженые, кг | C7: Куры охлажденные и мороженые, кг | D7: 10 | E7: =IF(D7=20,1,0) -> 0
A8: =EXACT(B8,C8) -> TRUE | B8: Окорочка куриные, кг | C8: Окорочка куриные, кг | D8: 10 | E8: =IF(D8=20,1,0) -> 0
A9: =EXACT(B9,C9) -> TRUE | B9: Мясо индейки, кг | C9: Мясо индейки, кг | D9: 10 | E9: =IF(D9=20,1,0) -> 0
A10: =EXACT(B10,C10) -> TRUE | B10: Печень говяжья, свиная, кг | C10: Печень говяжья, свиная, кг | D10: 10 | E10: =IF(D10=20,1,0) -> 0
A11: =EXACT(B11,C11) -> TRUE | B11: Фарш мясной, кг | C11: Фарш мясной, кг | D11: 10 | E11: =IF(D11=20,1,0) -> 0
A12: =EXACT(B12,C12) -> TRUE | B12: Пельмени, манты, равиоли, кг | C12: Пельмени, манты, равиоли, кг | D12: 10 | E12: =IF(D12=20,1,0) -> 0
A13: =EXACT(B13,C13) -> TRUE | B13: Сосиски, сардельки, кг | C13: Сосиски, сардельки, кг | D13: 10 | E13: =IF(D13=20,1,0) -> 0
A14: =EXACT(B14,C14) -> TRUE | B14: Колбаса полукопченая и варено-копченая, кг | C14: Колбаса полукопченая и варено-копченая, кг | D14: 10 | E14: =IF(D14=20,1,0) -> 0
... A28: =EXACT(B28,C28) -> TRUE | B28: Филе рыбное, кг | C28: Филе рыбное, кг | D28: 10 | E28: =IF(D28=20,1,0) -> 0
A29: =EXACT(B29,C29) -> FALSE | B29: Креветки мороженые, неразделанные, кг | C29: Креветки мороженые неразделанные, кг | D29: 10 | E29: =IF(D29=20,1,0) -> 0 | F29: https://base.garant.ru/12138471/#block_1000
A30: =EXACT(B30,C30) -> FALSE | B30: Кальмары мороженые, кг | C30: Кальмары мороженые,кг | D30: 10 | E30: =IF(D30=20,1,0) -> 0 | F30: https://enterfin.ru/q_a_31418/
A31: =EXACT(B31,C31) -> TRUE | B31: Сельдь соленая, кг | C31: Сельдь соленая, кг | D31: 10 | E31: =IF(D31=20,1,0) -> 0
A32: =EXACT(B32,C32) -> TRUE | B32: Филе сельди соленое, кг | C32: Филе сельди соленое, кг | D32: 10 | E32: =IF(D32=20,1,0) -> 0
A33: =EXACT(B33,C33) -> TRUE | B33: Консервы рыбные натуральные и с добавлением масла, кг | C33: Консервы рыбные натуральные и с добавлением масла, кг | D33: 10 | E33: =IF(D33=20,1,0) -> 0
A34: =EXACT(B34,C34) -> TRUE | B34: Консервы рыбные в томатном соусе, кг | C34: Консервы рыбные в томатном соусе, кг | D34: 10 | E34: =IF(D34=20,1,0) -> 0
A35: =EXACT(B35,C35) -> TRUE | B35: Масло сливочное, кг | C35: Масло сливочное, кг | D35: 10 | E35: =IF(D35=20,1,0) -> 0
A36: =EXACT(B36,C36) -> TRUE | B36: Масло подсолнечное, л | C36: Масло подсолнечное, л | D36: 10 | E36: =IF(D36=20,1,0) -> 0
A37: =EXACT(B37,C37) -> TRUE | B37: Масло оливковое, л | C37: Масло оливковое, л | D37: 10 | E37: =IF(D37=20,1,0) -> 0
A38: =EXACT(B38,C38) -> TRUE | B38: Маргарин, кг | C38: Маргарин, кг | D38: 10 | E38: =IF(D38=20,1,0) -> 0
A39: =EXACT(B39,C39) -> TRUE | B39: Молоко питьевое цельное пастеризованное 2,5-3,2% жирности, л | C39: Молоко питьевое цельное пастеризованное 2,5-3,2% жирности, л | D39: 10 | E39: =IF(D39=20,1,0) -> 0
A40: =EXACT(B40,C40) -> TRUE | B40: Молоко питьевое цельное ультрапастеризованное 2,5-3,2% жирности, л | C40: Молоко питьевое цельное ультрапастеризованное 2,5-3,2% жирности, л | D40: 10 | E40: =IF(D40=20,1,0) -> 0
A41: =EXACT(B41,C41) -> TRUE | B41: Молоко питьевое цельное пастеризованное более 3,2% жирности, л | C41: Молоко питьевое цельное пастеризованное более 3,2% жирности, л | D41: 10 | E41: =IF(D41=20,1,0) -> 0
A42: =EXACT(B42,C42) -> TRUE | B42: Сметана, кг | C42: Сметана, кг | D42: 10 | E42: =IF(D42=20,1,0) -> 0
... A52: =EXACT(B52,C52) -> TRUE | B52: Национальные сыры и брынза, кг | C52: Национальные сыры и брынза, кг | D52: 10 | E52: =IF(D52=20,1,0) -> 0
A53: =EXACT(B53,C53) -> TRUE | B53: Овощи натуральные консервированные, маринованные, кг | C53: Овощи натуральные консервированные, маринованные, кг | D53: 20 | E53: =IF(D53=20,1,0) -> 1 | F53: https://www.alta.ru/tnved/code/0711400000/
A54: =EXACT(B54,C54) -> TRUE | B54: Горошек зеленый консервированный, кг | C54: Горошек зеленый консервированный, кг | D54: 20 | E54: =IF(D54=20,1,0) -> 1 | F54: https://www.alta.ru/tnved/code/2005400000/ https://www.buhonline.ru/forum/index?g=posts&t=469410
A55: =EXACT(B55,C55) -> TRUE | B55: Консервы овощные для детского питания, кг | C55: Консервы овощные для детского питания, кг | D55: 10 | E55: =IF(D55=20,1,0) -> 0
A56: =EXACT(B56,C56) -> TRUE | B56: Консервы томатные, кг | C56: Консервы томатные, кг | D56: 20 | E56: =IF(D56=20,1,0) -> 1 | F56: https://www.alta.ru/tnved/code/2002101000/
A57: =EXACT(B57,C57) -> TRUE | B57: Соки фруктовые, л | C57: Соки фруктовые, л | D57: 10 | E57: =IF(D57=20,1,0) -> 0
A58: =EXACT(B58,C58) -> TRUE | B58: Консервы фруктово-ягодные для детского питания, кг | C58: Консервы фруктово-ягодные для детского питания, кг | D58: 10 | E58: =IF(D58=20,1,0) -> 0
A59: =EXACT(B59,C59) -> TRUE | B59: Зефир, пастила, кг | C59: Зефир, пастила, кг | D59: 20 | E59: =IF(D59=20,1,0) -> 1
A60: =EXACT(B60,C60) -> TRUE | B60: Карамель, кг | C60: Карамель, кг | D60: 20 | E60: =IF(D60=20,1,0) -> 1 | F60: https://www.alta.ru/tnved/code/1704907100/
A61: =EXACT(B61,C61) -> TRUE | B61: Шоколад, кг | C61: Шоколад, кг | D61: 20 | E61: =IF(D61=20,1,0) -> 1 | F61: https://www.alta.ru/tnved/code/1806903100/
A62: =EXACT(B62,C62) -> TRUE | B62: Конфеты мягкие, глазированные шоколадом, кг | C62: Конфеты мягкие, глазированные шоколадом, кг | D62: 20 | E62: =IF(D62=20,1,0) -> 1
...

Sheet Структура
A1: Новое название | B1: Название для поиска 2026 | C1: Название для поиска 2025 | D1: Название для поиска ИПЦ | E1: НДС | F1: Тип | G1: БИПЦ 2026 | H1: БИПЦ 2025 | I1: Туризм и общепит | J1: Вес янв26 | K1: Вес янв25 | L1: ИПЦ 2026 | M1: ИПЦ 2025 | N1: Учитывать | P1: ИПЦ янв25 | Q1: ИПЦ фев25 | R1: ИПЦ мар25 | S1: ИПЦ апр25 | T1: ИПЦ май25 | U1: ИПЦ июн25 | V1: ИПЦ июл25 | W1: ИПЦ авг25 | X1: ИПЦ сен25 | Y1: ИПЦ окт25 | Z1: ИПЦ ноя25 | AA1: ИПЦ дек25 | AB1: ИПЦ янв26 | AC1: ИПЦ фев26 | AD1: ИПЦ мар26 | AE1: ИПЦ апр26 | AG1: Вес янв25 | AH1: Вес фев25 | AI1: Вес мар25 | AJ1: Вес апр25 | AK1: Вес май25 | AL1: Вес июн25 | AM1: Вес июл25 | AN1: Вес авг25 | AO1: Вес сен25 | AP1: Вес окт25 | AQ1: Вес ноя25 | AR1: Вес дек25 | AS1: Вес янв26 | AT1: Вес фев26 | AU1: Вес мар26 | AV1: Вес апр26 | AW1: Вес май26
A2: Говядина (кроме бескостного мяса), кг | B2: =A2 -> Говядина (кроме бескостного мяса), кг | C2: =A2 -> Говядина (кроме бескостного мяса), кг | D2: =C2 -> Говядина (кроме бескостного мяса), кг | E2: =INDEX(БИПЦ_НДС!$D:$D,MATCH(Структура!A2,БИПЦ_НДС!$B:$B,0)) -> 10 | F2: Проды | G2: 1 | H2: 1 | I2: 0 | J2: =INDEX('2026'!$C:$C,MATCH(Структура!B2,'2026'!$B:$B,0)) -> 0.638 | K2: =INDEX('2025'!$C:$C,MATCH(Структура!C2,'2025'!$B:$B,0)) -> 0.627 | L2: 1 | M2: 1 | N2: 0 | P2: =INDEX('ИПЦ raw'!AA:AA, MATCH(Структура!$D2,'ИПЦ raw'!$A:$A,0)) -> 101.77 | Q2: =INDEX('ИПЦ raw'!AB:AB, MATCH(Структура!$D2,'ИПЦ raw'!$A:$A,0)) -> 101.57 | R2: =INDEX('ИПЦ raw'!AC:AC, MATCH(Структура!$D2,'ИПЦ raw'!$A:$A,0)) -> 102.06 | S2: =INDEX('ИПЦ raw'!AD:AD, MATCH(Структура!$D2,'ИПЦ raw'!$A:$A,0)) -> 101.45 | T2: =INDEX('ИПЦ raw'!AE:AE, MATCH(Структура!$D2,'ИПЦ raw'!$A:$A,0)) -> 100.69 | U2: =INDEX('ИПЦ raw'!AF:AF, MATCH(Структура!$D2,'ИПЦ raw'!$A:$A,0)) -> 100.66 | V2: =INDEX('ИПЦ raw'!AG:AG, MATCH(Структура!$D2,'ИПЦ raw'!$A:$A,0)) -> 100.5 | W2: =INDEX('ИПЦ raw'!AH:AH, MATCH(Структура!$D2,'ИПЦ raw'!$A:$A,0)) -> 100.54 | X2: =INDEX('ИПЦ raw'!AI:AI, MATCH(Структура!$D2,'ИПЦ raw'!$A:$A,0)) -> 101.34 | Y2: =INDEX('ИПЦ raw'!AJ:AJ, MATCH(Структура!$D2,'ИПЦ raw'!$A:$A,0)) -> 100.79 | Z2: =INDEX('ИПЦ raw'!AK:AK, MATCH(Структура!$D2,'ИПЦ raw'!$A:$A,0)) -> 100.64 | AA2: =INDEX('ИПЦ raw'!AL:AL, MATCH(Структура!$D2,'ИПЦ raw'!$A:$A,0)) -> 100.96 | AB2: =INDEX('ИПЦ raw'!AM:AM, MATCH(Структура!$D2,'ИПЦ raw'!$A:$A,0)) -> 102.13 | AC2: =INDEX('ИПЦ raw'!AN:AN, MATCH(Структура!$D2,'ИПЦ raw'!$A:$A,0)) -> 101.9 | AD2: =INDEX('ИПЦ raw'!AO:AO, MATCH(Структура!$D2,'ИПЦ raw'!$A:$A,0)) -> 102.33 | AE2: =INDEX('ИПЦ raw'!AP:AP, MATCH(Структура!$D2,'ИПЦ raw'!$A:$A,0)) -> 100.91 | AG2: =INDEX('2025'!$C:$C,MATCH(Структура!C2,'2025'!$B:$B,0)) -> 0.627 | AH2: =AG2*P2/100 -> 0.6380979 | AI2: =AH2*Q2/100 -> 0.64811604 | AJ2: =AI2*R2/100 -> 0.66146723 | AK2: =AJ2*S2/100 -> 0.6710585 | AL2: =AK2*T2/100 -> 0.67568881 | AM2: =AL2*U2/100 -> 0.68014835 | AN2: =AM2*V2/100 -> 0.68354909 | AO2: =AN2*W2/100 -> 0.68724026 | ... AR2: =AQ2*Z2/100 -> 0.70644372 | AS2: =J2 -> 0.638 | AT2: =AS2*AB2/100 -> 0.6515894 | AU2: =AT2*AC2/100 -> 0.6639696 | AV2: =AU2*AD2/100 -> 0.67944009 | AW2: =AV2*AE2/100 -> 0.685623
A3: Говядина бескостная, кг | B3: =A3 -> Говядина бескостная, кг | C3: =A3 -> Говядина бескостная, кг | D3: =C3 -> Говядина бескостная, кг | E3: =INDEX(БИПЦ_НДС!$D:$D,MATCH(Структура!A3,БИПЦ_НДС!$B:$B,0)) -> 10 | F3: Проды | G3: 1 | H3: 1 | I3: 0 | J3: =INDEX('2026'!$C:$C,MATCH(Структура!B3,'2026'!$B:$B,0)) -> 0.429 | K3: =INDEX('2025'!$C:$C,MATCH(Структура!C3,'2025'!$B:$B,0)) -> 0.396 | L3: 1 | M3: 1 | N3: =INDEX(MoM!B:B,MATCH(Структура!A3,MoM!J:J,0)) -> 1 | P3: =INDEX('ИПЦ raw'!AA:AA, MATCH(Структура!$D3,'ИПЦ raw'!$A:$A,0)) -> 101.49 | Q3: =INDEX('ИПЦ raw'!AB:AB, MATCH(Структура!$D3,'ИПЦ raw'!$A:$A,0)) -> 101.77 | R3: =INDEX('ИПЦ raw'!AC:AC, MATCH(Структура!$D3,'ИПЦ raw'!$A:$A,0)) -> 101.99 | S3: =INDEX('ИПЦ raw'!AD:AD, MATCH(Структура!$D3,'ИПЦ raw'!$A:$A,0)) -> 101.01 | T3: =INDEX('ИПЦ raw'!AE:AE, MATCH(Структура!$D3,'ИПЦ raw'!$A:$A,0)) -> 101.27 | U3: =INDEX('ИПЦ raw'!AF:AF, MATCH(Структура!$D3,'ИПЦ raw'!$A:$A,0)) -> 100.66 | V3: =INDEX('ИПЦ raw'!AG:AG, MATCH(Структура!$D3,'ИПЦ raw'!$A:$A,0)) -> 100.54 | W3: =INDEX('ИПЦ raw'!AH:AH, MATCH(Структура!$D3,'ИПЦ raw'!$A:$A,0)) -> 100.45 | X3: =INDEX('ИПЦ raw'!AI:AI, MATCH(Структура!$D3,'ИПЦ raw'!$A:$A,0)) -> 100.76 | Y3: =INDEX('ИПЦ raw'!AJ:AJ, MATCH(Структура!$D3,'ИПЦ raw'!$A:$A,0)) -> 100.53 | Z3: =INDEX('ИПЦ raw'!AK:AK, MATCH(Структура!$D3,'ИПЦ raw'!$A:$A,0)) -> 100.37 | AA3: =INDEX('ИПЦ raw'!AL:AL, MATCH(Структура!$D3,'ИПЦ raw'!$A:$A,0)) -> 100.72 | AB3: =INDEX('ИПЦ raw'!AM:AM, MATCH(Структура!$D3,'ИПЦ raw'!$A:$A,0)) -> 101.47 | AC3: =INDEX('ИПЦ raw'!AN:AN, MATCH(Структура!$D3,'ИПЦ raw'!$A:$A,0)) -> 101.56 | AD3: =INDEX('ИПЦ raw'!AO:AO, MATCH(Структура!$D3,'ИПЦ raw'!$A:$A,0)) -> 101.05 | AE3: =INDEX('ИПЦ raw'!AP:AP, MATCH(Структура!$D3,'ИПЦ raw'!$A:$A,0)) -> 101.05 | AG3: =INDEX('2025'!$C:$C,MATCH(Структура!C3,'2025'!$B:$B,0)) -> 0.396 | AH3: =AG3*P3/100 -> 0.4019004 | AI3: =AH3*Q3/100 -> 0.40901404 | AJ3: =AI3*R3/100 -> 0.41715342 | AK3: =AJ3*S3/100 -> 0.42136667 | AL3: =AK3*T3/100 -> 0.42671802 | AM3: =AL3*U3/100 -> 0.42953436 | AN3: =AM3*V3/100 -> 0.43185385 | AO3: =AN3*W3/100 -> 0.43379719 | ... AR3: =AQ3*Z3/100 -> 0.44103647 | AS3: =J3 -> 0.429 | AT3: =AS3*AB3/100 -> 0.4353063 | AU3: =AT3*AC3/100 -> 0.44209708 | AV3: =AU3*AD3/100 -> 0.4467391 | AW3: =AV3*AE3/100 -> 0.45142986
A4: Свинина (кроме бескостного мяса), кг | B4: =A4 -> Свинина (кроме бескостного мяса), кг | C4: =A4 -> Свинина (кроме бескостного мяса), кг | D4: =C4 -> Свинина (кроме бескостного мяса), кг | E4: =INDEX(БИПЦ_НДС!$D:$D,MATCH(Структура!A4,БИПЦ_НДС!$B:$B,0)) -> 10 | F4: Проды | G4: 1 | H4: 1 | I4: 0 | J4: =INDEX('2026'!$C:$C,MATCH(Структура!B4,'2026'!$B:$B,0)) -> 0.684 | K4: =INDEX('2025'!$C:$C,MATCH(Структура!C4,'2025'!$B:$B,0)) -> 0.726 | L4: 1 | M4: 1 | N4: =INDEX(MoM!B:B,MATCH(Структура!A4,MoM!J:J,0)) -> 1 | P4: =INDEX('ИПЦ raw'!AA:AA, MATCH(Структура!$D4,'ИПЦ raw'!$A:$A,0)) -> 101 | Q4: =INDEX('ИПЦ raw'!AB:AB, MATCH(Структура!$D4,'ИПЦ raw'!$A:$A,0)) -> 100.06 | R4: =INDEX('ИПЦ raw'!AC:AC, MATCH(Структура!$D4,'ИПЦ raw'!$A:$A,0)) -> 100.5 | S4: =INDEX('ИПЦ raw'!AD:AD, MATCH(Структура!$D4,'ИПЦ raw'!$A:$A,0)) -> 101.27 | T4: =INDEX('ИПЦ raw'!AE:AE, MATCH(Структура!$D4,'ИПЦ raw'!$A:$A,0)) -> 101.63 | U4: =INDEX('ИПЦ raw'!AF:AF, MATCH(Структура!$D4,'ИПЦ raw'!$A:$A,0)) -> 100.52 | V4: =INDEX('ИПЦ raw'!AG:AG, MATCH(Структура!$D4,'ИПЦ raw'!$A:$A,0)) -> 101.27 | W4: =INDEX('ИПЦ raw'!AH:AH, MATCH(Структура!$D4,'ИПЦ raw'!$A:$A,0)) -> 101.77 | X4: =INDEX('ИПЦ raw'!AI:AI, MATCH(Структура!$D4,'ИПЦ raw'!$A:$A,0)) -> 100.95 | Y4: =INDEX('ИПЦ raw'!AJ:AJ, MATCH(Структура!$D4,'ИПЦ raw'!$A:$A,0)) -> 100.28 | Z4: =INDEX('ИПЦ raw'!AK:AK, MATCH(Структура!$D4,'ИПЦ raw'!$A:$A,0)) -> 99.93 | AA4: =INDEX('ИПЦ raw'!AL:AL, MATCH(Структура!$D4,'ИПЦ raw'!$A:$A,0)) -> 98.96 | AB4: =INDEX('ИПЦ raw'!AM:AM, MATCH(Структура!$D4,'ИПЦ raw'!$A:$A,0)) -> 100.72 | AC4: =INDEX('ИПЦ raw'!AN:AN, MATCH(Структура!$D4,'ИПЦ raw'!$A:$A,0)) -> 98.67 | AD4: =INDEX('ИПЦ raw'!AO:AO, MATCH(Структура!$D4,'ИПЦ raw'!$A:$A,0)) -> 100.15 | AE4: =INDEX('ИПЦ raw'!AP:AP, MATCH(Структура!$D4,'ИПЦ raw'!$A:$A,0)) -> 100.89 | AG4: =INDEX('2025'!$C:$C,MATCH(Структура!C4,'2025'!$B:$B,0)) -> 0.726 | AH4: =AG4*P4/100 -> 0.73326 | AI4: =AH4*Q4/100 -> 0.73369996 | AJ4: =AI4*R4/100 -> 0.73736846 | AK4: =AJ4*S4/100 -> 0.74673304 | AL4: =AK4*T4/100 -> 0.75890478 | AM4: =AL4*U4/100 -> 0.76285109 | AN4: =AM4*V4/100 -> 0.7725393 | AO4: =AN4*W4/100 -> 0.78621324 | ... AR4: =AQ4*Z4/100 -> 0.79534745 | AS4: =J4 -> 0.684 | AT4: =AS4*AB4/100 -> 0.6889248 | AU4: =AT4*AC4/100 -> 0.6797621 | AV4: =AU4*AD4/100 -> 0.68078174 | AW4: =AV4*AE4/100 -> 0.6868407
A5: Свинина бескостная, кг | B5: =A5 -> Свинина бескостная, кг | C5: =A5 -> Свинина бескостная, кг | D5: =C5 -> Свинина бескостная, кг | E5: =INDEX(БИПЦ_НДС!$D:$D,MATCH(Структура!A5,БИПЦ_НДС!$B:$B,0)) -> 10 | F5: Проды | G5: 1 | H5: 1 | I5: 0 | J5: =INDEX('2026'!$C:$C,MATCH(Структура!B5,'2026'!$B:$B,0)) -> 0.713 | K5: =INDEX('2025'!$C:$C,MATCH(Структура!C5,'2025'!$B:$B,0)) -> 0.714 | L5: 1 | M5: 1 | N5: =INDEX(MoM!B:B,MATCH(Структура!A5,MoM!J:J,0)) -> 1 | P5: =INDEX('ИПЦ raw'!AA:AA, MATCH(Структура!$D5,'ИПЦ raw'!$A:$A,0)) -> 100.25 | Q5: =INDEX('ИПЦ raw'!AB:AB, MATCH(Структура!$D5,'ИПЦ raw'!$A:$A,0)) -> 99.66 | R5: =INDEX('ИПЦ raw'!AC:AC, MATCH(Структура!$D5,'ИПЦ raw'!$A:$A,0)) -> 100.2 | S5: =INDEX('ИПЦ raw'!AD:AD, MATCH(Структура!$D5,'ИПЦ raw'!$A:$A,0)) -> 100.99 | T5: =INDEX('ИПЦ raw'!AE:AE, MATCH(Структура!$D5,'ИПЦ raw'!$A:$A,0)) -> 102.09 | U5: =INDEX('ИПЦ raw'!AF:AF, MATCH(Структура!$D5,'ИПЦ raw'!$A:$A,0)) -> 100.29 | V5: =INDEX('ИПЦ raw'!AG:AG, MATCH(Структура!$D5,'ИПЦ raw'!$A:$A,0)) -> 101.45 | W5: =INDEX('ИПЦ raw'!AH:AH, MATCH(Структура!$D5,'ИПЦ raw'!$A:$A,0)) -> 102.15 | X5: =INDEX('ИПЦ raw'!AI:AI, MATCH(Структура!$D5,'ИПЦ raw'!$A:$A,0)) -> 100.99 | Y5: =INDEX('ИПЦ raw'!AJ:AJ, MATCH(Структура!$D5,'ИПЦ raw'!$A:$A,0)) -> 100.11 | Z5: =INDEX('ИПЦ raw'!AK:AK, MATCH(Структура!$D5,'ИПЦ raw'!$A:$A,0)) -> 99.53 | AA5: =INDEX('ИПЦ raw'!AL:AL, MATCH(Структура!$D5,'ИПЦ raw'!$A:$A,0)) -> 98.75 | AB5: =INDEX('ИПЦ raw'!AM:AM, MATCH(Структура!$D5,'ИПЦ raw'!$A:$A,0)) -> 100.32 | AC5: =INDEX('ИПЦ raw'!AN:AN, MATCH(Структура!$D5,'ИПЦ raw'!$A:$A,0)) -> 98.17 | AD5: =INDEX('ИПЦ raw'!AO:AO, MATCH(Структура!$D5,'ИПЦ raw'!$A:$A,0)) -> 99.28 | AE5: =INDEX('ИПЦ raw'!AP:AP, MATCH(Структура!$D5,'ИПЦ raw'!$A:$A,0)) -> 100.18 | AG5: =INDEX('2025'!$C:$C,MATCH(Структура!C5,'2025'!$B:$B,0)) -> 0.714 | AH5: =AG5*P5/100 -> 0.715785 | AI5: =AH5*Q5/100 -> 0.71335133 | AJ5: =AI5*R5/100 -> 0.71477803 | AK5: =AJ5*S5/100 -> 0.72185434 | AL5: =AK5*T5/100 -> 0.73694109 | AM5: =AL5*U5/100 -> 0.73907822 | AN5: =AM5*V5/100 -> 0.74979486 | AO5: =AN5*W5/100 -> 0.76591544 | ... AR5: =AQ5*Z5/100 -> 0.77070942 | AS5: =J5 -> 0.713 | AT5: =AS5*AB5/100 -> 0.7152816 | AU5: =AT5*AC5/100 -> 0.70219195 | AV5: =AU5*AD5/100 -> 0.69713616 | AW5: =AV5*AE5/100 -> 0.69839101
A6: Баранина (кроме бескостного мяса), кг | B6: =A6 -> Баранина (кроме бескостного мяса), кг | C6: =A6 -> Баранина (кроме бескостного мяса), кг | D6: =C6 -> Баранина (кроме бескостного мяса), кг | E6: =INDEX(БИПЦ_НДС!$D:$D,MATCH(Структура!A6,БИПЦ_НДС!$B:$B,0)) -> 10 | F6: Проды | G6: 1 | H6: 1 | I6: 0 | J6: =INDEX('2026'!$C:$C,MATCH(Структура!B6,'2026'!$B:$B,0)) -> 0.148 | K6: =INDEX('2025'!$C:$C,MATCH(Структура!C6,'2025'!$B:$B,0)) -> 0.145 | L6: 1 | M6: 1 | N6: =INDEX(MoM!B:B,MATCH(Структура!A6,MoM!J:J,0)) -> 1 | P6: =INDEX('ИПЦ raw'!AA:AA, MATCH(Структура!$D6,'ИПЦ raw'!$A:$A,0)) -> 100.21 | Q6: =INDEX('ИПЦ raw'!AB:AB, MATCH(Структура!$D6,'ИПЦ raw'!$A:$A,0)) -> 100.84 | R6: =INDEX('ИПЦ raw'!AC:AC, MATCH(Структура!$D6,'ИПЦ raw'!$A:$A,0)) -> 100.38 | S6: =INDEX('ИПЦ raw'!AD:AD, MATCH(Структура!$D6,'ИПЦ raw'!$A:$A,0)) -> 98.69 | T6: =INDEX('ИПЦ raw'!AE:AE, MATCH(Структура!$D6,'ИПЦ raw'!$A:$A,0)) -> 100.74 | U6: =INDEX('ИПЦ raw'!AF:AF, MATCH(Структура!$D6,'ИПЦ raw'!$A:$A,0)) -> 99.66 | V6: =INDEX('ИПЦ raw'!AG:AG, MATCH(Структура!$D6,'ИПЦ raw'!$A:$A,0)) -> 99.93 | W6: =INDEX('ИПЦ raw'!AH:AH, MATCH(Структура!$D6,'ИПЦ raw'!$A:$A,0)) -> 100.45 | X6: =INDEX('ИПЦ raw'!AI:AI, MATCH(Структура!$D6,'ИПЦ raw'!$A:$A,0)) -> 99.72 | Y6: =INDEX('ИПЦ raw'!AJ:AJ, MATCH(Структура!$D6,'ИПЦ raw'!$A:$A,0)) -> 100.01 | Z6: =INDEX('ИПЦ raw'!AK:AK, MATCH(Структура!$D6,'ИПЦ raw'!$A:$A,0)) -> 98.54 | AA6: =INDEX('ИПЦ raw'!AL:AL, MATCH(Структура!$D6,'ИПЦ raw'!$A:$A,0)) -> 100.32 | AB6: =INDEX('ИПЦ raw'!AM:AM, MATCH(Структура!$D6,'ИПЦ raw'!$A:$A,0)) -> 100.44 | AC6: =INDEX('ИПЦ raw'!AN:AN, MATCH(Структура!$D6,'ИПЦ raw'!$A:$A,0)) -> 102.05 | AD6: =INDEX('ИПЦ raw'!AO:AO, MATCH(Структура!$D6,'ИПЦ raw'!$A:$A,0)) -> 100.69 | AE6: =INDEX('ИПЦ raw'!AP:AP, MATCH(Структура!$D6,'ИПЦ raw'!$A:$A,0)) -> 100.69 | AG6: =INDEX('2025'!$C:$C,MATCH(Структура!C6,'2025'!$B:$B,0)) -> 0.145 | AH6: =AG6*P6/100 -> 0.1453045 | AI6: =AH6*Q6/100 -> 0.14652506 | AJ6: =AI6*R6/100 -> 0.14708185 | AK6: =AJ6*S6/100 -> 0.14515508 | AL6: =AK6*T6/100 -> 0.14622923 | AM6: =AL6*U6/100 -> 0.14573205 | AN6: =AM6*V6/100 -> 0.14563004 | AO6: =AN6*W6/100 -> 0.14628537 | ... AR6: =AQ6*Z6/100 -> 0.14376036 | AS6: =J6 -> 0.148 | AT6: =AS6*AB6/100 -> 0.1486512 | AU6: =AT6*AC6/100 -> 0.15169855 | AV6: =AU6*AD6/100 -> 0.15274527 | AW6: =AV6*AE6/100 -> 0.15379921
A7: Куры охлажденные и мороженые, кг | B7: =A7 -> Куры охлажденные и мороженые, кг | C7: =A7 -> Куры охлажденные и мороженые, кг | D7: =C7 -> Куры охлажденные и мороженые, кг | E7: =INDEX(БИПЦ_НДС!$D:$D,MATCH(Структура!A7,БИПЦ_НДС!$B:$B,0)) -> 10 | F7: Проды | G7: 1 | H7: 1 | I7: 0 | J7: =INDEX('2026'!$C:$C,MATCH(Структура!B7,'2026'!$B:$B,0)) -> 0.925 | K7: =INDEX('2025'!$C:$C,MATCH(Структура!C7,'2025'!$B:$B,0)) -> 0.965 | L7: 1 | M7: 1 | N7: =INDEX(MoM!B:B,MATCH(Структура!A7,MoM!J:J,0)) -> 1 | P7: =INDEX('ИПЦ raw'!AA:AA, MATCH(Структура!$D7,'ИПЦ raw'!$A:$A,0)) -> 100.7 | Q7: =INDEX('ИПЦ raw'!AB:AB, MATCH(Структура!$D7,'ИПЦ raw'!$A:$A,0)) -> 98.97 | R7: =INDEX('ИПЦ raw'!AC:AC, MATCH(Структура!$D7,'ИПЦ raw'!$A:$A,0)) -> 98.35 | S7: =INDEX('ИПЦ raw'!AD:AD, MATCH(Структура!$D7,'ИПЦ raw'!$A:$A,0)) -> 97.99 | T7: =INDEX('ИПЦ raw'!AE:AE, MATCH(Структура!$D7,'ИПЦ raw'!$A:$A,0)) -> 103.95 | U7: =INDEX('ИПЦ raw'!AF:AF, MATCH(Структура!$D7,'ИПЦ raw'!$A:$A,0)) -> 101.26 | V7: =INDEX('ИПЦ raw'!AG:AG, MATCH(Структура!$D7,'ИПЦ raw'!$A:$A,0)) -> 100.13 | W7: =INDEX('ИПЦ raw'!AH:AH, MATCH(Структура!$D7,'ИПЦ raw'!$A:$A,0)) -> 100.05 | X7: =INDEX('ИПЦ raw'!AI:AI, MATCH(Структура!$D7,'ИПЦ raw'!$A:$A,0)) -> 101.56 | Y7: =INDEX('ИПЦ raw'!AJ:AJ, MATCH(Структура!$D7,'ИПЦ raw'!$A:$A,0)) -> 102.34 | Z7: =INDEX('ИПЦ raw'!AK:AK, MATCH(Структура!$D7,'ИПЦ raw'!$A:$A,0)) -> 99.77 | AA7: =INDEX('ИПЦ raw'!AL:AL, MATCH(Структура!$D7,'ИПЦ raw'!$A:$A,0)) -> 100.22 | AB7: =INDEX('ИПЦ raw'!AM:AM, MATCH(Структура!$D7,'ИПЦ raw'!$A:$A,0)) -> 99.87 | AC7: =INDEX('ИПЦ raw'!AN:AN, MATCH(Структура!$D7,'ИПЦ raw'!$A:$A,0)) -> 98.97 | AD7: =INDEX('ИПЦ raw'!AO:AO, MATCH(Структура!$D7,'ИПЦ raw'!$A:$A,0)) -> 98 | AE7: =INDEX('ИПЦ raw'!AP:AP, MATCH(Структура!$D7,'ИПЦ raw'!$A:$A,0)) -> 99.89 | AG7: =INDEX('2025'!$C:$C,MATCH(Структура!C7,'2025'!$B:$B,0)) -> 0.965 | AH7: =AG7*P7/100 -> 0.971755 | AI7: =AH7*Q7/100 -> 0.96174592 | AJ7: =AI7*R7/100 -> 0.94587712 | AK7: =AJ7*S7/100 -> 0.92686499 | AL7: =AK7*T7/100 -> 0.96347615 | AM7: =AL7*U7/100 -> 0.97561595 | AN7: =AM7*V7/100 -> 0.97688425 | AO7: =AN7*W7/100 -> 0.9773727 | ... AR7: =AQ7*Z7/100 -> 1.0135106 | AS7: =J7 -> 0.925 | AT7: =AS7*AB7/100 -> 0.9237975 | AU7: =AT7*AC7/100 -> 0.91428239 | AV7: =AU7*AD7/100 -> 0.89599674 | AW7: =AV7*AE7/100 -> 0.89501114
A8: Окорочка куриные, кг | B8: =A8 -> Окорочка куриные, кг | C8: =A8 -> Окорочка куриные, кг | D8: =C8 -> Окорочка куриные, кг | E8: =INDEX(БИПЦ_НДС!$D:$D,MATCH(Структура!A8,БИПЦ_НДС!$B:$B,0)) -> 10 | F8: Проды | G8: 1 | H8: 1 | I8: 0 | J8: =INDEX('2026'!$C:$C,MATCH(Структура!B8,'2026'!$B:$B,0)) -> 0.44 | K8: =INDEX('2025'!$C:$C,MATCH(Структура!C8,'2025'!$B:$B,0)) -> 0.474 | L8: 1 | M8: 1 | N8: =INDEX(MoM!B:B,MATCH(Структура!A8,MoM!J:J,0)) -> 1 | P8: =INDEX('ИПЦ raw'!AA:AA, MATCH(Структура!$D8,'ИПЦ raw'!$A:$A,0)) -> 100.75 | Q8: =INDEX('ИПЦ raw'!AB:AB, MATCH(Структура!$D8,'ИПЦ raw'!$A:$A,0)) -> 100.16 | R8: =INDEX('ИПЦ raw'!AC:AC, MATCH(Структура!$D8,'ИПЦ raw'!$A:$A,0)) -> 99.89 | S8: =INDEX('ИПЦ raw'!AD:AD, MATCH(Структура!$D8,'ИПЦ raw'!$A:$A,0)) -> 99.54 | T8: =INDEX('ИПЦ raw'!AE:AE, MATCH(Структура!$D8,'ИПЦ raw'!$A:$A,0)) -> 101.37 | U8: =INDEX('ИПЦ raw'!AF:AF, MATCH(Структура!$D8,'ИПЦ raw'!$A:$A,0)) -> 100.45 | V8: =INDEX('ИПЦ raw'!AG:AG, MATCH(Структура!$D8,'ИПЦ raw'!$A:$A,0)) -> 100.45 | W8: =INDEX('ИПЦ raw'!AH:AH, MATCH(Структура!$D8,'ИПЦ raw'!$A:$A,0)) -> 100.52 | X8: =INDEX('ИПЦ raw'!AI:AI, MATCH(Структура!$D8,'ИПЦ raw'!$A:$A,0)) -> 100.68 | Y8: =INDEX('ИПЦ raw'!AJ:AJ, MATCH(Структура!$D8,'ИПЦ raw'!$A:$A,0)) -> 101.39 | Z8: =INDEX('ИПЦ raw'!AK:AK, MATCH(Структура!$D8,'ИПЦ raw'!$A:$A,0)) -> 99.92 | AA8: =INDEX('ИПЦ raw'!AL:AL, MATCH(Структура!$D8,'ИПЦ raw'!$A:$A,0)) -> 100.44 | AB8: =INDEX('ИПЦ raw'!AM:AM, MATCH(Структура!$D8,'ИПЦ raw'!$A:$A,0)) -> 99.94 | AC8: =INDEX('ИПЦ raw'!AN:AN, MATCH(Структура!$D8,'ИПЦ raw'!$A:$A,0)) -> 99.2 | AD8: =INDEX('ИПЦ raw'!AO:AO, MATCH(Структура!$D8,'ИПЦ raw'!$A:$A,0)) -> 99.47 | AE8: =INDEX('ИПЦ raw'!AP:AP, MATCH(Структура!$D8,'ИПЦ raw'!$A:$A,0)) -> 100.53 | AG8: =INDEX('2025'!$C:$C,MATCH(Структура!C8,'2025'!$B:$B,0)) -> 0.474 | AH8: =AG8*P8/100 -> 0.477555 | AI8: =AH8*Q8/100 -> 0.47831909 | AJ8: =AI8*R8/100 -> 0.47779294 | AK8: =AJ8*S8/100 -> 0.47559509 | AL8: =AK8*T8/100 -> 0.48211074 | AM8: =AL8*U8/100 -> 0.48428024 | AN8: =AM8*V8/100 -> 0.4864595 | AO8: =AN8*W8/100 -> 0.48898909 | ... AR8: =AQ8*Z8/100 -> 0.49875806 | AS8: =J8 -> 0.44 | AT8: =AS8*AB8/100 -> 0.439736 | AU8: =AT8*AC8/100 -> 0.43621811 | AV8: =AU8*AD8/100 -> 0.43390616 | AW8: =AV8*AE8/100 -> 0.43620586
A9: Мясо индейки, кг | B9: =A9 -> Мясо индейки, кг | C9: =A9 -> Мясо индейки, кг | D9: Мясо индейки, кг | E9: =INDEX(БИПЦ_НДС!$D:$D,MATCH(Структура!A9,БИПЦ_НДС!$B:$B,0)) -> 10 | F9: Проды | G9: 1 | H9: 1 | I9: 0 | J9: =INDEX('2026'!$C:$C,MATCH(Структура!B9,'2026'!$B:$B,0)) -> 0.235 | K9: =INDEX('2025'!$C:$C,MATCH(Структура!C9,'2025'!$B:$B,0)) -> 0.268 | L9: 1 | M9: 1 | N9: =INDEX(MoM!B:B,MATCH(Структура!A9,MoM!J:J,0)) -> 1 | P9: =INDEX('ИПЦ raw'!AA:AA, MATCH(Структура!$D9,'ИПЦ raw'!$A:$A,0)) -> 101.5 | Q9: =INDEX('ИПЦ raw'!AB:AB, MATCH(Структура!$D9,'ИПЦ raw'!$A:$A,0)) -> 100.62 | R9: =INDEX('ИПЦ raw'!AC:AC, MATCH(Структура!$D9,'ИПЦ raw'!$A:$A,0)) -> 99.8 | S9: =INDEX('ИПЦ raw'!AD:AD, MATCH(Структура!$D9,'ИПЦ raw'!$A:$A,0)) -> 99.79 | T9: =INDEX('ИПЦ raw'!AE:AE, MATCH(Структура!$D9,'ИПЦ raw'!$A:$A,0)) -> 99.13 | U9: =INDEX('ИПЦ raw'!AF:AF, MATCH(Структура!$D9,'ИПЦ raw'!$A:$A,0)) -> 99.06 | V9: =INDEX('ИПЦ raw'!AG:AG, MATCH(Структура!$D9,'ИПЦ raw'!$A:$A,0)) -> 99.48 | W9: =INDEX('ИПЦ raw'!AH:AH, MATCH(Структура!$D9,'ИПЦ raw'!$A:$A,0)) -> 99.69 | X9: =INDEX('ИПЦ raw'!AI:AI, MATCH(Структура!$D9,'ИПЦ raw'!$A:$A,0)) -> 99.58 | Y9: =INDEX('ИПЦ raw'!AJ:AJ, MATCH(Структура!$D9,'ИПЦ raw'!$A:$A,0)) -> 101.38 | Z9: =INDEX('ИПЦ raw'!AK:AK, MATCH(Структура!$D9,'ИПЦ raw'!$A:$A,0)) -> 102.75 | AA9: =INDEX('ИПЦ raw'!AL:AL, MATCH(Структура!$D9,'ИПЦ raw'!$A:$A,0)) -> 101.54 | AB9: =INDEX('ИПЦ raw'!AM:AM, MATCH(Структура!$D9,'ИПЦ raw'!$A:$A,0)) -> 101.2 | AC9: =INDEX('ИПЦ raw'!AN:AN, MATCH(Структура!$D9,'ИПЦ raw'!$A:$A,0)) -> 100.47 | AD9: =INDEX('ИПЦ raw'!AO:AO, MATCH(Структура!$D9,'ИПЦ raw'!$A:$A,0)) -> 100.72 | AE9: =INDEX('ИПЦ raw'!AP:AP, MATCH(Структура!$D9,'ИПЦ raw'!$A:$A,0)) -> 100.69 | AG9: =INDEX('2025'!$C:$C,MATCH(Структура!C9,'2025'!$B:$B,0)) -> 0.268 | AH9: =AG9*P9/100 -> 0.27202 | AI9: =AH9*Q9/100 -> 0.27370652 | AJ9: =AI9*R9/100 -> 0.27315911 | AK9: =AJ9*S9/100 -> 0.27258548 | AL9: =AK9*T9/100 -> 0.27021398 | AM9: =AL9*U9/100 -> 0.26767397 | AN9: =AM9*V9/100 -> 0.26628207 | AO9: =AN9*W9/100 -> 0.26545659 | ... AR9: =AQ9*Z9/100 -> 0.2753593 | AS9: =J9 -> 0.235 | AT9: =AS9*AB9/100 -> 0.23782 | AU9: =AT9*AC9/100 -> 0.23893775 | AV9: =AU9*AD9/100 -> 0.24065811 | AW9: =AV9*AE9/100 -> 0.24231865
A10: Печень говяжья, свиная, кг | B10: =A10 -> Печень говяжья, свиная, кг | C10: =A10 -> Печень говяжья, свиная, кг | D10: =C10 -> Печень говяжья, свиная, кг | E10: =INDEX(БИПЦ_НДС!$D:$D,MATCH(Структура!A10,БИПЦ_НДС!$B:$B,0)) -> 10 | F10: Проды | G10: 1 | H10: 1 | I10: 0 | J10: =INDEX('2026'!$C:$C,MATCH(Структура!B10,'2026'!$B:$B,0)) -> 0.151 | K10: =INDEX('2025'!$C:$C,MATCH(Структура!C10,'2025'!$B:$B,0)) -> 0.168 | L10: 1 | M10: 1 | N10: =INDEX(MoM!B:B,MATCH(Структура!A10,MoM!J:J,0)) -> 1 | P10: =INDEX('ИПЦ raw'!AA:AA, MATCH(Структура!$D10,'ИПЦ raw'!$A:$A,0)) -> 100.28 | Q10: =INDEX('ИПЦ raw'!AB:AB, MATCH(Структура!$D10,'ИПЦ raw'!$A:$A,0)) -> 100.32 | R10: =INDEX('ИПЦ raw'!AC:AC, MATCH(Структура!$D10,'ИПЦ raw'!$A:$A,0)) -> 100.86 | S10: =INDEX('ИПЦ raw'!AD:AD, MATCH(Структура!$D10,'ИПЦ raw'!$A:$A,0)) -> 100.79 | T10: =INDEX('ИПЦ raw'!AE:AE, MATCH(Структура!$D10,'ИПЦ raw'!$A:$A,0)) -> 100.78 | U10: =INDEX('ИПЦ raw'!AF:AF, MATCH(Структура!$D10,'ИПЦ raw'!$A:$A,0)) -> 100.6 | V10: =INDEX('ИПЦ raw'!AG:AG, MATCH(Структура!$D10,'ИПЦ raw'!$A:$A,0)) -> 101.08 | W10: =INDEX('ИПЦ raw'!AH:AH, MATCH(Структура!$D10,'ИПЦ raw'!$A:$A,0)) -> 101.24 | X10: =INDEX('ИПЦ raw'!AI:AI, MATCH(Структура!$D10,'ИПЦ raw'!$A:$A,0)) -> 101.65 | Y10: =INDEX('ИПЦ raw'!AJ:AJ, MATCH(Структура!$D10,'ИПЦ raw'!$A:$A,0)) -> 101.33 | Z10: =INDEX('ИПЦ raw'!AK:AK, MATCH(Структура!$D10,'ИПЦ raw'!$A:$A,0)) -> 101.5 | AA10: =INDEX('ИПЦ raw'!AL:AL, MATCH(Структура!$D10,'ИПЦ raw'!$A:$A,0)) -> 101.99 | AB10: =INDEX('ИПЦ raw'!AM:AM, MATCH(Структура!$D10,'ИПЦ raw'!$A:$A,0)) -> 101.29 | AC10: =INDEX('ИПЦ raw'!AN:AN, MATCH(Структура!$D10,'ИПЦ raw'!$A:$A,0)) -> 101.75 | AD10: =INDEX('ИПЦ raw'!AO:AO, MATCH(Структура!$D10,'ИПЦ raw'!$A:$A,0)) -> 100.77 | AE10: =INDEX('ИПЦ raw'!AP:AP, MATCH(Структура!$D10,'ИПЦ raw'!$A:$A,0)) -> 101.16 | AG10: =INDEX('2025'!$C:$C,MATCH(Структура!C10,'2025'!$B:$B,0)) -> 0.168 | AH10: =AG10*P10/100 -> 0.1684704 | AI10: =AH10*Q10/100 -> 0.16900951 | AJ10: =AI10*R10/100 -> 0.17046299 | AK10: =AJ10*S10/100 -> 0.17180964 | AL10: =AK10*T10/100 -> 0.17314976 | AM10: =AL10*U10/100 -> 0.17418866 | AN10: =AM10*V10/100 -> 0.1760699 | AO10: =AN10*W10/100 -> 0.17825316 | ... AR10: =AQ10*Z10/100 -> 0.18635829 | AS10: =J10 -> 0.151 | AT10: =AS10*AB10/100 -> 0.1529479 | AU10: =AT10*AC10/100 -> 0.15562449 | AV10: =AU10*AD10/100 -> 0.1568228 | AW10: =AV10*AE10/100 -> 0.15864194
A11: Фарш мясной, кг | B11: =A11 -> Фарш мясной, кг | C11: =A11 -> Фарш мясной, кг | D11: =C11 -> Фарш мясной, кг | E11: =INDEX(БИПЦ_НДС!$D:$D,MATCH(Структура!A11,БИПЦ_НДС!$B:$B,0)) -> 10 | F11: Проды | G11: 1 | H11: 1 | I11: 0 | J11: =INDEX('2026'!$C:$C,MATCH(Структура!B11,'2026'!$B:$B,0)) -> 0.892 | K11: =INDEX('2025'!$C:$C,MATCH(Структура!C11,'2025'!$B:$B,0)) -> 0.88 | L11: 1 | M11: 1 | N11: =INDEX(MoM!B:B,MATCH(Структура!A11,MoM!J:J,0)) -> 1 | P11: =INDEX('ИПЦ raw'!AA:AA, MATCH(Структура!$D11,'ИПЦ raw'!$A:$A,0)) -> 101.09 | Q11: =INDEX('ИПЦ raw'!AB:AB, MATCH(Структура!$D11,'ИПЦ raw'!$A:$A,0)) -> 101.09 | R11: =INDEX('ИПЦ raw'!AC:AC, MATCH(Структура!$D11,'ИПЦ raw'!$A:$A,0)) -> 100.81 | S11: =INDEX('ИПЦ raw'!AD:AD, MATCH(Структура!$D11,'ИПЦ raw'!$A:$A,0)) -> 101.25 | T11: =INDEX('ИПЦ raw'!AE:AE, MATCH(Структура!$D11,'ИПЦ raw'!$A:$A,0)) -> 100.78 | U11: =INDEX('ИПЦ raw'!AF:AF, MATCH(Структура!$D11,'ИПЦ raw'!$A:$A,0)) -> 100.75 | V11: =INDEX('ИПЦ raw'!AG:AG, MATCH(Структура!$D11,'ИПЦ raw'!$A:$A,0)) -> 100.33 | W11: =INDEX('ИПЦ raw'!AH:AH, MATCH(Структура!$D11,'ИПЦ raw'!$A:$A,0)) -> 101.32 | X11: =INDEX('ИПЦ raw'!AI:AI, MATCH(Структура!$D11,'ИПЦ raw'!$A:$A,0)) -> 100.86 | Y11: =INDEX('ИПЦ raw'!AJ:AJ, MATCH(Структура!$D11,'ИПЦ raw'!$A:$A,0)) -> 100.96 | Z11: =INDEX('ИПЦ raw'!AK:AK, MATCH(Структура!$D11,'ИПЦ raw'!$A:$A,0)) -> 100.14 | AA11: =INDEX('ИПЦ raw'!AL:AL, MATCH(Структура!$D11,'ИПЦ raw'!$A:$A,0)) -> 100.48 | AB11: =INDEX('ИПЦ raw'!AM:AM, MATCH(Структура!$D11,'ИПЦ raw'!$A:$A,0)) -> 100.33 | AC11: =INDEX('ИПЦ raw'!AN:AN, MATCH(Структура!$D11,'ИПЦ raw'!$A:$A,0)) -> 100.22 | AD11: =INDEX('ИПЦ raw'!AO:AO, MATCH(Структура!$D11,'ИПЦ raw'!$A:$A,0)) -> 100.77 | AE11: =INDEX('ИПЦ raw'!AP:AP, MATCH(Структура!$D11,'ИПЦ raw'!$A:$A,0)) -> 100.27 | AG11: =INDEX('2025'!$C:$C,MATCH(Структура!C11,'2025'!$B:$B,0)) -> 0.88 | AH11: =AG11*P11/100 -> 0.889592 | AI11: =AH11*Q11/100 -> 0.89928855 | AJ11: =AI11*R11/100 -> 0.90657279 | AK11: =AJ11*S11/100 -> 0.91790495 | AL11: =AK11*T11/100 -> 0.92506461 | AM11: =AL11*U11/100 -> 0.93200259 | AN11: =AM11*V11/100 -> 0.9350782 | AO11: =AN11*W11/100 -> 0.94742123 | ... AR11: =AQ11*Z11/100 -> 0.96609316 | AS11: =J11 -> 0.892 | AT11: =AS11*AB11/100 -> 0.8949436 | AU11: =AT11*AC11/100 -> 0.89691248 | AV11: =AU11*AD11/100 -> 0.9038187 | AW11: =AV11*AE11/100 -> 0.90625901
A12: Пельмени, манты, равиоли, кг | B12: =A12 -> Пельмени, манты, равиоли, кг | C12: =A12 -> Пельмени, манты, равиоли, кг | D12: =C12 -> Пельмени, манты, равиоли, кг | E12: =INDEX(БИПЦ_НДС!$D:$D,MATCH(Структура!A12,БИПЦ_НДС!$B:$B,0)) -> 10 | F12: Проды | G12: 1 | H12: 1 | I12: 0 | J12: =INDEX('2026'!$C:$C,MATCH(Структура!B12,'2026'!$B:$B,0)) -> 0.765 | K12: =INDEX('2025'!$C:$C,MATCH(Структура!C12,'2025'!$B:$B,0)) -> 0.757 | L12: 1 | M12: 1 | N12: =INDEX(MoM!B:B,MATCH(Структура!A12,MoM!J:J,0)) -> 1 | P12: =INDEX('ИПЦ raw'!AA:AA, MATCH(Структура!$D12,'ИПЦ raw'!$A:$A,0)) -> 100.36 | Q12: =INDEX('ИПЦ raw'!AB:AB, MATCH(Структура!$D12,'ИПЦ raw'!$A:$A,0)) -> 100.39 | R12: =INDEX('ИПЦ raw'!AC:AC, MATCH(Структура!$D12,'ИПЦ raw'!$A:$A,0)) -> 100.06 | S12: =INDEX('ИПЦ raw'!AD:AD, MATCH(Структура!$D12,'ИПЦ raw'!$A:$A,0)) -> 100.38 | T12: =INDEX('ИПЦ raw'!AE:AE, MATCH(Структура!$D12,'ИПЦ raw'!$A:$A,0)) -> 100.46 | U12: =INDEX('ИПЦ raw'!AF:AF, MATCH(Структура!$D12,'ИПЦ raw'!$A:$A,0)) -> 100.08 | V12: =INDEX('ИПЦ raw'!AG:AG, MATCH(Структура!$D12,'ИПЦ raw'!$A:$A,0)) -> 99.75 | W12: =INDEX('ИПЦ raw'!AH:AH, MATCH(Структура!$D12,'ИПЦ raw'!$A:$A,0)) -> 100.2 | X12: =INDEX('ИПЦ raw'!AI:AI, MATCH(Структура!$D12,'ИПЦ raw'!$A:$A,0)) -> 100.05 | Y12: =INDEX('ИПЦ raw'!AJ:AJ, MATCH(Структура!$D12,'ИПЦ raw'!$A:$A,0)) -> 100.4 | Z12: =INDEX('ИПЦ raw'!AK:AK, MATCH(Структура!$D12,'ИПЦ raw'!$A:$A,0)) -> 100.9 | AA12: =INDEX('ИПЦ raw'!AL:AL, MATCH(Структура!$D12,'ИПЦ raw'!$A:$A,0)) -> 100.74 | AB12: =INDEX('ИПЦ raw'!AM:AM, MATCH(Структура!$D12,'ИПЦ raw'!$A:$A,0)) -> 100.75 | AC12: =INDEX('ИПЦ raw'!AN:AN, MATCH(Структура!$D12,'ИПЦ raw'!$A:$A,0)) -> 100.13 | AD12: =INDEX('ИПЦ raw'!AO:AO, MATCH(Структура!$D12,'ИПЦ raw'!$A:$A,0)) -> 99.71 | AE12: =INDEX('ИПЦ raw'!AP:AP, MATCH(Структура!$D12,'ИПЦ raw'!$A:$A,0)) -> 99.52 | AG12: =INDEX('2025'!$C:$C,MATCH(Структура!C12,'2025'!$B:$B,0)) -> 0.757 | AH12: =AG12*P12/100 -> 0.7597252 | AI12: =AH12*Q12/100 -> 0.76268813 | AJ12: =AI12*R12/100 -> 0.76314574 | AK12: =AJ12*S12/100 -> 0.76604569 | AL12: =AK12*T12/100 -> 0.76956951 | AM12: =AL12*U12/100 -> 0.77018516 | AN12: =AM12*V12/100 -> 0.7682597 | AO12: =AN12*W12/100 -> 0.76979622 | ... AR12: =AQ12*Z12/100 -> 0.7802212 | AS12: =J12 -> 0.765 | AT12: =AS12*AB12/100 -> 0.7707375 | AU12: =AT12*AC12/100 -> 0.77173946 | AV12: =AU12*AD12/100 -> 0.76950141 | AW12: =AV12*AE12/100 -> 0.76580781
A13: Сосиски, сардельки, кг | B13: =A13 -> Сосиски, сардельки, кг | C13: =A13 -> Сосиски, сардельки, кг | D13: =C13 -> Сосиски, сардельки, кг | E13: =INDEX(БИПЦ_НДС!$D:$D,MATCH(Структура!A13,БИПЦ_НДС!$B:$B,0)) -> 10 | F13: Проды | G13: 1 | H13: 1 | I13: 0 | J13: =INDEX('2026'!$C:$C,MATCH(Структура!B13,'2026'!$B:$B,0)) -> 0.647 | K13: =INDEX('2025'!$C:$C,MATCH(Структура!C13,'2025'!$B:$B,0)) -> 0.68 | L13: 1 | M13: 1 | N13: =INDEX(MoM!B:B,MATCH(Структура!A13,MoM!J:J,0)) -> 1 | P13: =INDEX('ИПЦ raw'!AA:AA, MATCH(Структура!$D13,'ИПЦ raw'!$A:$A,0)) -> 99.7 | Q13: =INDEX('ИПЦ raw'!AB:AB, MATCH(Структура!$D13,'ИПЦ raw'!$A:$A,0)) -> 100.33 | R13: =INDEX('ИПЦ raw'!AC:AC, MATCH(Структура!$D13,'ИПЦ raw'!$A:$A,0)) -> 100.4 | S13: =INDEX('ИПЦ raw'!AD:AD, MATCH(Структура!$D13,'ИПЦ raw'!$A:$A,0)) -> 100.04 | T13: =INDEX('ИПЦ raw'!AE:AE, MATCH(Структура!$D13,'ИПЦ raw'!$A:$A,0)) -> 100.69 | U13: =INDEX('ИПЦ raw'!AF:AF, MATCH(Структура!$D13,'ИПЦ raw'!$A:$A,0)) -> 100.02 | V13: =INDEX('ИПЦ raw'!AG:AG, MATCH(Структура!$D13,'ИПЦ raw'!$A:$A,0)) -> 99.8 | W13: =INDEX('ИПЦ raw'!AH:AH, MATCH(Структура!$D13,'ИПЦ raw'!$A:$A,0)) -> 100.41 | X13: =INDEX('ИПЦ raw'!AI:AI, MATCH(Структура!$D13,'ИПЦ raw'!$A:$A,0)) -> 100.7 | Y13: =INDEX('ИПЦ raw'!AJ:AJ, MATCH(Структура!$D13,'ИПЦ raw'!$A:$A,0)) -> 100.71 | Z13: =INDEX('ИПЦ raw'!AK:AK, MATCH(Структура!$D13,'ИПЦ raw'!$A:$A,0)) -> 100.55 | AA13: =INDEX('ИПЦ raw'!AL:AL, MATCH(Структура!$D13,'ИПЦ raw'!$A:$A,0)) -> 100.56 | AB13: =INDEX('ИПЦ raw'!AM:AM, MATCH(Структура!$D13,'ИПЦ raw'!$A:$A,0)) -> 100.64 | AC13: =INDEX('ИПЦ raw'!AN:AN, MATCH(Структура!$D13,'ИПЦ raw'!$A:$A,0)) -> 99.86 | AD13: =INDEX('ИПЦ raw'!AO:AO, MATCH(Структура!$D13,'ИПЦ raw'!$A:$A,0)) -> 99.72 | AE13: =INDEX('ИПЦ raw'!AP:AP, MATCH(Структура!$D13,'ИПЦ raw'!$A:$A,0)) -> 99.47 | AG13: =INDEX('2025'!$C:$C,MATCH(Структура!C13,'2025'!$B:$B,0)) -> 0.68 | AH13: =AG13*P13/100 -> 0.67796 | AI13: =AH13*Q13/100 -> 0.68019727 | AJ13: =AI13*R13/100 -> 0.68291806 | AK13: =AJ13*S13/100 -> 0.68319122 | AL13: =AK13*T13/100 -> 0.68790524 | AM13: =AL13*U13/100 -> 0.68804282 | AN13: =AM13*V13/100 -> 0.68666674 | AO13: =AN13*W13/100 -> 0.68948207 | ... AR13: =AQ13*Z13/100 -> 0.70308385 | AS13: =J13 -> 0.647 | AT13: =AS13*AB13/100 -> 0.6511408 | AU13: =AT13*AC13/100 -> 0.6502292 | AV13: =AU13*AD13/100 -> 0.64840856 | AW13: =AV13*AE13/100 -> 0.644972
A14: Колбаса полукопченая и варено-копченая, кг | B14: =A14 -> Колбаса полукопченая и варено-копченая, кг | C14: =A14 -> Колбаса полукопченая и варено-копченая, кг | D14: =C14 -> Колбаса полукопченая и варено-копченая, кг | E14: =INDEX(БИПЦ_НДС!$D:$D,MATCH(Структура!A14,БИПЦ_НДС!$B:$B,0)) -> 10 | F14: Проды | G14: 1 | H14: 1 | I14: 0 | J14: =INDEX('2026'!$C:$C,MATCH(Структура!B14,'2026'!$B:$B,0)) -> 0.507 | K14: =INDEX('2025'!$C:$C,MATCH(Структура!C14,'2025'!$B:$B,0)) -> 0.501 | L14: 1 | M14: 1 | N14: =INDEX(MoM!B:B,MATCH(Структура!A14,MoM!J:J,0)) -> 1 | P14: =INDEX('ИПЦ raw'!AA:AA, MATCH(Структура!$D14,'ИПЦ raw'!$A:$A,0)) -> 100.28 | Q14: =INDEX('ИПЦ raw'!AB:AB, MATCH(Структура!$D14,'ИПЦ raw'!$A:$A,0)) -> 100.53 | R14: =INDEX('ИПЦ raw'!AC:AC, MATCH(Структура!$D14,'ИПЦ raw'!$A:$A,0)) -> 101.22 | S14: =INDEX('ИПЦ raw'!AD:AD, MATCH(Структура!$D14,'ИПЦ raw'!$A:$A,0)) -> 100.25 | T14: =INDEX('ИПЦ raw'!AE:AE, MATCH(Структура!$D14,'ИПЦ raw'!$A:$A,0)) -> 100.34 | U14: =INDEX('ИПЦ raw'!AF:AF, MATCH(Структура!$D14,'ИПЦ raw'!$A:$A,0)) -> 99.82 | V14: =INDEX('ИПЦ raw'!AG:AG, MATCH(Структура!$D14,'ИПЦ raw'!$A:$A,0)) -> 100.35 | W14: =INDEX('ИПЦ raw'!AH:AH, MATCH(Структура!$D14,'ИПЦ raw'!$A:$A,0)) -> 100.59 | X14: =INDEX('ИПЦ raw'!AI:AI, MATCH(Структура!$D14,'ИПЦ raw'!$A:$A,0)) -> 100.5 | Y14: =INDEX('ИПЦ raw'!AJ:AJ, MATCH(Структура!$D14,'ИПЦ raw'!$A:$A,0)) -> 100.8 | Z14: =INDEX('ИПЦ raw'!AK:AK, MATCH(Структура!$D14,'ИПЦ raw'!$A:$A,0)) -> 100.73 | AA14: =INDEX('ИПЦ raw'!AL:AL, MATCH(Структура!$D14,'ИПЦ raw'!$A:$A,0)) -> 100.1 | AB14: =INDEX('ИПЦ raw'!AM:AM, MATCH(Структура!$D14,'ИПЦ raw'!$A:$A,0)) -> 100.33 | AC14: =INDEX('ИПЦ raw'!AN:AN, MATCH(Структура!$D14,'ИПЦ raw'!$A:$A,0)) -> 100.1 | AD14: =INDEX('ИПЦ raw'!AO:AO, MATCH(Структура!$D14,'ИПЦ raw'!$A:$A,0)) -> 99.76 | AE14: =INDEX('ИПЦ raw'!AP:AP, MATCH(Структура!$D14,'ИПЦ raw'!$A:$A,0)) -> 99.6 | AG14: =INDEX('2025'!$C:$C,MATCH(Структура!C14,'2025'!$B:$B,0)) -> 0.501 | AH14: =AG14*P14/100 -> 0.5024028 | AI14: =AH14*Q14/100 -> 0.50506553 | AJ14: =AI14*R14/100 -> 0.51122733 | AK14: =AJ14*S14/100 -> 0.5125054 | AL14: =AK14*T14/100 -> 0.51424792 | AM14: =AL14*U14/100 -> 0.51332227 | AN14: =AM14*V14/100 -> 0.5151189 | AO14: =AN14*W14/100 -> 0.5181581 | ... AR14: =AQ14*Z14/100 -> 0.52874676 | AS14: =J14 -> 0.507 | AT14: =AS14*AB14/100 -> 0.5086731 | AU14: =AT14*AC14/100 -> 0.50918177 | AV14: =AU14*AD14/100 -> 0.50795974 | AW14: =AV14*AE14/100 -> 0.5059279
A15: Колбаса сырокопченая, кг | B15: =A15 -> Колбаса сырокопченая, кг | C15: =A15 -> Колбаса сырокопченая, кг | D15: =C15 -> Колбаса сырокопченая, кг | E15: =INDEX(БИПЦ_НДС!$D:$D,MATCH(Структура!A15,БИПЦ_НДС!$B:$B,0)) -> 10 | F15: Проды | G15: 1 | H15: 1 | I15: 0 | J15: =INDEX('2026'!$C:$C,MATCH(Структура!B15,'2026'!$B:$B,0)) -> 0.204 | K15: =INDEX('2025'!$C:$C,MATCH(Структура!C15,'2025'!$B:$B,0)) -> 0.195 | L15: 1 | M15: 1 | N15: =INDEX(MoM!B:B,MATCH(Структура!A15,MoM!J:J,0)) -> 1 | P15: =INDEX('ИПЦ raw'!AA:AA, MATCH(Структура!$D15,'ИПЦ raw'!$A:$A,0)) -> 99.68 | Q15: =INDEX('ИПЦ raw'!AB:AB, MATCH(Структура!$D15,'ИПЦ raw'!$A:$A,0)) -> 100.44 | R15: =INDEX('ИПЦ raw'!AC:AC, MATCH(Структура!$D15,'ИПЦ raw'!$A:$A,0)) -> 99.88 | S15: =INDEX('ИПЦ raw'!AD:AD, MATCH(Структура!$D15,'ИПЦ raw'!$A:$A,0)) -> 100.2 | T15: =INDEX('ИПЦ raw'!AE:AE, MATCH(Структура!$D15,'ИПЦ raw'!$A:$A,0)) -> 100.09 | U15: =INDEX('ИПЦ raw'!AF:AF, MATCH(Структура!$D15,'ИПЦ raw'!$A:$A,0)) -> 100.39 | V15: =INDEX('ИПЦ raw'!AG:AG, MATCH(Структура!$D15,'ИПЦ raw'!$A:$A,0)) -> 99.22 | W15: =INDEX('ИПЦ raw'!AH:AH, MATCH(Структура!$D15,'ИПЦ raw'!$A:$A,0)) -> 100.63 | X15: =INDEX('ИПЦ raw'!AI:AI, MATCH(Структура!$D15,'ИПЦ raw'!$A:$A,0)) -> 100.3 | Y15: =INDEX('ИПЦ raw'!AJ:AJ, MATCH(Структура!$D15,'ИПЦ raw'!$A:$A,0)) -> 101.1 | Z15: =INDEX('ИПЦ raw'!AK:AK, MATCH(Структура!$D15,'ИПЦ raw'!$A:$A,0)) -> 99.54 | AA15: =INDEX('ИПЦ raw'!AL:AL, MATCH(Структура!$D15,'ИПЦ raw'!$A:$A,0)) -> 99.65 | AB15: =INDEX('ИПЦ raw'!AM:AM, MATCH(Структура!$D15,'ИПЦ raw'!$A:$A,0)) -> 100.65 | AC15: =INDEX('ИПЦ raw'!AN:AN, MATCH(Структура!$D15,'ИПЦ raw'!$A:$A,0)) -> 100.69 | AD15: =INDEX('ИПЦ raw'!AO:AO, MATCH(Структура!$D15,'ИПЦ raw'!$A:$A,0)) -> 100.53 | AE15: =INDEX('ИПЦ raw'!AP:AP, MATCH(Структура!$D15,'ИПЦ raw'!$A:$A,0)) -> 99.05 | AG15: =INDEX('2025'!$C:$C,MATCH(Структура!C15,'2025'!$B:$B,0)) -> 0.195 | AH15: =AG15*P15/100 -> 0.194376 | AI15: =AH15*Q15/100 -> 0.19523125 | AJ15: =AI15*R15/100 -> 0.19499698 | AK15: =AJ15*S15/100 -> 0.19538697 | AL15: =AK15*T15/100 -> 0.19556282 | AM15: =AL15*U15/100 -> 0.19632551 | AN15: =AM15*V15/100 -> 0.19479418 | AO15: =AN15*W15/100 -> 0.19602138 | ... AR15: =AQ15*Z15/100 -> 0.19785779 | AS15: =J15 -> 0.204 | AT15: =AS15*AB15/100 -> 0.205326 | AU15: =AT15*AC15/100 -> 0.20674275 | AV15: =AU15*AD15/100 -> 0.20783849 | AW15: =AV15*AE15/100 -> 0.20586402
A16: Колбаса вареная, кг | B16: =A16 -> Колбаса вареная, кг | C16: =A16 -> Колбаса вареная, кг | D16: =C16 -> Колбаса вареная, кг | E16: =INDEX(БИПЦ_НДС!$D:$D,MATCH(Структура!A16,БИПЦ_НДС!$B:$B,0)) -> 10 | F16: Проды | G16: 1 | H16: 1 | I16: 0 | J16: =INDEX('2026'!$C:$C,MATCH(Структура!B16,'2026'!$B:$B,0)) -> 0.604 | K16: =INDEX('2025'!$C:$C,MATCH(Структура!C16,'2025'!$B:$B,0)) -> 0.602 | L16: 1 | M16: 1 | N16: =INDEX(MoM!B:B,MATCH(Структура!A16,MoM!J:J,0)) -> 1 | P16: =INDEX('ИПЦ raw'!AA:AA, MATCH(Структура!$D16,'ИПЦ raw'!$A:$A,0)) -> 99.7 | Q16: =INDEX('ИПЦ raw'!AB:AB, MATCH(Структура!$D16,'ИПЦ raw'!$A:$A,0)) -> 100.42 | R16: =INDEX('ИПЦ raw'!AC:AC, MATCH(Структура!$D16,'ИПЦ raw'!$A:$A,0)) -> 100.24 | S16: =INDEX('ИПЦ raw'!AD:AD, MATCH(Структура!$D16,'ИПЦ raw'!$A:$A,0)) -> 100.12 | T16: =INDEX('ИПЦ raw'!AE:AE, MATCH(Структура!$D16,'ИПЦ raw'!$A:$A,0)) -> 100.2 | U16: =INDEX('ИПЦ raw'!AF:AF, MATCH(Структура!$D16,'ИПЦ raw'!$A:$A,0)) -> 100.55 | V16: =INDEX('ИПЦ raw'!AG:AG, MATCH(Структура!$D16,'ИПЦ raw'!$A:$A,0)) -> 100.19 | W16: =INDEX('ИПЦ raw'!AH:AH, MATCH(Структура!$D16,'ИПЦ raw'!$A:$A,0)) -> 99.82 | X16: =INDEX('ИПЦ raw'!AI:AI, MATCH(Структура!$D16,'ИПЦ raw'!$A:$A,0)) -> 100.71 | Y16: =INDEX('ИПЦ raw'!AJ:AJ, MATCH(Структура!$D16,'ИПЦ raw'!$A:$A,0)) -> 100.59 | Z16: =INDEX('ИПЦ raw'!AK:AK, MATCH(Структура!$D16,'ИПЦ raw'!$A:$A,0)) -> 100.84 | AA16: =INDEX('ИПЦ raw'!AL:AL, MATCH(Структура!$D16,'ИПЦ raw'!$A:$A,0)) -> 99.85 | AB16: =INDEX('ИПЦ raw'!AM:AM, MATCH(Структура!$D16,'ИПЦ raw'!$A:$A,0)) -> 100.44 | AC16: =INDEX('ИПЦ raw'!AN:AN, MATCH(Структура!$D16,'ИПЦ raw'!$A:$A,0)) -> 100.28 | AD16: =INDEX('ИПЦ raw'!AO:AO, MATCH(Структура!$D16,'ИПЦ raw'!$A:$A,0)) -> 99.93 | AE16: =INDEX('ИПЦ raw'!AP:AP, MATCH(Структура!$D16,'ИПЦ raw'!$A:$A,0)) -> 99.74 | AG16: =INDEX('2025'!$C:$C,MATCH(Структура!C16,'2025'!$B:$B,0)) -> 0.602 | AH16: =AG16*P16/100 -> 0.600194 | AI16: =AH16*Q16/100 -> 0.60271481 | AJ16: =AI16*R16/100 -> 0.60416133 | AK16: =AJ16*S16/100 -> 0.60488632 | AL16: =AK16*T16/100 -> 0.6060961 | AM16: =AL16*U16/100 -> 0.60942963 | AN16: =AM16*V16/100 -> 0.61058754 | AO16: =AN16*W16/100 -> 0.60948848 | ... AR16: =AQ16*Z16/100 -> 0.62262384 | AS16: =J16 -> 0.604 | AT16: =AS16*AB16/100 -> 0.6066576 | AU16: =AT16*AC16/100 -> 0.60835624 | AV16: =AU16*AD16/100 -> 0.60793039 | AW16: =AV16*AE16/100 -> 0.60634977
A17: Мясокопчености, кг | B17: =A17 -> Мясокопчености, кг | C17: =A17 -> Мясокопчености, кг | D17: =C17 -> Мясокопчености, кг | E17: =INDEX(БИПЦ_НДС!$D:$D,MATCH(Структура!A17,БИПЦ_НДС!$B:$B,0)) -> 20 | F17: Проды | G17: 1 | H17: 1 | I17: 0 | J17: =INDEX('2026'!$C:$C,MATCH(Структура!B17,'2026'!$B:$B,0)) -> 0.402 | K17: =INDEX('2025'!$C:$C,MATCH(Структура!C17,'2025'!$B:$B,0)) -> 0.394 | L17: 1 | M17: 1 | N17: =INDEX(MoM!B:B,MATCH(Структура!A17,MoM!J:J,0)) -> 1 | P17: =INDEX('ИПЦ raw'!AA:AA, MATCH(Структура!$D17,'ИПЦ raw'!$A:$A,0)) -> 100.62 | Q17: =INDEX('ИПЦ raw'!AB:AB, MATCH(Структура!$D17,'ИПЦ raw'!$A:$A,0)) -> 100.58 | R17: =INDEX('ИПЦ raw'!AC:AC, MATCH(Структура!$D17,'ИПЦ raw'!$A:$A,0)) -> 100.96 | S17: =INDEX('ИПЦ raw'!AD:AD, MATCH(Структура!$D17,'ИПЦ raw'!$A:$A,0)) -> 100.15 | T17: =INDEX('ИПЦ raw'!AE:AE, MATCH(Структура!$D17,'ИПЦ raw'!$A:$A,0)) -> 100.45 | U17: =INDEX('ИПЦ raw'!AF:AF, MATCH(Структура!$D17,'ИПЦ raw'!$A:$A,0)) -> 100.28 | V17: =INDEX('ИПЦ raw'!AG:AG, MATCH(Структура!$D17,'ИПЦ raw'!$A:$A,0)) -> 100.42 | W17: =INDEX('ИПЦ raw'!AH:AH, MATCH(Структура!$D17,'ИПЦ raw'!$A:$A,0)) -> 100.47 | X17: =INDEX('ИПЦ raw'!AI:AI, MATCH(Структура!$D17,'ИПЦ raw'!$A:$A,0)) -> 100.84 | Y17: =INDEX('ИПЦ raw'!AJ:AJ, MATCH(Структура!$D17,'ИПЦ raw'!$A:$A,0)) -> 101.1 | Z17: =INDEX('ИПЦ raw'!AK:AK, MATCH(Структура!$D17,'ИПЦ raw'!$A:$A,0)) -> 100.4 | AA17: =INDEX('ИПЦ raw'!AL:AL, MATCH(Структура!$D17,'ИПЦ raw'!$A:$A,0)) -> 100.57 | AB17: =INDEX('ИПЦ raw'!AM:AM, MATCH(Структура!$D17,'ИПЦ raw'!$A:$A,0)) -> 100.59 | AC17: =INDEX('ИПЦ raw'!AN:AN, MATCH(Структура!$D17,'ИПЦ raw'!$A:$A,0)) -> 100.2 | AD17: =INDEX('ИПЦ raw'!AO:AO, MATCH(Структура!$D17,'ИПЦ raw'!$A:$A,0)) -> 100.07 | AE17: =INDEX('ИПЦ raw'!AP:AP, MATCH(Структура!$D17,'ИПЦ raw'!$A:$A,0)) -> 99.69 | AG17: =INDEX('2025'!$C:$C,MATCH(Структура!C17,'2025'!$B:$B,0)) -> 0.394 | AH17: =AG17*P17/100 -> 0.3964428 | AI17: =AH17*Q17/100 -> 0.39874217 | AJ17: =AI17*R17/100 -> 0.40257009 | AK17: =AJ17*S17/100 -> 0.40317395 | AL17: =AK17*T17/100 -> 0.40498823 | AM17: =AL17*U17/100 -> 0.4061222 | AN17: =AM17*V17/100 -> 0.40782791 | AO17: =AN17*W17/100 -> 0.4097447 | ... AR17: =AQ17*Z17/100 -> 0.41940254 | AS17: =J17 -> 0.402 | AT17: =AS17*AB17/100 -> 0.4043718 | AU17: =AT17*AC17/100 -> 0.40518054 | AV17: =AU17*AD17/100 -> 0.40546417 | AW17: =AV17*AE17/100 -> 0.40420723
A18: Кулинарные изделия из птицы, кг | B18: =A18 -> Кулинарные изделия из птицы, кг | C18: =A18 -> Кулинарные изделия из птицы, кг | D18: =C18 -> Кулинарные изделия из птицы, кг | E18: =INDEX(БИПЦ_НДС!$D:$D,MATCH(Структура!A18,БИПЦ_НДС!$B:$B,0)) -> 10 | F18: Проды | G18: 1 | H18: 1 | I18: 0 | J18: =INDEX('2026'!$C:$C,MATCH(Структура!B18,'2026'!$B:$B,0)) -> 0.17 | K18: =INDEX('2025'!$C:$C,MATCH(Структура!C18,'2025'!$B:$B,0)) -> 0.185 | L18: 1 | M18: 1 | N18: =INDEX(MoM!B:B,MATCH(Структура!A18,MoM!J:J,0)) -> 1 | P18: =INDEX('ИПЦ raw'!AA:AA, MATCH(Структура!$D18,'ИПЦ raw'!$A:$A,0)) -> 101.17 | Q18: =INDEX('ИПЦ raw'!AB:AB, MATCH(Структура!$D18,'ИПЦ raw'!$A:$A,0)) -> 101.09 | R18: =INDEX('ИПЦ raw'!AC:AC, MATCH(Структура!$D18,'ИПЦ raw'!$A:$A,0)) -> 100.66 | S18: =INDEX('ИПЦ raw'!AD:AD, MATCH(Структура!$D18,'ИПЦ raw'!$A:$A,0)) -> 100.5 | T18: =INDEX('ИПЦ raw'!AE:AE, MATCH(Структура!$D18,'ИПЦ raw'!$A:$A,0)) -> 100.91 | U18: =INDEX('ИПЦ raw'!AF:AF, MATCH(Структура!$D18,'ИПЦ raw'!$A:$A,0)) -> 100.36 | V18: =INDEX('ИПЦ raw'!AG:AG, MATCH(Структура!$D18,'ИПЦ raw'!$A:$A,0)) -> 100.51 | W18: =INDEX('ИПЦ raw'!AH:AH, MATCH(Структура!$D18,'ИПЦ raw'!$A:$A,0)) -> 100.05 | X18: =INDEX('ИПЦ raw'!AI:AI, MATCH(Структура!$D18,'ИПЦ raw'!$A:$A,0)) -> 100.52 | Y18: =INDEX('ИПЦ raw'!AJ:AJ, MATCH(Структура!$D18,'ИПЦ raw'!$A:$A,0)) -> 100.61 | Z18: =INDEX('ИПЦ raw'!AK:AK, MATCH(Структура!$D18,'ИПЦ raw'!$A:$A,0)) -> 100.71 | AA18: =INDEX('ИПЦ raw'!AL:AL, MATCH(Структура!$D18,'ИПЦ raw'!$A:$A,0)) -> 100.64 | AB18: =INDEX('ИПЦ raw'!AM:AM, MATCH(Структура!$D18,'ИПЦ raw'!$A:$A,0)) -> 100.28 | AC18: =INDEX('ИПЦ raw'!AN:AN, MATCH(Структура!$D18,'ИПЦ raw'!$A:$A,0)) -> 100.26 | AD18: =INDEX('ИПЦ raw'!AO:AO, MATCH(Структура!$D18,'ИПЦ raw'!$A:$A,0)) -> 100.36 | AE18: =INDEX('ИПЦ raw'!AP:AP, MATCH(Структура!$D18,'ИПЦ raw'!$A:$A,0)) -> 100.21 | AG18: =INDEX('2025'!$C:$C,MATCH(Структура!C18,'2025'!$B:$B,0)) -> 0.185 | AH18: =AG18*P18/100 -> 0.1871645 | AI18: =AH18*Q18/100 -> 0.18920459 | AJ18: =AI18*R18/100 -> 0.19045334 | AK18: =AJ18*S18/100 -> 0.19140561 | AL18: =AK18*T18/100 -> 0.1931474 | AM18: =AL18*U18/100 -> 0.19384273 | AN18: =AM18*V18/100 -> 0.19483133 | AO18: =AN18*W18/100 -> 0.19492875 | ... AR18: =AQ18*Z18/100 -> 0.1985373 | AS18: =J18 -> 0.17 | AT18: =AS18*AB18/100 -> 0.170476 | AU18: =AT18*AC18/100 -> 0.17091924 | AV18: =AU18*AD18/100 -> 0.17153455 | AW18: =AV18*AE18/100 -> 0.17189477
A19: Консервы мясные, кг | B19: =A19 -> Консервы мясные, кг | C19: =A19 -> Консервы мясные, кг | D19: =C19 -> Консервы мясные, кг | E19: =INDEX(БИПЦ_НДС!$D:$D,MATCH(Структура!A19,БИПЦ_НДС!$B:$B,0)) -> 10 | F19: Проды | G19: 1 | H19: 1 | I19: 0 | J19: =INDEX('2026'!$C:$C,MATCH(Структура!B19,'2026'!$B:$B,0)) -> 0.129 | K19: =INDEX('2025'!$C:$C,MATCH(Структура!C19,'2025'!$B:$B,0)) -> 0.129 | L19: 1 | M19: 1 | N19: =INDEX(MoM!B:B,MATCH(Структура!A19,MoM!J:J,0)) -> 1 | P19: =INDEX('ИПЦ raw'!AA:AA, MATCH(Структура!$D19,'ИПЦ raw'!$A:$A,0)) -> 100.67 | Q19: =INDEX('ИПЦ raw'!AB:AB, MATCH(Структура!$D19,'ИПЦ raw'!$A:$A,0)) -> 100.29 | R19: =INDEX('ИПЦ raw'!AC:AC, MATCH(Структура!$D19,'ИПЦ raw'!$A:$A,0)) -> 100.58 | S19: =INDEX('ИПЦ raw'!AD:AD, MATCH(Структура!$D19,'ИПЦ raw'!$A:$A,0)) -> 100.8 | T19: =INDEX('ИПЦ raw'!AE:AE, MATCH(Структура!$D19,'ИПЦ raw'!$A:$A,0)) -> 100.74 | U19: =INDEX('ИПЦ raw'!AF:AF, MATCH(Структура!$D19,'ИПЦ raw'!$A:$A,0)) -> 100.73 | V19: =INDEX('ИПЦ raw'!AG:AG, MATCH(Структура!$D19,'ИПЦ raw'!$A:$A,0)) -> 101 | W19: =INDEX('ИПЦ raw'!AH:AH, MATCH(Структура!$D19,'ИПЦ raw'!$A:$A,0)) -> 100.34 | X19: =INDEX('ИПЦ raw'!AI:AI, MATCH(Структура!$D19,'ИПЦ raw'!$A:$A,0)) -> 100.89 | Y19: =INDEX('ИПЦ raw'!AJ:AJ, MATCH(Структура!$D19,'ИПЦ raw'!$A:$A,0)) -> 100.19 | Z19: =INDEX('ИПЦ raw'!AK:AK, MATCH(Структура!$D19,'ИПЦ raw'!$A:$A,0)) -> 100.51 | AA19: =INDEX('ИПЦ raw'!AL:AL, MATCH(Структура!$D19,'ИПЦ raw'!$A:$A,0)) -> 100.53 | AB19: =INDEX('ИПЦ raw'!AM:AM, MATCH(Структура!$D19,'ИПЦ raw'!$A:$A,0)) -> 100.45 | AC19: =INDEX('ИПЦ raw'!AN:AN, MATCH(Структура!$D19,'ИПЦ raw'!$A:$A,0)) -> 100.23 | AD19: =INDEX('ИПЦ raw'!AO:AO, MATCH(Структура!$D19,'ИПЦ raw'!$A:$A,0)) -> 100.31 | AE19: =INDEX('ИПЦ raw'!AP:AP, MATCH(Структура!$D19,'ИПЦ raw'!$A:$A,0)) -> 100.56 | AG19: =INDEX('2025'!$C:$C,MATCH(Структура!C19,'2025'!$B:$B,0)) -> 0.129 | AH19: =AG19*P19/100 -> 0.1298643 | AI19: =AH19*Q19/100 -> 0.13024091 | AJ19: =AI19*R19/100 -> 0.1309963 | AK19: =AJ19*S19/100 -> 0.13204427 | AL19: =AK19*T19/100 -> 0.1330214 | AM19: =AL19*U19/100 -> 0.13399246 | AN19: =AM19*V19/100 -> 0.13533238 | AO19: =AN19*W19/100 -> 0.13579251 | ... AR19: =AQ19*Z19/100 -> 0.1379614 | AS19: =J19 -> 0.129 | AT19: =AS19*AB19/100 -> 0.1295805 | AU19: =AT19*AC19/100 -> 0.12987854 | AV19: =AU19*AD19/100 -> 0.13028116 | AW19: =AV19*AE19/100 -> 0.13101073
A20: Консервы мясные для детского питания, кг | B20: =A20 -> Консервы мясные для детского питания, кг | C20: =A20 -> Консервы мясные для детского питания, кг | D20: =C20 -> Консервы мясные для детского питания, кг | E20: =INDEX(БИПЦ_НДС!$D:$D,MATCH(Структура!A20,БИПЦ_НДС!$B:$B,0)) -> 10 | F20: Проды | G20: 1 | H20: 1 | I20: 0 | J20: =INDEX('2026'!$C:$C,MATCH(Структура!B20,'2026'!$B:$B,0)) -> 0.019 | K20: =INDEX('2025'!$C:$C,MATCH(Структура!C20,'2025'!$B:$B,0)) -> 0.016 | L20: 1 | M20: 1 | N20: =INDEX(MoM!B:B,MATCH(Структура!A20,MoM!J:J,0)) -> 1 | P20: =INDEX('ИПЦ raw'!AA:AA, MATCH(Структура!$D20,'ИПЦ raw'!$A:$A,0)) -> 99.88 | Q20: =INDEX('ИПЦ raw'!AB:AB, MATCH(Структура!$D20,'ИПЦ raw'!$A:$A,0)) -> 102.69 | R20: =INDEX('ИПЦ raw'!AC:AC, MATCH(Структура!$D20,'ИПЦ raw'!$A:$A,0)) -> 100.59 | S20: =INDEX('ИПЦ raw'!AD:AD, MATCH(Структура!$D20,'ИПЦ raw'!$A:$A,0)) -> 100.2 | T20: =INDEX('ИПЦ raw'!AE:AE, MATCH(Структура!$D20,'ИПЦ raw'!$A:$A,0)) -> 99.07 | U20: =INDEX('ИПЦ raw'!AF:AF, MATCH(Структура!$D20,'ИПЦ raw'!$A:$A,0)) -> 99.47 | V20: =INDEX('ИПЦ raw'!AG:AG, MATCH(Структура!$D20,'ИПЦ raw'!$A:$A,0)) -> 99.52 | W20: =INDEX('ИПЦ raw'!AH:AH, MATCH(Структура!$D20,'ИПЦ raw'!$A:$A,0)) -> 101.46 | X20: =INDEX('ИПЦ raw'!AI:AI, MATCH(Структура!$D20,'ИПЦ raw'!$A:$A,0)) -> 100.55 | Y20: =INDEX('ИПЦ raw'!AJ:AJ, MATCH(Структура!$D20,'ИПЦ raw'!$A:$A,0)) -> 99.87 | Z20: =INDEX('ИПЦ raw'!AK:AK, MATCH(Структура!$D20,'ИПЦ raw'!$A:$A,0)) -> 100.84 | AA20: =INDEX('ИПЦ raw'!AL:AL, MATCH(Структура!$D20,'ИПЦ raw'!$A:$A,0)) -> 100.14 | AB20: =INDEX('ИПЦ raw'!AM:AM, MATCH(Структура!$D20,'ИПЦ raw'!$A:$A,0)) -> 101.8 | AC20: =INDEX('ИПЦ raw'!AN:AN, MATCH(Структура!$D20,'ИПЦ raw'!$A:$A,0)) -> 100.36 | AD20: =INDEX('ИПЦ raw'!AO:AO, MATCH(Структура!$D20,'ИПЦ raw'!$A:$A,0)) -> 100.23 | AE20: =INDEX('ИПЦ raw'!AP:AP, MATCH(Структура!$D20,'ИПЦ raw'!$A:$A,0)) -> 100.99 | AG20: =INDEX('2025'!$C:$C,MATCH(Структура!C20,'2025'!$B:$B,0)) -> 0.016 | AH20: =AG20*P20/100 -> 0.0159808 | AI20: =AH20*Q20/100 -> 0.016410684 | AJ20: =AI20*R20/100 -> 0.016507507 | AK20: =AJ20*S20/100 -> 0.016540522 | AL20: =AK20*T20/100 -> 0.016386695 | AM20: =AL20*U20/100 -> 0.016299845 | AN20: =AM20*V20/100 -> 0.016221606 | AO20: =AN20*W20/100 -> 0.016458441 | ... AR20: =AQ20*Z20/100 -> 0.01666628 | AS20: =J20 -> 0.019 | AT20: =AS20*AB20/100 -> 0.019342 | AU20: =AT20*AC20/100 -> 0.019411631 | AV20: =AU20*AD20/100 -> 0.019456278 | AW20: =AV20*AE20/100 -> 0.019648895
A21: Рыба живая и охлажденная, кг | B21: =A21 -> Рыба живая и охлажденная, кг | C21: =A21 -> Рыба живая и охлажденная, кг | D21: =C21 -> Рыба живая и охлажденная, кг | E21: =INDEX(БИПЦ_НДС!$D:$D,MATCH(Структура!A21,БИПЦ_НДС!$B:$B,0)) -> 10 | F21: Проды | G21: 1 | H21: 1 | I21: 0 | J21: =INDEX('2026'!$C:$C,MATCH(Структура!B21,'2026'!$B:$B,0)) -> 0.133 | K21: =INDEX('2025'!$C:$C,MATCH(Структура!C21,'2025'!$B:$B,0)) -> 0.134 | L21: 1 | M21: 1 | N21: =INDEX(MoM!B:B,MATCH(Структура!A21,MoM!J:J,0)) -> 1 | P21: =INDEX('ИПЦ raw'!AA:AA, MATCH(Структура!$D21,'ИПЦ raw'!$A:$A,0)) -> 100.99 | Q21: =INDEX('ИПЦ raw'!AB:AB, MATCH(Структура!$D21,'ИПЦ raw'!$A:$A,0)) -> 101.69 | R21: =INDEX('ИПЦ raw'!AC:AC, MATCH(Структура!$D21,'ИПЦ raw'!$A:$A,0)) -> 100.14 | S21: =INDEX('ИПЦ raw'!AD:AD, MATCH(Структура!$D21,'ИПЦ raw'!$A:$A,0)) -> 101.78 | T21: =INDEX('ИПЦ raw'!AE:AE, MATCH(Структура!$D21,'ИПЦ raw'!$A:$A,0)) -> 101.25 | U21: =INDEX('ИПЦ raw'!AF:AF, MATCH(Структура!$D21,'ИПЦ raw'!$A:$A,0)) -> 101.63 | V21: =INDEX('ИПЦ raw'!AG:AG, MATCH(Структура!$D21,'ИПЦ raw'!$A:$A,0)) -> 101.33 | W21: =INDEX('ИПЦ raw'!AH:AH, MATCH(Структура!$D21,'ИПЦ raw'!$A:$A,0)) -> 100.96 | X21: =INDEX('ИПЦ raw'!AI:AI, MATCH(Структура!$D21,'ИПЦ raw'!$A:$A,0)) -> 100.07 | Y21: =INDEX('ИПЦ raw'!AJ:AJ, MATCH(Структура!$D21,'ИПЦ raw'!$A:$A,0)) -> 100.87 | Z21: =INDEX('ИПЦ raw'!AK:AK, MATCH(Структура!$D21,'ИПЦ raw'!$A:$A,0)) -> 100.23 | AA21: =INDEX('ИПЦ raw'!AL:AL, MATCH(Структура!$D21,'ИПЦ raw'!$A:$A,0)) -> 100.64 | AB21: =INDEX('ИПЦ raw'!AM:AM, MATCH(Структура!$D21,'ИПЦ raw'!$A:$A,0)) -> 100.2 | AC21: =INDEX('ИПЦ raw'!AN:AN, MATCH(Структура!$D21,'ИПЦ raw'!$A:$A,0)) -> 101.16 | AD21: =INDEX('ИПЦ raw'!AO:AO, MATCH(Структура!$D21,'ИПЦ raw'!$A:$A,0)) -> 100.98 | AE21: =INDEX('ИПЦ raw'!AP:AP, MATCH(Структура!$D21,'ИПЦ raw'!$A:$A,0)) -> 100.51 | AG21: =INDEX('2025'!$C:$C,MATCH(Структура!C21,'2025'!$B:$B,0)) -> 0.134 | AH21: =AG21*P21/100 -> 0.1353266 | AI21: =AH21*Q21/100 -> 0.13761362 | AJ21: =AI21*R21/100 -> 0.13780628 | AK21: =AJ21*S21/100 -> 0.14025923 | AL21: =AK21*T21/100 -> 0.14201247 | AM21: =AL21*U21/100 -> 0.14432727 | AN21: =AM21*V21/100 -> 0.14624683 | AO21: =AN21*W21/100 -> 0.1476508 | ... AR21: =AQ21*Z21/100 -> 0.1493824 | AS21: =J21 -> 0.133 | AT21: =AS21*AB21/100 -> 0.133266 | AU21: =AT21*AC21/100 -> 0.13481189 | AV21: =AU21*AD21/100 -> 0.13613304 | AW21: =AV21*AE21/100 -> 0.13682732
... A23: Соленые и копченые деликатесные продукты из рыбы, кг | B23: =A23 -> Соленые и копченые деликатесные продукты из рыбы, кг | C23: =A23 -> Соленые и копченые деликатесные продукты из рыбы, кг | D23: =C23 -> Соленые и копченые деликатесные продукты из рыбы, кг | E23: =INDEX(БИПЦ_НДС!$D:$D,MATCH(Структура!A23,БИПЦ_НДС!$B:$B,0)) -> 20 | F23: Проды | G23: 1 | H23: 1 | I23: 0 | J23: =INDEX('2026'!$C:$C,MATCH(Структура!B23,'2026'!$B:$B,0)) -> 0.159 | K23: =INDEX('2025'!$C:$C,MATCH(Структура!C23,'2025'!$B:$B,0)) -> 0.147 | L23: 1 | M23: 1 | N23: =INDEX(MoM!B:B,MATCH(Структура!A23,MoM!J:J,0)) -> 1 | P23: =INDEX('ИПЦ raw'!AA:AA, MATCH(Структура!$D23,'ИПЦ raw'!$A:$A,0)) -> 101.2 | Q23: =INDEX('ИПЦ raw'!AB:AB, MATCH(Структура!$D23,'ИПЦ raw'!$A:$A,0)) -> 101.44 | R23: =INDEX('ИПЦ raw'!AC:AC, MATCH(Структура!$D23,'ИПЦ raw'!$A:$A,0)) -> 101.39 | S23: =INDEX('ИПЦ raw'!AD:AD, MATCH(Структура!$D23,'ИПЦ raw'!$A:$A,0)) -> 100.63 | T23: =INDEX('ИПЦ raw'!AE:AE, MATCH(Структура!$D23,'ИПЦ raw'!$A:$A,0)) -> 100.38 | U23: =INDEX('ИПЦ raw'!AF:AF, MATCH(Структура!$D23,'ИПЦ raw'!$A:$A,0)) -> 100.02 | V23: =INDEX('ИПЦ raw'!AG:AG, MATCH(Структура!$D23,'ИПЦ raw'!$A:$A,0)) -> 100.3 | W23: =INDEX('ИПЦ raw'!AH:AH, MATCH(Структура!$D23,'ИПЦ raw'!$A:$A,0)) -> 100.08 | X23: =INDEX('ИПЦ raw'!AI:AI, MATCH(Структура!$D23,'ИПЦ raw'!$A:$A,0)) -> 100.15 | Y23: =INDEX('ИПЦ raw'!AJ:AJ, MATCH(Структура!$D23,'ИПЦ raw'!$A:$A,0)) -> 100.05 | Z23: =INDEX('ИПЦ raw'!AK:AK, MATCH(Структура!$D23,'ИПЦ raw'!$A:$A,0)) -> 99.79 | AA23: =INDEX('ИПЦ raw'!AL:AL, MATCH(Структура!$D23,'ИПЦ raw'!$A:$A,0)) -> 99.85 | AB23: =INDEX('ИПЦ raw'!AM:AM, MATCH(Структура!$D23,'ИПЦ raw'!$A:$A,0)) -> 100.38 | AC23: =INDEX('ИПЦ raw'!AN:AN, MATCH(Структура!$D23,'ИПЦ raw'!$A:$A,0)) -> 100.21 | AD23: =INDEX('ИПЦ raw'!AO:AO, MATCH(Структура!$D23,'ИПЦ raw'!$A:$A,0)) -> 99.98 | AE23: =INDEX('ИПЦ raw'!AP:AP, MATCH(Структура!$D23,'ИПЦ raw'!$A:$A,0)) -> 100.6 | AG23: =INDEX('2025'!$C:$C,MATCH(Структура!C23,'2025'!$B:$B,0)) -> 0.147 | AH23: =AG23*P23/100 -> 0.148764 | AI23: =AH23*Q23/100 -> 0.1509062 | AJ23: =AI23*R23/100 -> 0.1530038 | AK23: =AJ23*S23/100 -> 0.15396772 | AL23: =AK23*T23/100 -> 0.1545528 | AM23: =AL23*U23/100 -> 0.15458371 | AN23: =AM23*V23/100 -> 0.15504746 | AO23: =AN23*W23/100 -> 0.1551715 | ... AR23: =AQ23*Z23/100 -> 0.15515545 | AS23: =J23 -> 0.159 | AT23: =AS23*AB23/100 -> 0.1596042 | AU23: =AT23*AC23/100 -> 0.15993937 | AV23: =AU23*AD23/100 -> 0.15990738 | AW23: =AV23*AE23/100 -> 0.16086683
A24: Икра лососевых рыб отечественная, кг | B24: =A24 -> Икра лососевых рыб отечественная, кг | C24: Икра лососевых рыб, отечественная, кг | D24: Икра лососевых рыб отечественная, кг | E24: =INDEX(БИПЦ_НДС!$D:$D,MATCH(Структура!A24,БИПЦ_НДС!$B:$B,0)) -> 20 | F24: Проды | G24: 1 | H24: 1 | I24: 0 | J24: =INDEX('2026'!$C:$C,MATCH(Структура!B24,'2026'!$B:$B,0)) -> 0.161 | K24: =INDEX('2025'!$C:$C,MATCH(Структура!C24,'2025'!$B:$B,0)) -> 0.142 | L24: 1 | M24: 1 | N24: =INDEX(MoM!B:B,MATCH(Структура!A24,MoM!J:J,0)) -> 1 | P24: =INDEX('ИПЦ raw'!AA:AA, MATCH(Структура!$D24,'ИПЦ raw'!$A:$A,0)) -> 100.92 | Q24: =INDEX('ИПЦ raw'!AB:AB, MATCH(Структура!$D24,'ИПЦ raw'!$A:$A,0)) -> 100.08 | R24: =INDEX('ИПЦ raw'!AC:AC, MATCH(Структура!$D24,'ИПЦ raw'!$A:$A,0)) -> 100.63 | S24: =INDEX('ИПЦ raw'!AD:AD, MATCH(Структура!$D24,'ИПЦ raw'!$A:$A,0)) -> 100.14 | T24: =INDEX('ИПЦ raw'!AE:AE, MATCH(Структура!$D24,'ИПЦ raw'!$A:$A,0)) -> 100.08 | U24: =INDEX('ИПЦ raw'!AF:AF, MATCH(Структура!$D24,'ИПЦ raw'!$A:$A,0)) -> 99.64 | V24: =INDEX('ИПЦ raw'!AG:AG, MATCH(Структура!$D24,'ИПЦ raw'!$A:$A,0)) -> 100.4 | W24: =INDEX('ИПЦ raw'!AH:AH, MATCH(Структура!$D24,'ИПЦ raw'!$A:$A,0)) -> 99.14 | X24: =INDEX('ИПЦ raw'!AI:AI, MATCH(Структура!$D24,'ИПЦ raw'!$A:$A,0)) -> 98.77 | Y24: =INDEX('ИПЦ raw'!AJ:AJ, MATCH(Структура!$D24,'ИПЦ raw'!$A:$A,0)) -> 98.87 | Z24: =INDEX('ИПЦ raw'!AK:AK, MATCH(Структура!$D24,'ИПЦ raw'!$A:$A,0)) -> 100.04 | AA24: =INDEX('ИПЦ raw'!AL:AL, MATCH(Структура!$D24,'ИПЦ raw'!$A:$A,0)) -> 99.52 | AB24: =INDEX('ИПЦ raw'!AM:AM, MATCH(Структура!$D24,'ИПЦ raw'!$A:$A,0)) -> 100.1 | AC24: =INDEX('ИПЦ raw'!AN:AN, MATCH(Структура!$D24,'ИПЦ raw'!$A:$A,0)) -> 99.78 | AD24: =INDEX('ИПЦ raw'!AO:AO, MATCH(Структура!$D24,'ИПЦ raw'!$A:$A,0)) -> 100.24 | AE24: =INDEX('ИПЦ raw'!AP:AP, MATCH(Структура!$D24,'ИПЦ raw'!$A:$A,0)) -> 99.81 | AG24: =INDEX('2025'!$C:$C,MATCH(Структура!C24,'2025'!$B:$B,0)) -> 0.142 | AH24: =AG24*P24/100 -> 0.1433064 | AI24: =AH24*Q24/100 -> 0.14342105 | AJ24: =AI24*R24/100 -> 0.1443246 | AK24: =AJ24*S24/100 -> 0.14452665 | AL24: =AK24*T24/100 -> 0.14464227 | AM24: =AL24*U24/100 -> 0.14412156 | AN24: =AM24*V24/100 -> 0.14469805 | AO24: =AN24*W24/100 -> 0.14345364 | ... AR24: =AQ24*Z24/100 -> 0.14014411 | AS24: =J24 -> 0.161 | AT24: =AS24*AB24/100 -> 0.161161 | AU24: =AT24*AC24/100 -> 0.16080645 | AV24: =AU24*AD24/100 -> 0.16119238 | AW24: =AV24*AE24/100 -> 0.16088612
