Workbook

Sheet БИПЦ_НДС
A1: Совпадение ключей названия | B1: Новое название | C1: Старое основное название | D1: Итог | E1: Базовая ставка
A2: =EXACT(B2,C2) -> TRUE | B2: Говядина (кроме бескостного мяса), кг | C2: Говядина (кроме бескостного мяса), кг | D2: 10 | E2: =IF(D2=20,1,0) -> 0
A3: =EXACT(B3,C3) -> TRUE | B3: Говядина бескостная, кг | C3: Говядина бескостная, кг | D3: 10 | E3: =IF(D3=20,1,0) -> 0
A4: =EXACT(B4,C4) -> TRUE | B4: Свинина (кроме бескостного мяса), кг | C4: Свинина (кроме бескостного мяса), кг | D4: 10 | E4: =IF(D4=20,1,0) -> 0
A5: =EXACT(B5,C5) -> TRUE | B5: Свинина бескостная, кг | C5: Свинина бескостная, кг | D5: 10 | E5: =IF(D5=20,1,0) -> 0
A6: =EXACT(B6,C6) -> TRUE | B6: Баранина (кроме бескостного мяса), кг | C6: Баранина (кроме бескостного мяса), кг | D6: 10 | E6: =IF(D6=20,1,0) -> 0
A7: =EXACT(B7,C7) -> TRUE | B7: Куры охлажденные и мороженые, кг | C7: Куры охлажденные и мороженые, кг | D7: 10 | E7: =IF(D7=20,1,0) -> 0
A8: =EXACT(B8,C8) -> TRUE | B8: Окорочка куриные, кг | C8: Окорочка куриные, кг | D8: 10 | E8: =IF(D8=20,1,0) -> 0
A9: =EXACT(B9,C9) -> TRUE | B9: Мясо индейки, кг | C9: Мясо индейки, кг | D9: 10 | E9: =IF(D9=20,1,0) -> 0
A10: =EXACT(B10,C10) -> TRUE | B10: Печень говяжья, свиная, кг | C10: Печень говяжья, свиная, кг | D10: 10 | E10: =IF(D10=20,1,0) -> 0
A11: =EXACT(B11,C11) -> TRUE | B11: Фарш мясной, кг | C11: Фарш мясной, кг | D11: 10 | E11: =IF(D11=20,1,0) -> 0
A12: =EXACT(B12,C12) -> TRUE | B12: Пельмени, манты, равиоли, кг | C12: Пельмени, манты, равиоли, кг | D12: 10 | E12: =IF(D12=20,1,0) -> 0
A13: =EXACT(B13,C13) -> TRUE | B13: Сосиски, сардельки, кг | C13: Сосиски, сардельки, кг | D13: 10 | E13: =IF(D13=20,1,0) -> 0
... A394: =EXACT(B394,C394) -> TRUE | B394: Музеи и выставки, билет | C394: Музеи и выставки, билет | D394: 0 | E394: =IF(D394=20,1,0) -> 0
A395: =EXACT(B395,C395) -> TRUE | B395: Поездка на отдых в Турцию, поездка | C395: Поездка на отдых в Турцию, поездка | E395: =IF(D395=20,1,0) -> 0
A396: =EXACT(B396,C396) -> TRUE | B396: Поездка на отдых в ОАЭ, поездка | C396: Поездка на отдых в ОАЭ, поездка | E396: =IF(D396=20,1,0) -> 0
A397: =EXACT(B397,C397) -> TRUE | B397: Поездка на отдых в Египет, поездка | C397: Поездка на отдых в Египет, поездка | E397: =IF(D397=20,1,0) -> 0
A398: =EXACT(B398,C398) -> TRUE | B398: Поездка в Беларусь, поездка | C398: Поездка в Беларусь, поездка | E398: =IF(D398=20,1,0) -> 0
A399: =EXACT(B399,C399) -> TRUE | B399: Поездки в страны Закавказья, поездка | C399: Поездки в страны Закавказья, поездка | E399: =IF(D399=20,1,0) -> 0
A400: =EXACT(B400,C400) -> TRUE | B400: Поездки в отдельные страны Средней Азии, поездка | C400: Поездки в отдельные страны Средней Азии, поездка | E400: =IF(D400=20,1,0) -> 0
A401: =EXACT(B401,C401) -> TRUE | B401: Поездки в отдельные страны Юго-Восточной Азии, поездка | C401: Поездки в отдельные страны Юго-Восточной Азии, поездка | E401: =IF(D401=20,1,0) -> 0
A402: =EXACT(B402,C402) -> TRUE | B402: Экскурсия автобусная, час | C402: Экскурсия автобусная, час | D402: 0 | E402: =IF(D402=20,1,0) -> 0
A403: =EXACT(B403,C403) -> FALSE | B403: Экскурсионные туры по России, экскурсия | C403: Экскурсионные туры по России, поездка | D403: 0 | E403: =IF(D403=20,1,0) -> 0
A404: =EXACT(B404,C404) -> TRUE | B404: Поездка на отдых на Черноморское побережье России, поездка | C404: Поездка на отдых на Черноморское побережье России, поездка | E404: =IF(D404=20,1,0) -> 0
A405: =EXACT(B405,C405) -> TRUE | B405: Санаторий, день | C405: Санаторий, день | E405: =IF(D405=20,1,0) -> 0
A406: =EXACT(B406,C406) -> TRUE | B406: Дом отдыха, пансионат, день | C406: Дом отдыха, пансионат, день | E406: =IF(D406=20,1,0) -> 0
A407: =EXACT(B407,C407) -> TRUE | B407: Первичный консультативный прием у врача специалиста, посещение | C407: Первичный консультативный прием у врача специалиста, посещение | D407: 0 | E407: =IF(D407=20,1,0) -> 0
A408: =EXACT(B408,C408) -> TRUE | B408: Ультразвуковое исследование брюшной полости, исследование | C408: Ультразвуковое исследование брюшной полости, исследование | D408: 0 | E408: =IF(D408=20,1,0) -> 0
A409: =EXACT(B409,C409) -> TRUE | B409: Диагностика на магнитно-резонансном или компьютерном томографе, услуга | C409: Диагностика на магнитно-резонансном или компьютерном томографе, услуга | D409: 0 | E409: =IF(D409=20,1,0) -> 0
A410: =EXACT(B410,C410) -> TRUE | B410: Гастроскопия (ФГДС, ЭГДС), услуга | C410: Гастроскопия (ФГДС, ЭГДС), услуга | D410: 0 | E410: =IF(D410=20,1,0) -> 0
A411: =EXACT(B411,C411) -> TRUE | B411: Физиотерапевтическое лечение, процедура | C411: Физиотерапевтическое лечение, процедура | D411: 0 | E411: =IF(D411=20,1,0) -> 0
A412: =EXACT(B412,C412) -> TRUE | B412: Общий анализ крови, анализ | C412: Общий анализ крови, анализ | D412: 0 | E412: =IF(D412=20,1,0) -> 0
A413: =EXACT(B413,C413) -> TRUE | B413: Пребывание пациента в круглосуточном стационаре, койко-день | C413: Пребывание пациента в круглосуточном стационаре, койко-день | D413: 0 | E413: =IF(D413=20,1,0) -> 0
A414: =EXACT(B414,C414) -> TRUE | B414: Первичный консультативный осмотр больного у стоматолога, посещение | C414: Первичный консультативный осмотр больного у стоматолога, посещение | D414: 0 | E414: =IF(D414=20,1,0) -> 0
A415: =EXACT(B415,C415) -> TRUE | B415: Удаление зуба под местным обезболиванием, удаление | C415: Удаление зуба под местным обезболиванием, удаление | D415: 0 | E415: =IF(D415=20,1,0) -> 0
A416: =EXACT(B416,C416) -> TRUE | B416: Восстановление зуба пломбой, услуга | C416: Восстановление зуба пломбой, услуга | D416: 0 | E416: =IF(D416=20,1,0) -> 0
A417: =EXACT(B417,C417) -> TRUE | B417: Изготовление съёмного зубного протеза, протез | C417: Изготовление съёмного зубного протеза, протез | D417: 0 | E417: =IF(D417=20,1,0) -> 0
A418: =EXACT(B418,C418) -> TRUE | B418: Изготовление коронки, шт. | C418: Изготовление коронки, шт. | D418: 0 | E418: =IF(D418=20,1,0) -> 0
... A433: =EXACT(B433,C433) -> TRUE | B433: Пользование общественным туалетом, посещение | C433: Пользование общественным туалетом, посещение | D433: 20 | E433: =IF(D433=20,1,0) -> 1
B437: Для маски: https://cntd.ru/news/read/vvoz-i-prodaja-tekstilnyh-masok-obschego-polzovaniya-daje-esli-oni-ispolzuutsya-v-kachestve-siz-dlya-borby-s-koronavirusnoy-infekciey-oblagautsya-nds-po-stavke-20

Sheet Структура
A1: Новое название | B1: Название для поиска 2026 | C1: Название для поиска 2025 | D1: Название для поиска ИПЦ | E1: НДС | F1: Тип | G1: БИПЦ 2026 | H1: БИПЦ 2025 | I1: Туризм и общепит | J1: ИПЦ 2026 | K1: ИПЦ 2025 | L1: Учитывать
A2: Говядина (кроме бескостного мяса), кг | B2: =A2 -> Говядина (кроме бескостного мяса), кг | C2: =A2 -> Говядина (кроме бескостного мяса), кг | D2: =C2 -> Говядина (кроме бескостного мяса), кг | E2: =INDEX(БИПЦ_НДС!$D:$D,MATCH(Структура!A2,БИПЦ_НДС!$B:$B,0)) -> 10 | F2: Проды | G2: 1 | H2: 1 | I2: 0 | J2: 1 | K2: 1 | L2: 0
A3: Говядина бескостная, кг | B3: =A3 -> Говядина бескостная, кг | C3: =A3 -> Говядина бескостная, кг | D3: =C3 -> Говядина бескостная, кг | E3: =INDEX(БИПЦ_НДС!$D:$D,MATCH(Структура!A3,БИПЦ_НДС!$B:$B,0)) -> 10 | F3: Проды | G3: 1 | H3: 1 | I3: 0 | J3: 1 | K3: 1 | L3: =INDEX(MoM!B:B,MATCH(Структура!A3,MoM!K:K,0)) -> 1
A4: Свинина (кроме бескостного мяса), кг | B4: =A4 -> Свинина (кроме бескостного мяса), кг | C4: =A4 -> Свинина (кроме бескостного мяса), кг | D4: =C4 -> Свинина (кроме бескостного мяса), кг | E4: =INDEX(БИПЦ_НДС!$D:$D,MATCH(Структура!A4,БИПЦ_НДС!$B:$B,0)) -> 10 | F4: Проды | G4: 1 | H4: 1 | I4: 0 | J4: 1 | K4: 1 | L4: =INDEX(MoM!B:B,MATCH(Структура!A4,MoM!K:K,0)) -> 1
A5: Свинина бескостная, кг | B5: =A5 -> Свинина бескостная, кг | C5: =A5 -> Свинина бескостная, кг | D5: =C5 -> Свинина бескостная, кг | E5: =INDEX(БИПЦ_НДС!$D:$D,MATCH(Структура!A5,БИПЦ_НДС!$B:$B,0)) -> 10 | F5: Проды | G5: 1 | H5: 1 | I5: 0 | J5: 1 | K5: 1 | L5: =INDEX(MoM!B:B,MATCH(Структура!A5,MoM!K:K,0)) -> 1
A6: Баранина (кроме бескостного мяса), кг | B6: =A6 -> Баранина (кроме бескостного мяса), кг | C6: =A6 -> Баранина (кроме бескостного мяса), кг | D6: =C6 -> Баранина (кроме бескостного мяса), кг | E6: =INDEX(БИПЦ_НДС!$D:$D,MATCH(Структура!A6,БИПЦ_НДС!$B:$B,0)) -> 10 | F6: Проды | G6: 1 | H6: 1 | I6: 0 | J6: 1 | K6: 1 | L6: =INDEX(MoM!B:B,MATCH(Структура!A6,MoM!K:K,0)) -> 1
A7: Куры охлажденные и мороженые, кг | B7: =A7 -> Куры охлажденные и мороженые, кг | C7: =A7 -> Куры охлажденные и мороженые, кг | D7: =C7 -> Куры охлажденные и мороженые, кг | E7: =INDEX(БИПЦ_НДС!$D:$D,MATCH(Структура!A7,БИПЦ_НДС!$B:$B,0)) -> 10 | F7: Проды | G7: 1 | H7: 1 | I7: 0 | J7: 1 | K7: 1 | L7: =INDEX(MoM!B:B,MATCH(Структура!A7,MoM!K:K,0)) -> 1
A8: Окорочка куриные, кг | B8: =A8 -> Окорочка куриные, кг | C8: =A8 -> Окорочка куриные, кг | D8: =C8 -> Окорочка куриные, кг | E8: =INDEX(БИПЦ_НДС!$D:$D,MATCH(Структура!A8,БИПЦ_НДС!$B:$B,0)) -> 10 | F8: Проды | G8: 1 | H8: 1 | I8: 0 | J8: 1 | K8: 1 | L8: =INDEX(MoM!B:B,MATCH(Структура!A8,MoM!K:K,0)) -> 1
A9: Мясо индейки, кг | B9: =A9 -> Мясо индейки, кг | C9: =A9 -> Мясо индейки, кг | D9: Мясо индейки, кг | E9: =INDEX(БИПЦ_НДС!$D:$D,MATCH(Структура!A9,БИПЦ_НДС!$B:$B,0)) -> 10 | F9: Проды | G9: 1 | H9: 1 | I9: 0 | J9: 1 | K9: 1 | L9: =INDEX(MoM!B:B,MATCH(Структура!A9,MoM!K:K,0)) -> 0
A10: Печень говяжья, свиная, кг | B10: =A10 -> Печень говяжья, свиная, кг | C10: =A10 -> Печень говяжья, свиная, кг | D10: =C10 -> Печень говяжья, свиная, кг | E10: =INDEX(БИПЦ_НДС!$D:$D,MATCH(Структура!A10,БИПЦ_НДС!$B:$B,0)) -> 10 | F10: Проды | G10: 1 | H10: 1 | I10: 0 | J10: 1 | K10: 1 | L10: =INDEX(MoM!B:B,MATCH(Структура!A10,MoM!K:K,0)) -> 1
A11: Фарш мясной, кг | B11: =A11 -> Фарш мясной, кг | C11: =A11 -> Фарш мясной, кг | D11: =C11 -> Фарш мясной, кг | E11: =INDEX(БИПЦ_НДС!$D:$D,MATCH(Структура!A11,БИПЦ_НДС!$B:$B,0)) -> 10 | F11: Проды | G11: 1 | H11: 1 | I11: 0 | J11: 1 | K11: 1 | L11: =INDEX(MoM!B:B,MATCH(Структура!A11,MoM!K:K,0)) -> 1
A12: Пельмени, манты, равиоли, кг | B12: =A12 -> Пельмени, манты, равиоли, кг | C12: =A12 -> Пельмени, манты, равиоли, кг | D12: =C12 -> Пельмени, манты, равиоли, кг | E12: =INDEX(БИПЦ_НДС!$D:$D,MATCH(Структура!A12,БИПЦ_НДС!$B:$B,0)) -> 10 | F12: Проды | G12: 1 | H12: 1 | I12: 0 | J12: 1 | K12: 1 | L12: =INDEX(MoM!B:B,MATCH(Структура!A12,MoM!K:K,0)) -> 1
A13: Сосиски, сардельки, кг | B13: =A13 -> Сосиски, сардельки, кг | C13: =A13 -> Сосиски, сардельки, кг | D13: =C13 -> Сосиски, сардельки, кг | E13: =INDEX(БИПЦ_НДС!$D:$D,MATCH(Структура!A13,БИПЦ_НДС!$B:$B,0)) -> 10 | F13: Проды | G13: 1 | H13: 1 | I13: 0 | J13: 1 | K13: 1 | L13: =INDEX(MoM!B:B,MATCH(Структура!A13,MoM!K:K,0)) -> 1
A14: Колбаса полукопченая и варено-копченая, кг | B14: =A14 -> Колбаса полукопченая и варено-копченая, кг | C14: =A14 -> Колбаса полукопченая и варено-копченая, кг | D14: =C14 -> Колбаса полукопченая и варено-копченая, кг | E14: =INDEX(БИПЦ_НДС!$D:$D,MATCH(Структура!A14,БИПЦ_НДС!$B:$B,0)) -> 10 | F14: Проды | G14: 1 | H14: 1 | I14: 0 | J14: 1 | K14: 1 | L14: =INDEX(MoM!B:B,MATCH(Структура!A14,MoM!K:K,0)) -> 1
A15: Колбаса сырокопченая, кг | B15: =A15 -> Колбаса сырокопченая, кг | C15: =A15 -> Колбаса сырокопченая, кг | D15: =C15 -> Колбаса сырокопченая, кг | E15: =INDEX(БИПЦ_НДС!$D:$D,MATCH(Структура!A15,БИПЦ_НДС!$B:$B,0)) -> 10 | F15: Проды | G15: 1 | H15: 1 | I15: 0 | J15: 1 | K15: 1 | L15: =INDEX(MoM!B:B,MATCH(Структура!A15,MoM!K:K,0)) -> 1
A16: Колбаса вареная, кг | B16: =A16 -> Колбаса вареная, кг | C16: =A16 -> Колбаса вареная, кг | D16: =C16 -> Колбаса вареная, кг | E16: =INDEX(БИПЦ_НДС!$D:$D,MATCH(Структура!A16,БИПЦ_НДС!$B:$B,0)) -> 10 | F16: Проды | G16: 1 | H16: 1 | I16: 0 | J16: 1 | K16: 1 | L16: =INDEX(MoM!B:B,MATCH(Структура!A16,MoM!K:K,0)) -> 1
A17: Мясокопчености, кг | B17: =A17 -> Мясокопчености, кг | C17: =A17 -> Мясокопчености, кг | D17: =C17 -> Мясокопчености, кг | E17: =INDEX(БИПЦ_НДС!$D:$D,MATCH(Структура!A17,БИПЦ_НДС!$B:$B,0)) -> 20 | F17: Проды | G17: 1 | H17: 1 | I17: 0 | J17: 1 | K17: 1 | L17: =INDEX(MoM!B:B,MATCH(Структура!A17,MoM!K:K,0)) -> 1
A18: Кулинарные изделия из птицы, кг | B18: =A18 -> Кулинарные изделия из птицы, кг | C18: =A18 -> Кулинарные изделия из птицы, кг | D18: =C18 -> Кулинарные изделия из птицы, кг | E18: =INDEX(БИПЦ_НДС!$D:$D,MATCH(Структура!A18,БИПЦ_НДС!$B:$B,0)) -> 10 | F18: Проды | G18: 1 | H18: 1 | I18: 0 | J18: 1 | K18: 1 | L18: =INDEX(MoM!B:B,MATCH(Структура!A18,MoM!K:K,0)) -> 1
A19: Консервы мясные, кг | B19: =A19 -> Консервы мясные, кг | C19: =A19 -> Консервы мясные, кг | D19: =C19 -> Консервы мясные, кг | E19: =INDEX(БИПЦ_НДС!$D:$D,MATCH(Структура!A19,БИПЦ_НДС!$B:$B,0)) -> 10 | F19: Проды | G19: 1 | H19: 1 | I19: 0 | J19: 1 | K19: 1 | L19: =INDEX(MoM!B:B,MATCH(Структура!A19,MoM!K:K,0)) -> 1
A20: Консервы мясные для детского питания, кг | B20: =A20 -> Консервы мясные для детского питания, кг | C20: =A20 -> Консервы мясные для детского питания, кг | D20: =C20 -> Консервы мясные для детского питания, кг | E20: =INDEX(БИПЦ_НДС!$D:$D,MATCH(Структура!A20,БИПЦ_НДС!$B:$B,0)) -> 10 | F20: Проды | G20: 1 | H20: 1 | I20: 0 | J20: 1 | K20: 1 | L20: =INDEX(MoM!B:B,MATCH(Структура!A20,MoM!K:K,0)) -> 0
A21: Рыба живая и охлажденная, кг | B21: =A21 -> Рыба живая и охлажденная, кг | C21: =A21 -> Рыба живая и охлажденная, кг | D21: =C21 -> Рыба живая и охлажденная, кг | E21: =INDEX(БИПЦ_НДС!$D:$D,MATCH(Структура!A21,БИПЦ_НДС!$B:$B,0)) -> 10 | F21: Проды | G21: 1 | H21: 1 | I21: 0 | J21: 1 | K21: 1 | L21: =INDEX(MoM!B:B,MATCH(Структура!A21,MoM!K:K,0)) -> 1
... A23: Соленые и копченые деликатесные продукты из рыбы, кг | B23: =A23 -> Соленые и копченые деликатесные продукты из рыбы, кг | C23: =A23 -> Соленые и копченые деликатесные продукты из рыбы, кг | D23: =C23 -> Соленые и копченые деликатесные продукты из рыбы, кг | E23: =INDEX(БИПЦ_НДС!$D:$D,MATCH(Структура!A23,БИПЦ_НДС!$B:$B,0)) -> 20 | F23: Проды | G23: 1 | H23: 1 | I23: 0 | J23: 1 | K23: 1 | L23: =INDEX(MoM!B:B,MATCH(Структура!A23,MoM!K:K,0)) -> 1
A24: Икра лососевых рыб отечественная, кг | B24: =A24 -> Икра лососевых рыб отечественная, кг | C24: Икра лососевых рыб, отечественная, кг | D24: Икра лососевых рыб отечественная, кг | E24: =INDEX(БИПЦ_НДС!$D:$D,MATCH(Структура!A24,БИПЦ_НДС!$B:$B,0)) -> 20 | F24: Проды | G24: 1 | H24: 1 | I24: 0 | J24: 1 | K24: 1 | L24: =INDEX(MoM!B:B,MATCH(Структура!A24,MoM!K:K,0)) -> 1
A25: Рыба мороженая разделанная (кроме лососевых пород), кг | B25: =A25 -> Рыба мороженая разделанная (кроме лососевых пород), кг | C25: =A25 -> Рыба мороженая разделанная (кроме лососевых пород), кг | D25: =C25 -> Рыба мороженая разделанная (кроме лососевых пород), кг | E25: =INDEX(БИПЦ_НДС!$D:$D,MATCH(Структура!A25,БИПЦ_НДС!$B:$B,0)) -> 10 | F25: Проды | G25: 1 | H25: 1 | I25: 0 | J25: 1 | K25: 1 | L25: =INDEX(MoM!B:B,MATCH(Структура!A25,MoM!K:K,0)) -> 1
A26: Рыба охлажденная и мороженая разделанная лососевых пород, кг | B26: =A26 -> Рыба охлажденная и мороженая разделанная лососевых пород, кг | C26: =A26 -> Рыба охлажденная и мороженая разделанная лососевых пород, кг | D26: =C26 -> Рыба охлажденная и мороженая разделанная лососевых пород, кг | E26: =INDEX(БИПЦ_НДС!$D:$D,MATCH(Структура!A26,БИПЦ_НДС!$B:$B,0)) -> 20 | F26: Проды | G26: 1 | H26: 1 | I26: 0 | J26: 1 | K26: 1 | L26: =INDEX(MoM!B:B,MATCH(Структура!A26,MoM!K:K,0)) -> 1
A27: Рыба мороженая неразделанная, кг | B27: =A27 -> Рыба мороженая неразделанная, кг | C27: =A27 -> Рыба мороженая неразделанная, кг | D27: =C27 -> Рыба мороженая неразделанная, кг | E27: =INDEX(БИПЦ_НДС!$D:$D,MATCH(Структура!A27,БИПЦ_НДС!$B:$B,0)) -> 10 | F27: Проды | G27: 1 | H27: 1 | I27: 0 | J27: 1 | K27: 1 | L27: =INDEX(MoM!B:B,MATCH(Структура!A27,MoM!K:K,0)) -> 1
A28: Филе рыбное, кг | B28: =A28 -> Филе рыбное, кг | C28: =A28 -> Филе рыбное, кг | D28: =C28 -> Филе рыбное, кг | E28: =INDEX(БИПЦ_НДС!$D:$D,MATCH(Структура!A28,БИПЦ_НДС!$B:$B,0)) -> 10 | F28: Проды | G28: 1 | H28: 1 | I28: 0 | J28: 1 | K28: 1 | L28: =INDEX(MoM!B:B,MATCH(Структура!A28,MoM!K:K,0)) -> 1
A29: Креветки мороженые, неразделанные, кг | B29: =A29 -> Креветки мороженые, неразделанные, кг | C29: Креветки мороженые неразделанные, кг | D29: Креветки мороженые, неразделанные, кг | E29: =INDEX(БИПЦ_НДС!$D:$D,MATCH(Структура!A29,БИПЦ_НДС!$B:$B,0)) -> 10 | F29: Проды | G29: 1 | H29: 1 | I29: 0 | J29: 1 | K29: 1 | L29: =INDEX(MoM!B:B,MATCH(Структура!A29,MoM!K:K,0)) -> 0
A30: Кальмары мороженые, кг | B30: =A30 -> Кальмары мороженые, кг | C30: Кальмары мороженые,кг | D30: Кальмары мороженые, кг | E30: =INDEX(БИПЦ_НДС!$D:$D,MATCH(Структура!A30,БИПЦ_НДС!$B:$B,0)) -> 10 | F30: Проды | G30: 1 | H30: 1 | I30: 0 | J30: 1 | K30: 1 | L30: =INDEX(MoM!B:B,MATCH(Структура!A30,MoM!K:K,0)) -> 0
A31: Сельдь соленая, кг | B31: =A31 -> Сельдь соленая, кг | C31: =A31 -> Сельдь соленая, кг | D31: =C31 -> Сельдь соленая, кг | E31: =INDEX(БИПЦ_НДС!$D:$D,MATCH(Структура!A31,БИПЦ_НДС!$B:$B,0)) -> 10 | F31: Проды | G31: 1 | H31: 1 | I31: 0 | J31: 1 | K31: 1 | L31: =INDEX(MoM!B:B,MATCH(Структура!A31,MoM!K:K,0)) -> 1
A32: Филе сельди соленое, кг | B32: =A32 -> Филе сельди соленое, кг | C32: =A32 -> Филе сельди соленое, кг | D32: =C32 -> Филе сельди соленое, кг | E32: =INDEX(БИПЦ_НДС!$D:$D,MATCH(Структура!A32,БИПЦ_НДС!$B:$B,0)) -> 10 | F32: Проды | G32: 1 | H32: 1 | I32: 0 | J32: 1 | K32: 1 | L32: =INDEX(MoM!B:B,MATCH(Структура!A32,MoM!K:K,0)) -> 1
A33: Консервы рыбные натуральные и с добавлением масла, кг | B33: =A33 -> Консервы рыбные натуральные и с добавлением масла, кг | C33: =A33 -> Консервы рыбные натуральные и с добавлением масла, кг | D33: =C33 -> Консервы рыбные натуральные и с добавлением масла, кг | E33: =INDEX(БИПЦ_НДС!$D:$D,MATCH(Структура!A33,БИПЦ_НДС!$B:$B,0)) -> 10 | F33: Проды | G33: 1 | H33: 1 | I33: 0 | J33: 1 | K33: 1 | L33: =INDEX(MoM!B:B,MATCH(Структура!A33,MoM!K:K,0)) -> 1
A34: Консервы рыбные в томатном соусе, кг | B34: =A34 -> Консервы рыбные в томатном соусе, кг | C34: =A34 -> Консервы рыбные в томатном соусе, кг | D34: =C34 -> Консервы рыбные в томатном соусе, кг | E34: =INDEX(БИПЦ_НДС!$D:$D,MATCH(Структура!A34,БИПЦ_НДС!$B:$B,0)) -> 10 | F34: Проды | G34: 1 | H34: 1 | I34: 0 | J34: 1 | K34: 1 | L34: =INDEX(MoM!B:B,MATCH(Структура!A34,MoM!K:K,0)) -> 1
A35: Масло сливочное, кг | B35: =A35 -> Масло сливочное, кг | C35: =A35 -> Масло сливочное, кг | D35: =C35 -> Масло сливочное, кг | E35: =INDEX(БИПЦ_НДС!$D:$D,MATCH(Структура!A35,БИПЦ_НДС!$B:$B,0)) -> 10 | F35: Проды | G35: 1 | H35: 1 | I35: 0 | J35: 1 | K35: 1 | L35: =INDEX(MoM!B:B,MATCH(Структура!A35,MoM!K:K,0)) -> 1
A36: Масло подсолнечное, л | B36: =A36 -> Масло подсолнечное, л | C36: =A36 -> Масло подсолнечное, л | D36: =C36 -> Масло подсолнечное, л | E36: =INDEX(БИПЦ_НДС!$D:$D,MATCH(Структура!A36,БИПЦ_НДС!$B:$B,0)) -> 10 | F36: Проды | G36: 1 | H36: 1 | I36: 0 | J36: 1 | K36: 1 | L36: =INDEX(MoM!B:B,MATCH(Структура!A36,MoM!K:K,0)) -> 1
A37: Масло оливковое, л | B37: =A37 -> Масло оливковое, л | C37: =A37 -> Масло оливковое, л | D37: =C37 -> Масло оливковое, л | E37: =INDEX(БИПЦ_НДС!$D:$D,MATCH(Структура!A37,БИПЦ_НДС!$B:$B,0)) -> 10 | F37: Проды | G37: 1 | H37: 1 | I37: 0 | J37: 1 | K37: 1 | L37: =INDEX(MoM!B:B,MATCH(Структура!A37,MoM!K:K,0)) -> 1
A38: Маргарин, кг | B38: =A38 -> Маргарин, кг | C38: =A38 -> Маргарин, кг | D38: =C38 -> Маргарин, кг | E38: =INDEX(БИПЦ_НДС!$D:$D,MATCH(Структура!A38,БИПЦ_НДС!$B:$B,0)) -> 10 | F38: Проды | G38: 1 | H38: 1 | I38: 0 | J38: 1 | K38: 1 | L38: =INDEX(MoM!B:B,MATCH(Структура!A38,MoM!K:K,0)) -> 1
A39: Молоко питьевое цельное пастеризованное 2,5-3,2% жирности, л | B39: =A39 -> Молоко питьевое цельное пастеризованное 2,5-3,2% жирности, л | C39: =A39 -> Молоко питьевое цельное пастеризованное 2,5-3,2% жирности, л | D39: =C39 -> Молоко питьевое цельное пастеризованное 2,5-3,2% жирности, л | E39: =INDEX(БИПЦ_НДС!$D:$D,MATCH(Структура!A39,БИПЦ_НДС!$B:$B,0)) -> 10 | F39: Проды | G39: 1 | H39: 1 | I39: 0 | J39: 1 | K39: 1 | L39: =INDEX(MoM!B:B,MATCH(Структура!A39,MoM!K:K,0)) -> 1
A40: Молоко питьевое цельное ультрапастеризованное 2,5-3,2% жирности, л | B40: =A40 -> Молоко питьевое цельное ультрапастеризованное 2,5-3,2% жирности, л | C40: =A40 -> Молоко питьевое цельное ультрапастеризованное 2,5-3,2% жирности, л | D40: =C40 -> Молоко питьевое цельное ультрапастеризованное 2,5-3,2% жирности, л | E40: =INDEX(БИПЦ_НДС!$D:$D,MATCH(Структура!A40,БИПЦ_НДС!$B:$B,0)) -> 10 | F40: Проды | G40: 1 | H40: 1 | I40: 0 | J40: 1 | K40: 1 | L40: =INDEX(MoM!B:B,MATCH(Структура!A40,MoM!K:K,0)) -> 0
A41: Молоко питьевое цельное пастеризованное более 3,2% жирности, л | B41: =A41 -> Молоко питьевое цельное пастеризованное более 3,2% жирности, л | C41: =A41 -> Молоко питьевое цельное пастеризованное более 3,2% жирности, л | D41: =C41 -> Молоко питьевое цельное пастеризованное более 3,2% жирности, л | E41: =INDEX(БИПЦ_НДС!$D:$D,MATCH(Структура!A41,БИПЦ_НДС!$B:$B,0)) -> 10 | F41: Проды | G41: 1 | H41: 1 | I41: 0 | J41: 1 | K41: 1 | L41: =INDEX(MoM!B:B,MATCH(Структура!A41,MoM!K:K,0)) -> 0
...

Sheet Сводная
E2: Эффекты | L2: Вклад в ИПЦ | T2: СУММ эффект
B3: Вес янв25 | C3: Вес янв26 | D3: Доля по базовой | E3: 45931 | F3: 45962 | G3: 45992 | H3: 46023 | I3: 46054 | J3: 46082 | K3: 46113 | L3: 45931 | M3: 45962 | N3: 45992 | O3: 46023 | P3: 46054 | Q3: 46082 | R3: 46113 | S3: Накоп
A4: БИПЦ | B4: 71.169 | C4: 71.421 | D4: 0.57474692 | E4: 0.011510219 | F4: -0.011573879 | G4: 0.021567031 | H4: 0.20742507 | I4: 0.05447193 | J4: 0 | K4: 0 | L4: =E4*$C4*$D4/100 -> 0.00472483 | M4: =F4*$C4*$D4/100 -> -0.0047509617 | N4: =G4*$C4*$D4/100 -> 0.0088530505 | O4: =H4*$C4*$D4/100 -> 0.085145916 | P4: =I4*$C4*$D4/100 -> 0.022360182 | Q4: 0 | R4: 0 | S4: =SUM(L4:R4) -> 0.11633302 | T4: =SUM(E4:K4) -> 0.28340037
A5: Нефтепродукты | B5: 4.643 | C5: 4.801 | D5: 1 | H5: 0.6 | O5: =H5*$C5*$D5/100 -> 0.028806 | S5: =SUM(L5:R5) -> 0.028806 | T5: =SUM(E5:K5) -> 0.6
A6: ЖУ+КУ | B6: 8.006 | C6: 8.042 | D6: 1 | H6: 1.7 | O6: =H6*$C6*$D6/100 -> 0.136714 | S6: =SUM(L6:R6) -> 0.136714 | T6: =SUM(E6:K6) -> 1.7
A7: Прочее | B7: 16.032 | C7: 15.736 | D7: 0.34710219 | E7: =E4 -> 0.011510219 | F7: =F4 -> -0.011573879 | G7: =G4 -> 0.021567031 | H7: =H4 -> 0.20742507 | I7: =I4 -> 0.05447193 | J7: =J4 -> 0 | K7: =K4 -> 0 | L7: =E7*$C7*$D7/100 -> 0.00062868818 | M7: =F7*$C7*$D7/100 -> -0.00063216528 | N7: =G7*$C7*$D7/100 -> 0.0011779912 | O7: =H7*$C7*$D7/100 -> 0.011329557 | P7: =I7*$C7*$D7/100 -> 0.0029752568 | Q7: =J7*$C7*$D7/100 -> 0 | R7: =K7*$C7*$D7/100 -> 0 | S7: =SUM(L7:R7) -> 0.015479328 | T7: =SUM(E7:K7) -> 0.28340037
A8: СУММ | B8: =SUM(B4:B7) -> 99.85 | C8: =SUM(C4:C7) -> 100 | L8: =SUM(L4:L7) -> 0.0053535181 | M8: =SUM(M4:M7) -> -0.005383127 | N8: =SUM(N4:N7) -> 0.010031042 | O8: =SUM(O4:O7) -> 0.26199547 | P8: =SUM(P4:P7) -> 0.025335439 | Q8: =SUM(Q4:Q7) -> 0 | R8: =SUM(R4:R7) -> 0 | S8: =SUM(L8:R8) -> 0.29733235
A10: Вес по базовой в БИПЦ
A11: Вклад в БИПЦ
A12: Вклад в ИПЦ из БИПЦ
A15: Вес наблюдаемых компонент скорректированной БИПЦ | B15: =SUMIFS(Веса!AR2:AR433,MoM!$B$2:$B$433,1) -> 53.298
A16: Число объектов в донорской группе | B16: =COUNTIFS(ToSep17!$B$2:$B$433,1,ToSep17!$D$2:$D$433,1) -> 127
A17: Число объектов в группе воздействия | B17: =COUNTIFS(ToSep17!$B$2:$B$433,1,ToSep17!$C$2:$C$433,1) -> 188
B18: =SUM(B16:B17) -> 315

Sheet MoM
A1: Доступен весь период | B1: Учитывать | C1: Базовая ставка | D1: Льготная ставка | E1: Проды | F1: Непроды | G1: Непроды без одежды | H1: Одежда | I1: Услуги | J1: Название Классификатор 2015 | K1: Название Классификатор 2026 | L1: Название витрина данных Росстата | M1: 42005 | N1: 42036 | O1: 42064 | P1: 42095 | Q1: 42125 | R1: 42156 | S1: 42186 | T1: 42217 | U1: 42248 | V1: 42278 | W1: 42309 | X1: 42339 | Y1: 42370 | Z1: 42401 | AA1: 42430 | AB1: 42461 | AC1: 42491 | AD1: 42522 | AE1: 42552 | AF1: 42583 | AG1: 42614 | AH1: 42644 | AI1: 42675 | AJ1: 42705 | AK1: 42736 | AL1: 42767 | AM1: 42795 | AN1: 42826 | AO1: 42856 | AP1: 42887 | AQ1: 42917 | AR1: 42948 | AS1: 42979 | AT1: 43009 | AU1: 43040 | AV1: 43070 | AW1: 43101 | AX1: 43132 | AY1: 43160 | AZ1: 43191 | BA1: 43221 | BB1: 43252 | BC1: 43282 | BD1: 43313 | BE1: 43344 | BF1: 43374 | BG1: 43405 | BH1: 43435 | BI1: 43466 | BJ1: 43497 | BK1: 43525 | BL1: 43556 | BM1: 43586 | BN1: 43617 | BO1: 43647 | BP1: 43678 | BQ1: 43709 | BR1: 43739 | BS1: 43770 | BT1: 43800
A2: =Веса!A2 -> 1 | B2: =A2 -> 1 | C2: =БИПЦ_НДС!E2 -> 0 | D2: =1-C2 -> 1 | E2: 1 | F2: 0 | G2: 0 | H2: 0 | I2: 0 | J2: Говядина (кроме бескостного мяса), кг | K2: Говядина (кроме бескостного мяса), кг | L2: Говядина (кроме бескостного мяса), кг | M2: =INDEX('ИПЦ raw2015'!$1:$1048576, MATCH($J2,'ИПЦ raw2015'!$A:$A,0),MATCH(MoM!M$1,'ИПЦ raw2015'!$1:$1,0)) -> 105.82 | N2: =INDEX('ИПЦ raw2015'!$1:$1048576, MATCH($J2,'ИПЦ raw2015'!$A:$A,0),MATCH(MoM!N$1,'ИПЦ raw2015'!$1:$1,0)) -> 103.44 | O2: =INDEX('ИПЦ raw2015'!$1:$1048576, MATCH($J2,'ИПЦ raw2015'!$A:$A,0),MATCH(MoM!O$1,'ИПЦ raw2015'!$1:$1,0)) -> 101.87 | P2: =INDEX('ИПЦ raw2015'!$1:$1048576, MATCH($J2,'ИПЦ raw2015'!$A:$A,0),MATCH(MoM!P$1,'ИПЦ raw2015'!$1:$1,0)) -> 100.51 | Q2: =INDEX('ИПЦ raw2015'!$1:$1048576, MATCH($J2,'ИПЦ raw2015'!$A:$A,0),MATCH(MoM!Q$1,'ИПЦ raw2015'!$1:$1,0)) -> 100.51 | R2: =INDEX('ИПЦ raw2015'!$1:$1048576, MATCH($J2,'ИПЦ raw2015'!$A:$A,0),MATCH(MoM!R$1,'ИПЦ raw2015'!$1:$1,0)) -> 100.04 | S2: =INDEX('ИПЦ raw2015'!$1:$1048576, MATCH($J2,'ИПЦ raw2015'!$A:$A,0),MATCH(MoM!S$1,'ИПЦ raw2015'!$1:$1,0)) -> 100.2 | T2: =INDEX('ИПЦ raw2015'!$1:$1048576, MATCH($J2,'ИПЦ raw2015'!$A:$A,0),MATCH(MoM!T$1,'ИПЦ raw2015'!$1:$1,0)) -> 100.75 | ... BT2: =INDEX('ИПЦ raw2015'!$1:$1048576, MATCH($J2,'ИПЦ raw2015'!$A:$A,0),MATCH(MoM!BT$1,'ИПЦ raw2015'!$1:$1,0)) -> 100.68
A3: =Веса!A3 -> 1 | B3: =A3 -> 1 | C3: =БИПЦ_НДС!E3 -> 0 | D3: =1-C3 -> 1 | E3: 1 | F3: 0 | G3: 0 | H3: 0 | I3: 0 | J3: =L3 -> Говядина бескостная, кг | K3: Говядина бескостная, кг | L3: Говядина бескостная, кг | M3: =INDEX('ИПЦ raw2015'!$1:$1048576, MATCH($J3,'ИПЦ raw2015'!$A:$A,0),MATCH(MoM!M$1,'ИПЦ raw2015'!$1:$1,0)) -> 105.56 | N3: =INDEX('ИПЦ raw2015'!$1:$1048576, MATCH($J3,'ИПЦ raw2015'!$A:$A,0),MATCH(MoM!N$1,'ИПЦ raw2015'!$1:$1,0)) -> 102.81 | O3: =INDEX('ИПЦ raw2015'!$1:$1048576, MATCH($J3,'ИПЦ raw2015'!$A:$A,0),MATCH(MoM!O$1,'ИПЦ raw2015'!$1:$1,0)) -> 101.85 | P3: =INDEX('ИПЦ raw2015'!$1:$1048576, MATCH($J3,'ИПЦ raw2015'!$A:$A,0),MATCH(MoM!P$1,'ИПЦ raw2015'!$1:$1,0)) -> 101.12 | Q3: =INDEX('ИПЦ raw2015'!$1:$1048576, MATCH($J3,'ИПЦ raw2015'!$A:$A,0),MATCH(MoM!Q$1,'ИПЦ raw2015'!$1:$1,0)) -> 100.44 | R3: =INDEX('ИПЦ raw2015'!$1:$1048576, MATCH($J3,'ИПЦ raw2015'!$A:$A,0),MATCH(MoM!R$1,'ИПЦ raw2015'!$1:$1,0)) -> 100.25 | S3: =INDEX('ИПЦ raw2015'!$1:$1048576, MATCH($J3,'ИПЦ raw2015'!$A:$A,0),MATCH(MoM!S$1,'ИПЦ raw2015'!$1:$1,0)) -> 100.32 | T3: =INDEX('ИПЦ raw2015'!$1:$1048576, MATCH($J3,'ИПЦ raw2015'!$A:$A,0),MATCH(MoM!T$1,'ИПЦ raw2015'!$1:$1,0)) -> 100.41 | ... BT3: =INDEX('ИПЦ raw2015'!$1:$1048576, MATCH($J3,'ИПЦ raw2015'!$A:$A,0),MATCH(MoM!BT$1,'ИПЦ raw2015'!$1:$1,0)) -> 100.4
A4: =Веса!A4 -> 1 | B4: =A4 -> 1 | C4: =БИПЦ_НДС!E4 -> 0 | D4: =1-C4 -> 1 | E4: 1 | F4: 0 | G4: 0 | H4: 0 | I4: 0 | J4: =L4 -> Свинина (кроме бескостного мяса), кг | K4: Свинина (кроме бескостного мяса), кг | L4: Свинина (кроме бескостного мяса), кг | M4: =INDEX('ИПЦ raw2015'!$1:$1048576, MATCH($J4,'ИПЦ raw2015'!$A:$A,0),MATCH(MoM!M$1,'ИПЦ raw2015'!$1:$1,0)) -> 101.52 | N4: =INDEX('ИПЦ raw2015'!$1:$1048576, MATCH($J4,'ИПЦ raw2015'!$A:$A,0),MATCH(MoM!N$1,'ИПЦ raw2015'!$1:$1,0)) -> 99.24 | O4: =INDEX('ИПЦ raw2015'!$1:$1048576, MATCH($J4,'ИПЦ raw2015'!$A:$A,0),MATCH(MoM!O$1,'ИПЦ raw2015'!$1:$1,0)) -> 99.53 | P4: =INDEX('ИПЦ raw2015'!$1:$1048576, MATCH($J4,'ИПЦ raw2015'!$A:$A,0),MATCH(MoM!P$1,'ИПЦ raw2015'!$1:$1,0)) -> 100.94 | Q4: =INDEX('ИПЦ raw2015'!$1:$1048576, MATCH($J4,'ИПЦ raw2015'!$A:$A,0),MATCH(MoM!Q$1,'ИПЦ raw2015'!$1:$1,0)) -> 100.35 | R4: =INDEX('ИПЦ raw2015'!$1:$1048576, MATCH($J4,'ИПЦ raw2015'!$A:$A,0),MATCH(MoM!R$1,'ИПЦ raw2015'!$1:$1,0)) -> 99.83 | S4: =INDEX('ИПЦ raw2015'!$1:$1048576, MATCH($J4,'ИПЦ raw2015'!$A:$A,0),MATCH(MoM!S$1,'ИПЦ raw2015'!$1:$1,0)) -> 100.4 | T4: =INDEX('ИПЦ raw2015'!$1:$1048576, MATCH($J4,'ИПЦ raw2015'!$A:$A,0),MATCH(MoM!T$1,'ИПЦ raw2015'!$1:$1,0)) -> 100.11 | ... BT4: =INDEX('ИПЦ raw2015'!$1:$1048576, MATCH($J4,'ИПЦ raw2015'!$A:$A,0),MATCH(MoM!BT$1,'ИПЦ raw2015'!$1:$1,0)) -> 98.89
A5: =Веса!A5 -> 1 | B5: =A5 -> 1 | C5: =БИПЦ_НДС!E5 -> 0 | D5: =1-C5 -> 1 | E5: 1 | F5: 0 | G5: 0 | H5: 0 | I5: 0 | J5: =L5 -> Свинина бескостная, кг | K5: Свинина бескостная, кг | L5: Свинина бескостная, кг | M5: =INDEX('ИПЦ raw2015'!$1:$1048576, MATCH($J5,'ИПЦ raw2015'!$A:$A,0),MATCH(MoM!M$1,'ИПЦ raw2015'!$1:$1,0)) -> 101.94 | N5: =INDEX('ИПЦ raw2015'!$1:$1048576, MATCH($J5,'ИПЦ raw2015'!$A:$A,0),MATCH(MoM!N$1,'ИПЦ raw2015'!$1:$1,0)) -> 99.67 | O5: =INDEX('ИПЦ raw2015'!$1:$1048576, MATCH($J5,'ИПЦ raw2015'!$A:$A,0),MATCH(MoM!O$1,'ИПЦ raw2015'!$1:$1,0)) -> 99.92 | P5: =INDEX('ИПЦ raw2015'!$1:$1048576, MATCH($J5,'ИПЦ raw2015'!$A:$A,0),MATCH(MoM!P$1,'ИПЦ raw2015'!$1:$1,0)) -> 100.42 | Q5: =INDEX('ИПЦ raw2015'!$1:$1048576, MATCH($J5,'ИПЦ raw2015'!$A:$A,0),MATCH(MoM!Q$1,'ИПЦ raw2015'!$1:$1,0)) -> 100.47 | R5: =INDEX('ИПЦ raw2015'!$1:$1048576, MATCH($J5,'ИПЦ raw2015'!$A:$A,0),MATCH(MoM!R$1,'ИПЦ raw2015'!$1:$1,0)) -> 100.23 | S5: =INDEX('ИПЦ raw2015'!$1:$1048576, MATCH($J5,'ИПЦ raw2015'!$A:$A,0),MATCH(MoM!S$1,'ИПЦ raw2015'!$1:$1,0)) -> 100.41 | T5: =INDEX('ИПЦ raw2015'!$1:$1048576, MATCH($J5,'ИПЦ raw2015'!$A:$A,0),MATCH(MoM!T$1,'ИПЦ raw2015'!$1:$1,0)) -> 100.3 | ... BT5: =INDEX('ИПЦ raw2015'!$1:$1048576, MATCH($J5,'ИПЦ raw2015'!$A:$A,0),MATCH(MoM!BT$1,'ИПЦ raw2015'!$1:$1,0)) -> 99.51
A6: =Веса!A6 -> 1 | B6: =A6 -> 1 | C6: =БИПЦ_НДС!E6 -> 0 | D6: =1-C6 -> 1 | E6: 1 | F6: 0 | G6: 0 | H6: 0 | I6: 0 | J6: =L6 -> Баранина (кроме бескостного мяса), кг | K6: Баранина (кроме бескостного мяса), кг | L6: Баранина (кроме бескостного мяса), кг | M6: =INDEX('ИПЦ raw2015'!$1:$1048576, MATCH($J6,'ИПЦ raw2015'!$A:$A,0),MATCH(MoM!M$1,'ИПЦ raw2015'!$1:$1,0)) -> 102.84 | N6: =INDEX('ИПЦ raw2015'!$1:$1048576, MATCH($J6,'ИПЦ raw2015'!$A:$A,0),MATCH(MoM!N$1,'ИПЦ raw2015'!$1:$1,0)) -> 101.95 | O6: =INDEX('ИПЦ raw2015'!$1:$1048576, MATCH($J6,'ИПЦ raw2015'!$A:$A,0),MATCH(MoM!O$1,'ИПЦ raw2015'!$1:$1,0)) -> 101.06 | P6: =INDEX('ИПЦ raw2015'!$1:$1048576, MATCH($J6,'ИПЦ raw2015'!$A:$A,0),MATCH(MoM!P$1,'ИПЦ raw2015'!$1:$1,0)) -> 101.76 | Q6: =INDEX('ИПЦ raw2015'!$1:$1048576, MATCH($J6,'ИПЦ raw2015'!$A:$A,0),MATCH(MoM!Q$1,'ИПЦ raw2015'!$1:$1,0)) -> 100.44 | R6: =INDEX('ИПЦ raw2015'!$1:$1048576, MATCH($J6,'ИПЦ raw2015'!$A:$A,0),MATCH(MoM!R$1,'ИПЦ raw2015'!$1:$1,0)) -> 99.73 | S6: =INDEX('ИПЦ raw2015'!$1:$1048576, MATCH($J6,'ИПЦ raw2015'!$A:$A,0),MATCH(MoM!S$1,'ИПЦ raw2015'!$1:$1,0)) -> 100.2 | T6: =INDEX('ИПЦ raw2015'!$1:$1048576, MATCH($J6,'ИПЦ raw2015'!$A:$A,0),MATCH(MoM!T$1,'ИПЦ raw2015'!$1:$1,0)) -> 100.06 | ... BT6: =INDEX('ИПЦ raw2015'!$1:$1048576, MATCH($J6,'ИПЦ raw2015'!$A:$A,0),MATCH(MoM!BT$1,'ИПЦ raw2015'!$1:$1,0)) -> 100.2
A7: =Веса!A7 -> 1 | B7: =A7 -> 1 | C7: =БИПЦ_НДС!E7 -> 0 | D7: =1-C7 -> 1 | E7: 1 | F7: 0 | G7: 0 | H7: 0 | I7: 0 | J7: =L7 -> Куры охлажденные и мороженые, кг | K7: Куры охлажденные и мороженые, кг | L7: Куры охлажденные и мороженые, кг | M7: =INDEX('ИПЦ raw2015'!$1:$1048576, MATCH($J7,'ИПЦ raw2015'!$A:$A,0),MATCH(MoM!M$1,'ИПЦ raw2015'!$1:$1,0)) -> 102.41 | N7: =INDEX('ИПЦ raw2015'!$1:$1048576, MATCH($J7,'ИПЦ raw2015'!$A:$A,0),MATCH(MoM!N$1,'ИПЦ raw2015'!$1:$1,0)) -> 99.96 | O7: =INDEX('ИПЦ raw2015'!$1:$1048576, MATCH($J7,'ИПЦ raw2015'!$A:$A,0),MATCH(MoM!O$1,'ИПЦ raw2015'!$1:$1,0)) -> 99.31 | P7: =INDEX('ИПЦ raw2015'!$1:$1048576, MATCH($J7,'ИПЦ raw2015'!$A:$A,0),MATCH(MoM!P$1,'ИПЦ raw2015'!$1:$1,0)) -> 98.88 | Q7: =INDEX('ИПЦ raw2015'!$1:$1048576, MATCH($J7,'ИПЦ raw2015'!$A:$A,0),MATCH(MoM!Q$1,'ИПЦ raw2015'!$1:$1,0)) -> 98.99 | R7: =INDEX('ИПЦ raw2015'!$1:$1048576, MATCH($J7,'ИПЦ raw2015'!$A:$A,0),MATCH(MoM!R$1,'ИПЦ raw2015'!$1:$1,0)) -> 99.34 | S7: =INDEX('ИПЦ raw2015'!$1:$1048576, MATCH($J7,'ИПЦ raw2015'!$A:$A,0),MATCH(MoM!S$1,'ИПЦ raw2015'!$1:$1,0)) -> 99.71 | T7: =INDEX('ИПЦ raw2015'!$1:$1048576, MATCH($J7,'ИПЦ raw2015'!$A:$A,0),MATCH(MoM!T$1,'ИПЦ raw2015'!$1:$1,0)) -> 99.78 | ... BT7: =INDEX('ИПЦ raw2015'!$1:$1048576, MATCH($J7,'ИПЦ raw2015'!$A:$A,0),MATCH(MoM!BT$1,'ИПЦ raw2015'!$1:$1,0)) -> 99.82
A8: =Веса!A8 -> 1 | B8: =A8 -> 1 | C8: =БИПЦ_НДС!E8 -> 0 | D8: =1-C8 -> 1 | E8: 1 | F8: 0 | G8: 0 | H8: 0 | I8: 0 | J8: =L8 -> Окорочка куриные, кг | K8: Окорочка куриные, кг | L8: Окорочка куриные, кг | M8: =INDEX('ИПЦ raw2015'!$1:$1048576, MATCH($J8,'ИПЦ raw2015'!$A:$A,0),MATCH(MoM!M$1,'ИПЦ raw2015'!$1:$1,0)) -> 102.66 | N8: =INDEX('ИПЦ raw2015'!$1:$1048576, MATCH($J8,'ИПЦ raw2015'!$A:$A,0),MATCH(MoM!N$1,'ИПЦ raw2015'!$1:$1,0)) -> 100.98 | O8: =INDEX('ИПЦ raw2015'!$1:$1048576, MATCH($J8,'ИПЦ raw2015'!$A:$A,0),MATCH(MoM!O$1,'ИПЦ raw2015'!$1:$1,0)) -> 99.88 | P8: =INDEX('ИПЦ raw2015'!$1:$1048576, MATCH($J8,'ИПЦ raw2015'!$A:$A,0),MATCH(MoM!P$1,'ИПЦ raw2015'!$1:$1,0)) -> 99.25 | Q8: =INDEX('ИПЦ raw2015'!$1:$1048576, MATCH($J8,'ИПЦ raw2015'!$A:$A,0),MATCH(MoM!Q$1,'ИПЦ raw2015'!$1:$1,0)) -> 99.49 | R8: =INDEX('ИПЦ raw2015'!$1:$1048576, MATCH($J8,'ИПЦ raw2015'!$A:$A,0),MATCH(MoM!R$1,'ИПЦ raw2015'!$1:$1,0)) -> 99.65 | S8: =INDEX('ИПЦ raw2015'!$1:$1048576, MATCH($J8,'ИПЦ raw2015'!$A:$A,0),MATCH(MoM!S$1,'ИПЦ raw2015'!$1:$1,0)) -> 99.89 | T8: =INDEX('ИПЦ raw2015'!$1:$1048576, MATCH($J8,'ИПЦ raw2015'!$A:$A,0),MATCH(MoM!T$1,'ИПЦ raw2015'!$1:$1,0)) -> 100.05 | ... BT8: =INDEX('ИПЦ raw2015'!$1:$1048576, MATCH($J8,'ИПЦ raw2015'!$A:$A,0),MATCH(MoM!BT$1,'ИПЦ raw2015'!$1:$1,0)) -> 100.09
A9: =Веса!A9 -> 0 | B9: =A9 -> 0 | C9: =БИПЦ_НДС!E9 -> 0 | D9: =1-C9 -> 1 | E9: 1 | F9: 0 | G9: 0 | H9: 0 | I9: 0 | J9: Мясо индейки, кг | K9: Мясо индейки, кг | L9: Мясо индейки, кг | M9: 0 | N9: 0 | O9: 0 | P9: 0 | Q9: 0 | R9: 0 | S9: 0 | T9: 0 | U9: 0 | V9: 0 | W9: 0 | X9: 0 | Y9: 0 | Z9: 0 | AA9: 0 | AB9: 0 | AC9: 0 | AD9: 0 | AE9: 0 | AF9: 0 | AG9: 0 | AH9: 0 | AI9: 0 | AJ9: 0 | AK9: 0 | AL9: 0 | AM9: 0 | AN9: 0 | AO9: 0 | AP9: 0 | AQ9: 0 | AR9: 0 | AS9: 0 | AT9: 0 | AU9: 0 | AV9: 0 | AW9: 0 | AX9: 0 | AY9: 0 | AZ9: 0 | BA9: 0 | BB9: 0 | BC9: 0 | BD9: 0 | BE9: 0 | BF9: 0 | BG9: 0 | BH9: 0 | BI9: 0 | BJ9: 0 | BK9: 0 | BL9: 0 | BM9: 0 | BN9: 0 | BO9: 0 | BP9: 0 | BQ9: 0 | BR9: 0 | BS9: 0 | BT9: 0
A10: =Веса!A10 -> 1 | B10: =A10 -> 1 | C10: =БИПЦ_НДС!E10 -> 0 | D10: =1-C10 -> 1 | E10: 1 | F10: 0 | G10: 0 | H10: 0 | I10: 0 | J10: Печень говяжья, кг | K10: Печень говяжья, свиная, кг | L10: Печень говяжья, свиная, кг | M10: =INDEX('ИПЦ raw2015'!$1:$1048576, MATCH($J10,'ИПЦ raw2015'!$A:$A,0),MATCH(MoM!M$1,'ИПЦ raw2015'!$1:$1,0)) -> 104.75 | N10: =INDEX('ИПЦ raw2015'!$1:$1048576, MATCH($J10,'ИПЦ raw2015'!$A:$A,0),MATCH(MoM!N$1,'ИПЦ raw2015'!$1:$1,0)) -> 105.04 | O10: =INDEX('ИПЦ raw2015'!$1:$1048576, MATCH($J10,'ИПЦ raw2015'!$A:$A,0),MATCH(MoM!O$1,'ИПЦ raw2015'!$1:$1,0)) -> 102.85 | P10: =INDEX('ИПЦ raw2015'!$1:$1048576, MATCH($J10,'ИПЦ raw2015'!$A:$A,0),MATCH(MoM!P$1,'ИПЦ raw2015'!$1:$1,0)) -> 100.8 | Q10: =INDEX('ИПЦ raw2015'!$1:$1048576, MATCH($J10,'ИПЦ raw2015'!$A:$A,0),MATCH(MoM!Q$1,'ИПЦ raw2015'!$1:$1,0)) -> 98.97 | R10: =INDEX('ИПЦ raw2015'!$1:$1048576, MATCH($J10,'ИПЦ raw2015'!$A:$A,0),MATCH(MoM!R$1,'ИПЦ raw2015'!$1:$1,0)) -> 99.37 | S10: =INDEX('ИПЦ raw2015'!$1:$1048576, MATCH($J10,'ИПЦ raw2015'!$A:$A,0),MATCH(MoM!S$1,'ИПЦ raw2015'!$1:$1,0)) -> 99.25 | T10: =INDEX('ИПЦ raw2015'!$1:$1048576, MATCH($J10,'ИПЦ raw2015'!$A:$A,0),MATCH(MoM!T$1,'ИПЦ raw2015'!$1:$1,0)) -> 99.78 | ... BT10: =INDEX('ИПЦ raw2015'!$1:$1048576, MATCH($J10,'ИПЦ raw2015'!$A:$A,0),MATCH(MoM!BT$1,'ИПЦ raw2015'!$1:$1,0)) -> 100.31
A11: =Веса!A11 -> 1 | B11: =A11 -> 1 | C11: =БИПЦ_НДС!E11 -> 0 | D11: =1-C11 -> 1 | E11: 1 | F11: 0 | G11: 0 | H11: 0 | I11: 0 | J11: =L11 -> Фарш мясной, кг | K11: Фарш мясной, кг | L11: Фарш мясной, кг | M11: =INDEX('ИПЦ raw2015'!$1:$1048576, MATCH($J11,'ИПЦ raw2015'!$A:$A,0),MATCH(MoM!M$1,'ИПЦ raw2015'!$1:$1,0)) -> 103.9 | N11: =INDEX('ИПЦ raw2015'!$1:$1048576, MATCH($J11,'ИПЦ raw2015'!$A:$A,0),MATCH(MoM!N$1,'ИПЦ raw2015'!$1:$1,0)) -> 103 | O11: =INDEX('ИПЦ raw2015'!$1:$1048576, MATCH($J11,'ИПЦ raw2015'!$A:$A,0),MATCH(MoM!O$1,'ИПЦ raw2015'!$1:$1,0)) -> 101.68 | P11: =INDEX('ИПЦ raw2015'!$1:$1048576, MATCH($J11,'ИПЦ raw2015'!$A:$A,0),MATCH(MoM!P$1,'ИПЦ raw2015'!$1:$1,0)) -> 100.77 | Q11: =INDEX('ИПЦ raw2015'!$1:$1048576, MATCH($J11,'ИПЦ raw2015'!$A:$A,0),MATCH(MoM!Q$1,'ИПЦ raw2015'!$1:$1,0)) -> 100.19 | R11: =INDEX('ИПЦ raw2015'!$1:$1048576, MATCH($J11,'ИПЦ raw2015'!$A:$A,0),MATCH(MoM!R$1,'ИПЦ raw2015'!$1:$1,0)) -> 100.13 | S11: =INDEX('ИПЦ raw2015'!$1:$1048576, MATCH($J11,'ИПЦ raw2015'!$A:$A,0),MATCH(MoM!S$1,'ИПЦ raw2015'!$1:$1,0)) -> 100.23 | T11: =INDEX('ИПЦ raw2015'!$1:$1048576, MATCH($J11,'ИПЦ raw2015'!$A:$A,0),MATCH(MoM!T$1,'ИПЦ raw2015'!$1:$1,0)) -> 100.59 | ... BT11: =INDEX('ИПЦ raw2015'!$1:$1048576, MATCH($J11,'ИПЦ raw2015'!$A:$A,0),MATCH(MoM!BT$1,'ИПЦ raw2015'!$1:$1,0)) -> 99.98
A12: =Веса!A12 -> 1 | B12: =A12 -> 1 | C12: =БИПЦ_НДС!E12 -> 0 | D12: =1-C12 -> 1 | E12: 1 | F12: 0 | G12: 0 | H12: 0 | I12: 0 | J12: =L12 -> Пельмени, манты, равиоли, кг | K12: Пельмени, манты, равиоли, кг | L12: Пельмени, манты, равиоли, кг | M12: =INDEX('ИПЦ raw2015'!$1:$1048576, MATCH($J12,'ИПЦ raw2015'!$A:$A,0),MATCH(MoM!M$1,'ИПЦ raw2015'!$1:$1,0)) -> 103.23 | N12: =INDEX('ИПЦ raw2015'!$1:$1048576, MATCH($J12,'ИПЦ raw2015'!$A:$A,0),MATCH(MoM!N$1,'ИПЦ raw2015'!$1:$1,0)) -> 103.1 | O12: =INDEX('ИПЦ raw2015'!$1:$1048576, MATCH($J12,'ИПЦ raw2015'!$A:$A,0),MATCH(MoM!O$1,'ИПЦ raw2015'!$1:$1,0)) -> 102.14 | P12: =INDEX('ИПЦ raw2015'!$1:$1048576, MATCH($J12,'ИПЦ raw2015'!$A:$A,0),MATCH(MoM!P$1,'ИПЦ raw2015'!$1:$1,0)) -> 101.24 | Q12: =INDEX('ИПЦ raw2015'!$1:$1048576, MATCH($J12,'ИПЦ raw2015'!$A:$A,0),MATCH(MoM!Q$1,'ИПЦ raw2015'!$1:$1,0)) -> 100.91 | R12: =INDEX('ИПЦ raw2015'!$1:$1048576, MATCH($J12,'ИПЦ raw2015'!$A:$A,0),MATCH(MoM!R$1,'ИПЦ raw2015'!$1:$1,0)) -> 100.65 | S12: =INDEX('ИПЦ raw2015'!$1:$1048576, MATCH($J12,'ИПЦ raw2015'!$A:$A,0),MATCH(MoM!S$1,'ИПЦ raw2015'!$1:$1,0)) -> 100.52 | T12: =INDEX('ИПЦ raw2015'!$1:$1048576, MATCH($J12,'ИПЦ raw2015'!$A:$A,0),MATCH(MoM!T$1,'ИПЦ raw2015'!$1:$1,0)) -> 100.25 | ... BT12: =INDEX('ИПЦ raw2015'!$1:$1048576, MATCH($J12,'ИПЦ raw2015'!$A:$A,0),MATCH(MoM!BT$1,'ИПЦ raw2015'!$1:$1,0)) -> 100.34
A13: =Веса!A13 -> 1 | B13: =A13 -> 1 | C13: =БИПЦ_НДС!E13 -> 0 | D13: =1-C13 -> 1 | E13: 1 | F13: 0 | G13: 0 | H13: 0 | I13: 0 | J13: =L13 -> Сосиски, сардельки, кг | K13: Сосиски, сардельки, кг | L13: Сосиски, сардельки, кг | M13: =INDEX('ИПЦ raw2015'!$1:$1048576, MATCH($J13,'ИПЦ raw2015'!$A:$A,0),MATCH(MoM!M$1,'ИПЦ raw2015'!$1:$1,0)) -> 102.34 | N13: =INDEX('ИПЦ raw2015'!$1:$1048576, MATCH($J13,'ИПЦ raw2015'!$A:$A,0),MATCH(MoM!N$1,'ИПЦ raw2015'!$1:$1,0)) -> 102.47 | O13: =INDEX('ИПЦ raw2015'!$1:$1048576, MATCH($J13,'ИПЦ raw2015'!$A:$A,0),MATCH(MoM!O$1,'ИПЦ raw2015'!$1:$1,0)) -> 101.66 | P13: =INDEX('ИПЦ raw2015'!$1:$1048576, MATCH($J13,'ИПЦ raw2015'!$A:$A,0),MATCH(MoM!P$1,'ИПЦ raw2015'!$1:$1,0)) -> 101.17 | Q13: =INDEX('ИПЦ raw2015'!$1:$1048576, MATCH($J13,'ИПЦ raw2015'!$A:$A,0),MATCH(MoM!Q$1,'ИПЦ raw2015'!$1:$1,0)) -> 100.57 | R13: =INDEX('ИПЦ raw2015'!$1:$1048576, MATCH($J13,'ИПЦ raw2015'!$A:$A,0),MATCH(MoM!R$1,'ИПЦ raw2015'!$1:$1,0)) -> 100.19 | S13: =INDEX('ИПЦ raw2015'!$1:$1048576, MATCH($J13,'ИПЦ raw2015'!$A:$A,0),MATCH(MoM!S$1,'ИПЦ raw2015'!$1:$1,0)) -> 100.33 | T13: =INDEX('ИПЦ raw2015'!$1:$1048576, MATCH($J13,'ИПЦ raw2015'!$A:$A,0),MATCH(MoM!T$1,'ИПЦ raw2015'!$1:$1,0)) -> 100.26 | ... BT13: =INDEX('ИПЦ raw2015'!$1:$1048576, MATCH($J13,'ИПЦ raw2015'!$A:$A,0),MATCH(MoM!BT$1,'ИПЦ raw2015'!$1:$1,0)) -> 100.11
A14: =Веса!A14 -> 1 | B14: =A14 -> 1 | C14: =БИПЦ_НДС!E14 -> 0 | D14: =1-C14 -> 1 | E14: 1 | F14: 0 | G14: 0 | H14: 0 | I14: 0 | J14: =L14 -> Колбаса полукопченая и варено-копченая, кг | K14: Колбаса полукопченая и варено-копченая, кг | L14: Колбаса полукопченая и варено-копченая, кг | M14: =INDEX('ИПЦ raw2015'!$1:$1048576, MATCH($J14,'ИПЦ raw2015'!$A:$A,0),MATCH(MoM!M$1,'ИПЦ raw2015'!$1:$1,0)) -> 102.87 | N14: =INDEX('ИПЦ raw2015'!$1:$1048576, MATCH($J14,'ИПЦ raw2015'!$A:$A,0),MATCH(MoM!N$1,'ИПЦ raw2015'!$1:$1,0)) -> 102.63 | O14: =INDEX('ИПЦ raw2015'!$1:$1048576, MATCH($J14,'ИПЦ raw2015'!$A:$A,0),MATCH(MoM!O$1,'ИПЦ raw2015'!$1:$1,0)) -> 101.48 | P14: =INDEX('ИПЦ raw2015'!$1:$1048576, MATCH($J14,'ИПЦ raw2015'!$A:$A,0),MATCH(MoM!P$1,'ИПЦ raw2015'!$1:$1,0)) -> 101.09 | Q14: =INDEX('ИПЦ raw2015'!$1:$1048576, MATCH($J14,'ИПЦ raw2015'!$A:$A,0),MATCH(MoM!Q$1,'ИПЦ raw2015'!$1:$1,0)) -> 100.52 | R14: =INDEX('ИПЦ raw2015'!$1:$1048576, MATCH($J14,'ИПЦ raw2015'!$A:$A,0),MATCH(MoM!R$1,'ИПЦ raw2015'!$1:$1,0)) -> 100.23 | S14: =INDEX('ИПЦ raw2015'!$1:$1048576, MATCH($J14,'ИПЦ raw2015'!$A:$A,0),MATCH(MoM!S$1,'ИПЦ raw2015'!$1:$1,0)) -> 100.22 | T14: =INDEX('ИПЦ raw2015'!$1:$1048576, MATCH($J14,'ИПЦ raw2015'!$A:$A,0),MATCH(MoM!T$1,'ИПЦ raw2015'!$1:$1,0)) -> 100.21 | ... BT14: =INDEX('ИПЦ raw2015'!$1:$1048576, MATCH($J14,'ИПЦ raw2015'!$A:$A,0),MATCH(MoM!BT$1,'ИПЦ raw2015'!$1:$1,0)) -> 99.99
A15: =Веса!A15 -> 1 | B15: =A15 -> 1 | C15: =БИПЦ_НДС!E15 -> 0 | D15: =1-C15 -> 1 | E15: 1 | F15: 0 | G15: 0 | H15: 0 | I15: 0 | J15: =L15 -> Колбаса сырокопченая, кг | K15: Колбаса сырокопченая, кг | L15: Колбаса сырокопченая, кг | M15: =INDEX('ИПЦ raw2015'!$1:$1048576, MATCH($J15,'ИПЦ raw2015'!$A:$A,0),MATCH(MoM!M$1,'ИПЦ raw2015'!$1:$1,0)) -> 102.41 | N15: =INDEX('ИПЦ raw2015'!$1:$1048576, MATCH($J15,'ИПЦ raw2015'!$A:$A,0),MATCH(MoM!N$1,'ИПЦ raw2015'!$1:$1,0)) -> 102.14 | O15: =INDEX('ИПЦ raw2015'!$1:$1048576, MATCH($J15,'ИПЦ raw2015'!$A:$A,0),MATCH(MoM!O$1,'ИПЦ raw2015'!$1:$1,0)) -> 101.61 | P15: =INDEX('ИПЦ raw2015'!$1:$1048576, MATCH($J15,'ИПЦ raw2015'!$A:$A,0),MATCH(MoM!P$1,'ИПЦ raw2015'!$1:$1,0)) -> 101.08 | Q15: =INDEX('ИПЦ raw2015'!$1:$1048576, MATCH($J15,'ИПЦ raw2015'!$A:$A,0),MATCH(MoM!Q$1,'ИПЦ raw2015'!$1:$1,0)) -> 100.95 | R15: =INDEX('ИПЦ raw2015'!$1:$1048576, MATCH($J15,'ИПЦ raw2015'!$A:$A,0),MATCH(MoM!R$1,'ИПЦ raw2015'!$1:$1,0)) -> 100.4 | S15: =INDEX('ИПЦ raw2015'!$1:$1048576, MATCH($J15,'ИПЦ raw2015'!$A:$A,0),MATCH(MoM!S$1,'ИПЦ raw2015'!$1:$1,0)) -> 100.25 | T15: =INDEX('ИПЦ raw2015'!$1:$1048576, MATCH($J15,'ИПЦ raw2015'!$A:$A,0),MATCH(MoM!T$1,'ИПЦ raw2015'!$1:$1,0)) -> 100.45 | ... BT15: =INDEX('ИПЦ raw2015'!$1:$1048576, MATCH($J15,'ИПЦ raw2015'!$A:$A,0),MATCH(MoM!BT$1,'ИПЦ raw2015'!$1:$1,0)) -> 100.2
A16: =Веса!A16 -> 1 | B16: =A16 -> 1 | C16: =БИПЦ_НДС!E16 -> 0 | D16: =1-C16 -> 1 | E16: 1 | F16: 0 | G16: 0 | H16: 0 | I16: 0 | J16: =L16 -> Колбаса вареная, кг | K16: Колбаса вареная, кг | L16: Колбаса вареная, кг | M16: =INDEX('ИПЦ raw2015'!$1:$1048576, MATCH($J16,'ИПЦ raw2015'!$A:$A,0),MATCH(MoM!M$1,'ИПЦ raw2015'!$1:$1,0)) -> 102.47 | N16: =INDEX('ИПЦ raw2015'!$1:$1048576, MATCH($J16,'ИПЦ raw2015'!$A:$A,0),MATCH(MoM!N$1,'ИПЦ raw2015'!$1:$1,0)) -> 102.36 | O16: =INDEX('ИПЦ raw2015'!$1:$1048576, MATCH($J16,'ИПЦ raw2015'!$A:$A,0),MATCH(MoM!O$1,'ИПЦ raw2015'!$1:$1,0)) -> 101.73 | P16: =INDEX('ИПЦ raw2015'!$1:$1048576, MATCH($J16,'ИПЦ raw2015'!$A:$A,0),MATCH(MoM!P$1,'ИПЦ raw2015'!$1:$1,0)) -> 100.99 | Q16: =INDEX('ИПЦ raw2015'!$1:$1048576, MATCH($J16,'ИПЦ raw2015'!$A:$A,0),MATCH(MoM!Q$1,'ИПЦ raw2015'!$1:$1,0)) -> 100.6 | R16: =INDEX('ИПЦ raw2015'!$1:$1048576, MATCH($J16,'ИПЦ raw2015'!$A:$A,0),MATCH(MoM!R$1,'ИПЦ raw2015'!$1:$1,0)) -> 100.58 | S16: =INDEX('ИПЦ raw2015'!$1:$1048576, MATCH($J16,'ИПЦ raw2015'!$A:$A,0),MATCH(MoM!S$1,'ИПЦ raw2015'!$1:$1,0)) -> 100.25 | T16: =INDEX('ИПЦ raw2015'!$1:$1048576, MATCH($J16,'ИПЦ raw2015'!$A:$A,0),MATCH(MoM!T$1,'ИПЦ raw2015'!$1:$1,0)) -> 100.27 | ... BT16: =INDEX('ИПЦ raw2015'!$1:$1048576, MATCH($J16,'ИПЦ raw2015'!$A:$A,0),MATCH(MoM!BT$1,'ИПЦ raw2015'!$1:$1,0)) -> 100.27
A17: =Веса!A17 -> 1 | B17: =A17 -> 1 | C17: =БИПЦ_НДС!E17 -> 1 | D17: =1-C17 -> 0 | E17: 1 | F17: 0 | G17: 0 | H17: 0 | I17: 0 | J17: =L17 -> Мясокопчености, кг | K17: Мясокопчености, кг | L17: Мясокопчености, кг | M17: =INDEX('ИПЦ raw2015'!$1:$1048576, MATCH($J17,'ИПЦ raw2015'!$A:$A,0),MATCH(MoM!M$1,'ИПЦ raw2015'!$1:$1,0)) -> 102.06 | N17: =INDEX('ИПЦ raw2015'!$1:$1048576, MATCH($J17,'ИПЦ raw2015'!$A:$A,0),MATCH(MoM!N$1,'ИПЦ raw2015'!$1:$1,0)) -> 102.4 | O17: =INDEX('ИПЦ raw2015'!$1:$1048576, MATCH($J17,'ИПЦ raw2015'!$A:$A,0),MATCH(MoM!O$1,'ИПЦ raw2015'!$1:$1,0)) -> 101.55 | P17: =INDEX('ИПЦ raw2015'!$1:$1048576, MATCH($J17,'ИПЦ raw2015'!$A:$A,0),MATCH(MoM!P$1,'ИПЦ raw2015'!$1:$1,0)) -> 101.02 | Q17: =INDEX('ИПЦ raw2015'!$1:$1048576, MATCH($J17,'ИПЦ raw2015'!$A:$A,0),MATCH(MoM!Q$1,'ИПЦ raw2015'!$1:$1,0)) -> 100.66 | R17: =INDEX('ИПЦ raw2015'!$1:$1048576, MATCH($J17,'ИПЦ raw2015'!$A:$A,0),MATCH(MoM!R$1,'ИПЦ raw2015'!$1:$1,0)) -> 100.47 | S17: =INDEX('ИПЦ raw2015'!$1:$1048576, MATCH($J17,'ИПЦ raw2015'!$A:$A,0),MATCH(MoM!S$1,'ИПЦ raw2015'!$1:$1,0)) -> 100.14 | T17: =INDEX('ИПЦ raw2015'!$1:$1048576, MATCH($J17,'ИПЦ raw2015'!$A:$A,0),MATCH(MoM!T$1,'ИПЦ raw2015'!$1:$1,0)) -> 100.17 | ... BT17: =INDEX('ИПЦ raw2015'!$1:$1048576, MATCH($J17,'ИПЦ raw2015'!$A:$A,0),MATCH(MoM!BT$1,'ИПЦ raw2015'!$1:$1,0)) -> 100.15
A18: =Веса!A18 -> 1 | B18: =A18 -> 1 | C18: =БИПЦ_НДС!E18 -> 0 | D18: =1-C18 -> 1 | E18: 1 | F18: 0 | G18: 0 | H18: 0 | I18: 0 | J18: =L18 -> Кулинарные изделия из птицы, кг | K18: Кулинарные изделия из птицы, кг | L18: Кулинарные изделия из птицы, кг | M18: =INDEX('ИПЦ raw2015'!$1:$1048576, MATCH($J18,'ИПЦ raw2015'!$A:$A,0),MATCH(MoM!M$1,'ИПЦ raw2015'!$1:$1,0)) -> 102.51 | N18: =INDEX('ИПЦ raw2015'!$1:$1048576, MATCH($J18,'ИПЦ raw2015'!$A:$A,0),MATCH(MoM!N$1,'ИПЦ raw2015'!$1:$1,0)) -> 101.89 | O18: =INDEX('ИПЦ raw2015'!$1:$1048576, MATCH($J18,'ИПЦ raw2015'!$A:$A,0),MATCH(MoM!O$1,'ИПЦ raw2015'!$1:$1,0)) -> 100.47 | P18: =INDEX('ИПЦ raw2015'!$1:$1048576, MATCH($J18,'ИПЦ raw2015'!$A:$A,0),MATCH(MoM!P$1,'ИПЦ raw2015'!$1:$1,0)) -> 100.25 | Q18: =INDEX('ИПЦ raw2015'!$1:$1048576, MATCH($J18,'ИПЦ raw2015'!$A:$A,0),MATCH(MoM!Q$1,'ИПЦ raw2015'!$1:$1,0)) -> 100.33 | R18: =INDEX('ИПЦ raw2015'!$1:$1048576, MATCH($J18,'ИПЦ raw2015'!$A:$A,0),MATCH(MoM!R$1,'ИПЦ raw2015'!$1:$1,0)) -> 99.83 | S18: =INDEX('ИПЦ raw2015'!$1:$1048576, MATCH($J18,'ИПЦ raw2015'!$A:$A,0),MATCH(MoM!S$1,'ИПЦ raw2015'!$1:$1,0)) -> 100.31 | T18: =INDEX('ИПЦ raw2015'!$1:$1048576, MATCH($J18,'ИПЦ raw2015'!$A:$A,0),MATCH(MoM!T$1,'ИПЦ raw2015'!$1:$1,0)) -> 100.3 | ... BT18: =INDEX('ИПЦ raw2015'!$1:$1048576, MATCH($J18,'ИПЦ raw2015'!$A:$A,0),MATCH(MoM!BT$1,'ИПЦ raw2015'!$1:$1,0)) -> 100.55
A19: =Веса!A19 -> 1 | B19: =A19 -> 1 | C19: =БИПЦ_НДС!E19 -> 0 | D19: =1-C19 -> 1 | E19: 1 | F19: 0 | G19: 0 | H19: 0 | I19: 0 | J19: Консервы мясные, 350 г | K19: Консервы мясные, кг | L19: Консервы мясные, кг | M19: =INDEX('ИПЦ raw2015'!$1:$1048576, MATCH($J19,'ИПЦ raw2015'!$A:$A,0),MATCH(MoM!M$1,'ИПЦ raw2015'!$1:$1,0)) -> 104.92 | N19: =INDEX('ИПЦ raw2015'!$1:$1048576, MATCH($J19,'ИПЦ raw2015'!$A:$A,0),MATCH(MoM!N$1,'ИПЦ raw2015'!$1:$1,0)) -> 104.66 | O19: =INDEX('ИПЦ raw2015'!$1:$1048576, MATCH($J19,'ИПЦ raw2015'!$A:$A,0),MATCH(MoM!O$1,'ИПЦ raw2015'!$1:$1,0)) -> 103.44 | P19: =INDEX('ИПЦ raw2015'!$1:$1048576, MATCH($J19,'ИПЦ raw2015'!$A:$A,0),MATCH(MoM!P$1,'ИПЦ raw2015'!$1:$1,0)) -> 102.27 | Q19: =INDEX('ИПЦ raw2015'!$1:$1048576, MATCH($J19,'ИПЦ raw2015'!$A:$A,0),MATCH(MoM!Q$1,'ИПЦ raw2015'!$1:$1,0)) -> 101.07 | R19: =INDEX('ИПЦ raw2015'!$1:$1048576, MATCH($J19,'ИПЦ raw2015'!$A:$A,0),MATCH(MoM!R$1,'ИПЦ raw2015'!$1:$1,0)) -> 100.84 | S19: =INDEX('ИПЦ raw2015'!$1:$1048576, MATCH($J19,'ИПЦ raw2015'!$A:$A,0),MATCH(MoM!S$1,'ИПЦ raw2015'!$1:$1,0)) -> 100.44 | T19: =INDEX('ИПЦ raw2015'!$1:$1048576, MATCH($J19,'ИПЦ raw2015'!$A:$A,0),MATCH(MoM!T$1,'ИПЦ raw2015'!$1:$1,0)) -> 100.61 | ... BT19: =INDEX('ИПЦ raw2015'!$1:$1048576, MATCH($J19,'ИПЦ raw2015'!$A:$A,0),MATCH(MoM!BT$1,'ИПЦ raw2015'!$1:$1,0)) -> 100.61
A20: =Веса!A20 -> 0 | B20: =A20 -> 0 | C20: =БИПЦ_НДС!E20 -> 0 | D20: =1-C20 -> 1 | E20: 1 | F20: 0 | G20: 0 | H20: 0 | I20: 0 | J20: =L20 -> Консервы мясные для детского питания, кг | K20: Консервы мясные для детского питания, кг | L20: Консервы мясные для детского питания, кг | M20: 0 | N20: 0 | O20: 0 | P20: 0 | Q20: 0 | R20: 0 | S20: 0 | T20: 0 | U20: 0 | V20: 0 | W20: 0 | X20: 0 | Y20: 0 | Z20: 0 | AA20: 0 | AB20: 0 | AC20: 0 | AD20: 0 | AE20: 0 | AF20: 0 | AG20: 0 | AH20: 0 | AI20: 0 | AJ20: 0 | AK20: 0 | AL20: 0 | AM20: 0 | AN20: 0 | AO20: 0 | AP20: 0 | AQ20: 0 | AR20: 0 | AS20: 0 | AT20: 0 | AU20: 0 | AV20: 0 | AW20: 0 | AX20: 0 | AY20: 0 | AZ20: 0 | BA20: 0 | BB20: 0 | BC20: 0 | BD20: 0 | BE20: 0 | BF20: 0 | BG20: 0 | BH20: 0 | BI20: 0 | BJ20: 0 | BK20: 0 | BL20: 0 | BM20: 0 | BN20: 0 | BO20: 0 | BP20: 0 | BQ20: 0 | BR20: 0 | BS20: 0 | BT20: 0
A21: =Веса!A21 -> 1 | B21: =A21 -> 1 | C21: =БИПЦ_НДС!E21 -> 0 | D21: =1-C21 -> 1 | E21: 1 | F21: 0 | G21: 0 | H21: 0 | I21: 0 | J21: =L21 -> Рыба живая и охлажденная, кг | K21: Рыба живая и охлажденная, кг | L21: Рыба живая и охлажденная, кг | M21: =INDEX('ИПЦ raw2015'!$1:$1048576, MATCH($J21,'ИПЦ raw2015'!$A:$A,0),MATCH(MoM!M$1,'ИПЦ raw2015'!$1:$1,0)) -> 105.48 | N21: =INDEX('ИПЦ raw2015'!$1:$1048576, MATCH($J21,'ИПЦ raw2015'!$A:$A,0),MATCH(MoM!N$1,'ИПЦ raw2015'!$1:$1,0)) -> 104.04 | O21: =INDEX('ИПЦ raw2015'!$1:$1048576, MATCH($J21,'ИПЦ raw2015'!$A:$A,0),MATCH(MoM!O$1,'ИПЦ raw2015'!$1:$1,0)) -> 102.48 | P21: =INDEX('ИПЦ raw2015'!$1:$1048576, MATCH($J21,'ИПЦ raw2015'!$A:$A,0),MATCH(MoM!P$1,'ИПЦ raw2015'!$1:$1,0)) -> 101.66 | Q21: =INDEX('ИПЦ raw2015'!$1:$1048576, MATCH($J21,'ИПЦ raw2015'!$A:$A,0),MATCH(MoM!Q$1,'ИПЦ raw2015'!$1:$1,0)) -> 101.04 | R21: =INDEX('ИПЦ raw2015'!$1:$1048576, MATCH($J21,'ИПЦ raw2015'!$A:$A,0),MATCH(MoM!R$1,'ИПЦ raw2015'!$1:$1,0)) -> 102.14 | S21: =INDEX('ИПЦ raw2015'!$1:$1048576, MATCH($J21,'ИПЦ raw2015'!$A:$A,0),MATCH(MoM!S$1,'ИПЦ raw2015'!$1:$1,0)) -> 101.44 | T21: =INDEX('ИПЦ raw2015'!$1:$1048576, MATCH($J21,'ИПЦ raw2015'!$A:$A,0),MATCH(MoM!T$1,'ИПЦ raw2015'!$1:$1,0)) -> 102.22 | ... BT21: =INDEX('ИПЦ raw2015'!$1:$1048576, MATCH($J21,'ИПЦ raw2015'!$A:$A,0),MATCH(MoM!BT$1,'ИПЦ raw2015'!$1:$1,0)) -> 99.52
A22: =Веса!A22 -> 1 | B22: =A22 -> 1 | C22: =БИПЦ_НДС!E22 -> 0 | D22: =1-C22 -> 1 | E22: 1 | F22: 0 | G22: 0 | H22: 0 | I22: 0 | J22: =L22 -> Рыба соленая, маринованная, копченая, кг | K22: Рыба соленая, маринованная, копченая, кг | L22: Рыба соленая, маринованная, копченая, кг | M22: =INDEX('ИПЦ raw2015'!$1:$1048576, MATCH($J22,'ИПЦ raw2015'!$A:$A,0),MATCH(MoM!M$1,'ИПЦ raw2015'!$1:$1,0)) -> 104.96 | N22: =INDEX('ИПЦ raw2015'!$1:$1048576, MATCH($J22,'ИПЦ raw2015'!$A:$A,0),MATCH(MoM!N$1,'ИПЦ raw2015'!$1:$1,0)) -> 103.54 | O22: =INDEX('ИПЦ raw2015'!$1:$1048576, MATCH($J22,'ИПЦ raw2015'!$A:$A,0),MATCH(MoM!O$1,'ИПЦ raw2015'!$1:$1,0)) -> 102.86 | P22: =INDEX('ИПЦ raw2015'!$1:$1048576, MATCH($J22,'ИПЦ raw2015'!$A:$A,0),MATCH(MoM!P$1,'ИПЦ raw2015'!$1:$1,0)) -> 101.56 | Q22: =INDEX('ИПЦ raw2015'!$1:$1048576, MATCH($J22,'ИПЦ raw2015'!$A:$A,0),MATCH(MoM!Q$1,'ИПЦ raw2015'!$1:$1,0)) -> 100.63 | R22: =INDEX('ИПЦ raw2015'!$1:$1048576, MATCH($J22,'ИПЦ raw2015'!$A:$A,0),MATCH(MoM!R$1,'ИПЦ raw2015'!$1:$1,0)) -> 100.53 | S22: =INDEX('ИПЦ raw2015'!$1:$1048576, MATCH($J22,'ИПЦ raw2015'!$A:$A,0),MATCH(MoM!S$1,'ИПЦ raw2015'!$1:$1,0)) -> 100.49 | T22: =INDEX('ИПЦ raw2015'!$1:$1048576, MATCH($J22,'ИПЦ raw2015'!$A:$A,0),MATCH(MoM!T$1,'ИПЦ raw2015'!$1:$1,0)) -> 100.41 | ... BT22: =INDEX('ИПЦ raw2015'!$1:$1048576, MATCH($J22,'ИПЦ raw2015'!$A:$A,0),MATCH(MoM!BT$1,'ИПЦ raw2015'!$1:$1,0)) -> 100.48
A23: =Веса!A23 -> 1 | B23: =A23 -> 1 | C23: =БИПЦ_НДС!E23 -> 1 | D23: =1-C23 -> 0 | E23: 1 | F23: 0 | G23: 0 | H23: 0 | I23: 0 | J23: =L23 -> Соленые и копченые деликатесные продукты из рыбы, кг | K23: Соленые и копченые деликатесные продукты из рыбы, кг | L23: Соленые и копченые деликатесные продукты из рыбы, кг | M23: =INDEX('ИПЦ raw2015'!$1:$1048576, MATCH($J23,'ИПЦ raw2015'!$A:$A,0),MATCH(MoM!M$1,'ИПЦ raw2015'!$1:$1,0)) -> 107.47 | N23: =INDEX('ИПЦ raw2015'!$1:$1048576, MATCH($J23,'ИПЦ raw2015'!$A:$A,0),MATCH(MoM!N$1,'ИПЦ raw2015'!$1:$1,0)) -> 105.19 | O23: =INDEX('ИПЦ raw2015'!$1:$1048576, MATCH($J23,'ИПЦ raw2015'!$A:$A,0),MATCH(MoM!O$1,'ИПЦ raw2015'!$1:$1,0)) -> 102.31 | P23: =INDEX('ИПЦ raw2015'!$1:$1048576, MATCH($J23,'ИПЦ raw2015'!$A:$A,0),MATCH(MoM!P$1,'ИПЦ raw2015'!$1:$1,0)) -> 100.42 | Q23: =INDEX('ИПЦ raw2015'!$1:$1048576, MATCH($J23,'ИПЦ raw2015'!$A:$A,0),MATCH(MoM!Q$1,'ИПЦ raw2015'!$1:$1,0)) -> 99.66 | R23: =INDEX('ИПЦ raw2015'!$1:$1048576, MATCH($J23,'ИПЦ raw2015'!$A:$A,0),MATCH(MoM!R$1,'ИПЦ raw2015'!$1:$1,0)) -> 99.73 | S23: =INDEX('ИПЦ raw2015'!$1:$1048576, MATCH($J23,'ИПЦ raw2015'!$A:$A,0),MATCH(MoM!S$1,'ИПЦ raw2015'!$1:$1,0)) -> 99.35 | T23: =INDEX('ИПЦ raw2015'!$1:$1048576, MATCH($J23,'ИПЦ raw2015'!$A:$A,0),MATCH(MoM!T$1,'ИПЦ raw2015'!$1:$1,0)) -> 99.82 | ... BT23: =INDEX('ИПЦ raw2015'!$1:$1048576, MATCH($J23,'ИПЦ raw2015'!$A:$A,0),MATCH(MoM!BT$1,'ИПЦ raw2015'!$1:$1,0)) -> 100.34
A24: =Веса!A24 -> 1 | B24: =A24 -> 1 | C24: =БИПЦ_НДС!E24 -> 1 | D24: =1-C24 -> 0 | E24: 1 | F24: 0 | G24: 0 | H24: 0 | I24: 0 | J24: =L24 -> Икра лососевых рыб отечественная, кг | K24: Икра лососевых рыб отечественная, кг | L24: Икра лососевых рыб отечественная, кг | M24: =INDEX('ИПЦ raw2015'!$1:$1048576, MATCH($J24,'ИПЦ raw2015'!$A:$A,0),MATCH(MoM!M$1,'ИПЦ raw2015'!$1:$1,0)) -> 101.32 | N24: =INDEX('ИПЦ raw2015'!$1:$1048576, MATCH($J24,'ИПЦ raw2015'!$A:$A,0),MATCH(MoM!N$1,'ИПЦ raw2015'!$1:$1,0)) -> 100.87 | O24: =INDEX('ИПЦ raw2015'!$1:$1048576, MATCH($J24,'ИПЦ raw2015'!$A:$A,0),MATCH(MoM!O$1,'ИПЦ raw2015'!$1:$1,0)) -> 100.63 | P24: =INDEX('ИПЦ raw2015'!$1:$1048576, MATCH($J24,'ИПЦ raw2015'!$A:$A,0),MATCH(MoM!P$1,'ИПЦ raw2015'!$1:$1,0)) -> 100.47 | Q24: =INDEX('ИПЦ raw2015'!$1:$1048576, MATCH($J24,'ИПЦ raw2015'!$A:$A,0),MATCH(MoM!Q$1,'ИПЦ raw2015'!$1:$1,0)) -> 100.52 | R24: =INDEX('ИПЦ raw2015'!$1:$1048576, MATCH($J24,'ИПЦ raw2015'!$A:$A,0),MATCH(MoM!R$1,'ИПЦ raw2015'!$1:$1,0)) -> 100.01 | S24: =INDEX('ИПЦ raw2015'!$1:$1048576, MATCH($J24,'ИПЦ raw2015'!$A:$A,0),MATCH(MoM!S$1,'ИПЦ raw2015'!$1:$1,0)) -> 99.98 | T24: =INDEX('ИПЦ raw2015'!$1:$1048576, MATCH($J24,'ИПЦ raw2015'!$A:$A,0),MATCH(MoM!T$1,'ИПЦ raw2015'!$1:$1,0)) -> 100.44 | ... BT24: =INDEX('ИПЦ raw2015'!$1:$1048576, MATCH($J24,'ИПЦ raw2015'!$A:$A,0),MATCH(MoM!BT$1,'ИПЦ raw2015'!$1:$1,0)) -> 100.23
A25: =Веса!A25 -> 1 | B25: =A25 -> 1 | C25: =БИПЦ_НДС!E25 -> 0 | D25: =1-C25 -> 1 | E25: 1 | F25: 0 | G25: 0 | H25: 0 | I25: 0 | J25: =L25 -> Рыба мороженая разделанная (кроме лососевых пород), кг | K25: Рыба мороженая разделанная (кроме лососевых пород), кг | L25: Рыба мороженая разделанная (кроме лососевых пород), кг | M25: =INDEX('ИПЦ raw2015'!$1:$1048576, MATCH($J25,'ИПЦ raw2015'!$A:$A,0),MATCH(MoM!M$1,'ИПЦ raw2015'!$1:$1,0)) -> 107.5 | N25: =INDEX('ИПЦ raw2015'!$1:$1048576, MATCH($J25,'ИПЦ raw2015'!$A:$A,0),MATCH(MoM!N$1,'ИПЦ raw2015'!$1:$1,0)) -> 107.9 | O25: =INDEX('ИПЦ raw2015'!$1:$1048576, MATCH($J25,'ИПЦ raw2015'!$A:$A,0),MATCH(MoM!O$1,'ИПЦ raw2015'!$1:$1,0)) -> 104.23 | P25: =INDEX('ИПЦ raw2015'!$1:$1048576, MATCH($J25,'ИПЦ raw2015'!$A:$A,0),MATCH(MoM!P$1,'ИПЦ raw2015'!$1:$1,0)) -> 101.45 | Q25: =INDEX('ИПЦ raw2015'!$1:$1048576, MATCH($J25,'ИПЦ raw2015'!$A:$A,0),MATCH(MoM!Q$1,'ИПЦ raw2015'!$1:$1,0)) -> 99.08 | R25: =INDEX('ИПЦ raw2015'!$1:$1048576, MATCH($J25,'ИПЦ raw2015'!$A:$A,0),MATCH(MoM!R$1,'ИПЦ raw2015'!$1:$1,0)) -> 99.2 | S25: =INDEX('ИПЦ raw2015'!$1:$1048576, MATCH($J25,'ИПЦ raw2015'!$A:$A,0),MATCH(MoM!S$1,'ИПЦ raw2015'!$1:$1,0)) -> 99.69 | T25: =INDEX('ИПЦ raw2015'!$1:$1048576, MATCH($J25,'ИПЦ raw2015'!$A:$A,0),MATCH(MoM!T$1,'ИПЦ raw2015'!$1:$1,0)) -> 99.95 | ... BT25: =INDEX('ИПЦ raw2015'!$1:$1048576, MATCH($J25,'ИПЦ raw2015'!$A:$A,0),MATCH(MoM!BT$1,'ИПЦ raw2015'!$1:$1,0)) -> 100.79
A26: =Веса!A26 -> 1 | B26: =A26 -> 1 | C26: =БИПЦ_НДС!E26 -> 1 | D26: =1-C26 -> 0 | E26: 1 | F26: 0 | G26: 0 | H26: 0 | I26: 0 | J26: =L26 -> Рыба охлажденная и мороженая разделанная лососевых пород, кг | K26: Рыба охлажденная и мороженая разделанная лососевых пород, кг | L26: Рыба охлажденная и мороженая разделанная лососевых пород, кг | M26: =INDEX('ИПЦ raw2015'!$1:$1048576, MATCH($J26,'ИПЦ raw2015'!$A:$A,0),MATCH(MoM!M$1,'ИПЦ raw2015'!$1:$1,0)) -> 107.79 | N26: =INDEX('ИПЦ raw2015'!$1:$1048576, MATCH($J26,'ИПЦ raw2015'!$A:$A,0),MATCH(MoM!N$1,'ИПЦ raw2015'!$1:$1,0)) -> 103.73 | O26: =INDEX('ИПЦ raw2015'!$1:$1048576, MATCH($J26,'ИПЦ raw2015'!$A:$A,0),MATCH(MoM!O$1,'ИПЦ raw2015'!$1:$1,0)) -> 102.8 | P26: =INDEX('ИПЦ raw2015'!$1:$1048576, MATCH($J26,'ИПЦ raw2015'!$A:$A,0),MATCH(MoM!P$1,'ИПЦ raw2015'!$1:$1,0)) -> 100.83 | Q26: =INDEX('ИПЦ raw2015'!$1:$1048576, MATCH($J26,'ИПЦ raw2015'!$A:$A,0),MATCH(MoM!Q$1,'ИПЦ raw2015'!$1:$1,0)) -> 100.13 | R26: =INDEX('ИПЦ raw2015'!$1:$1048576, MATCH($J26,'ИПЦ raw2015'!$A:$A,0),MATCH(MoM!R$1,'ИПЦ raw2015'!$1:$1,0)) -> 100.51 | S26: =INDEX('ИПЦ raw2015'!$1:$1048576, MATCH($J26,'ИПЦ raw2015'!$A:$A,0),MATCH(MoM!S$1,'ИПЦ raw2015'!$1:$1,0)) -> 99.9 | T26: =INDEX('ИПЦ raw2015'!$1:$1048576, MATCH($J26,'ИПЦ raw2015'!$A:$A,0),MATCH(MoM!T$1,'ИПЦ raw2015'!$1:$1,0)) -> 100.48 | ... BT26: =INDEX('ИПЦ raw2015'!$1:$1048576, MATCH($J26,'ИПЦ raw2015'!$A:$A,0),MATCH(MoM!BT$1,'ИПЦ raw2015'!$1:$1,0)) -> 100.34
A27: =Веса!A27 -> 1 | B27: =A27 -> 1 | C27: =БИПЦ_НДС!E27 -> 0 | D27: =1-C27 -> 1 | E27: 1 | F27: 0 | G27: 0 | H27: 0 | I27: 0 | J27: =L27 -> Рыба мороженая неразделанная, кг | K27: Рыба мороженая неразделанная, кг | L27: Рыба мороженая неразделанная, кг | M27: =INDEX('ИПЦ raw2015'!$1:$1048576, MATCH($J27,'ИПЦ raw2015'!$A:$A,0),MATCH(MoM!M$1,'ИПЦ raw2015'!$1:$1,0)) -> 107.7 | N27: =INDEX('ИПЦ raw2015'!$1:$1048576, MATCH($J27,'ИПЦ raw2015'!$A:$A,0),MATCH(MoM!N$1,'ИПЦ raw2015'!$1:$1,0)) -> 108.06 | O27: =INDEX('ИПЦ raw2015'!$1:$1048576, MATCH($J27,'ИПЦ raw2015'!$A:$A,0),MATCH(MoM!O$1,'ИПЦ raw2015'!$1:$1,0)) -> 104.06 | P27: =INDEX('ИПЦ raw2015'!$1:$1048576, MATCH($J27,'ИПЦ raw2015'!$A:$A,0),MATCH(MoM!P$1,'ИПЦ raw2015'!$1:$1,0)) -> 101.38 | Q27: =INDEX('ИПЦ raw2015'!$1:$1048576, MATCH($J27,'ИПЦ raw2015'!$A:$A,0),MATCH(MoM!Q$1,'ИПЦ raw2015'!$1:$1,0)) -> 99.36 | R27: =INDEX('ИПЦ raw2015'!$1:$1048576, MATCH($J27,'ИПЦ raw2015'!$A:$A,0),MATCH(MoM!R$1,'ИПЦ raw2015'!$1:$1,0)) -> 99.7 | S27: =INDEX('ИПЦ raw2015'!$1:$1048576, MATCH($J27,'ИПЦ raw2015'!$A:$A,0),MATCH(MoM!S$1,'ИПЦ raw2015'!$1:$1,0)) -> 99.81 | T27: =INDEX('ИПЦ raw2015'!$1:$1048576, MATCH($J27,'ИПЦ raw2015'!$A:$A,0),MATCH(MoM!T$1,'ИПЦ raw2015'!$1:$1,0)) -> 99.22 | ... BT27: =INDEX('ИПЦ raw2015'!$1:$1048576, MATCH($J27,'ИПЦ raw2015'!$A:$A,0),MATCH(MoM!BT$1,'ИПЦ raw2015'!$1:$1,0)) -> 100.42
A28: =Веса!A28 -> 1 | B28: =A28 -> 1 | C28: =БИПЦ_НДС!E28 -> 0 | D28: =1-C28 -> 1 | E28: 1 | F28: 0 | G28: 0 | H28: 0 | I28: 0 | J28: =L28 -> Филе рыбное, кг | K28: Филе рыбное, кг | L28: Филе рыбное, кг | M28: =INDEX('ИПЦ raw2015'!$1:$1048576, MATCH($J28,'ИПЦ raw2015'!$A:$A,0),MATCH(MoM!M$1,'ИПЦ raw2015'!$1:$1,0)) -> 106.83 | N28: =INDEX('ИПЦ raw2015'!$1:$1048576, MATCH($J28,'ИПЦ raw2015'!$A:$A,0),MATCH(MoM!N$1,'ИПЦ raw2015'!$1:$1,0)) -> 107.22 | O28: =INDEX('ИПЦ raw2015'!$1:$1048576, MATCH($J28,'ИПЦ raw2015'!$A:$A,0),MATCH(MoM!O$1,'ИПЦ raw2015'!$1:$1,0)) -> 103.74 | P28: =INDEX('ИПЦ raw2015'!$1:$1048576, MATCH($J28,'ИПЦ raw2015'!$A:$A,0),MATCH(MoM!P$1,'ИПЦ raw2015'!$1:$1,0)) -> 101.49 | Q28: =INDEX('ИПЦ raw2015'!$1:$1048576, MATCH($J28,'ИПЦ raw2015'!$A:$A,0),MATCH(MoM!Q$1,'ИПЦ raw2015'!$1:$1,0)) -> 100.69 | R28: =INDEX('ИПЦ raw2015'!$1:$1048576, MATCH($J28,'ИПЦ raw2015'!$A:$A,0),MATCH(MoM!R$1,'ИПЦ raw2015'!$1:$1,0)) -> 100.3 | S28: =INDEX('ИПЦ raw2015'!$1:$1048576, MATCH($J28,'ИПЦ raw2015'!$A:$A,0),MATCH(MoM!S$1,'ИПЦ raw2015'!$1:$1,0)) -> 99.89 | T28: =INDEX('ИПЦ raw2015'!$1:$1048576, MATCH($J28,'ИПЦ raw2015'!$A:$A,0),MATCH(MoM!T$1,'ИПЦ raw2015'!$1:$1,0)) -> 100.26 | ... BT28: =INDEX('ИПЦ raw2015'!$1:$1048576, MATCH($J28,'ИПЦ raw2015'!$A:$A,0),MATCH(MoM!BT$1,'ИПЦ raw2015'!$1:$1,0)) -> 100.39
