Workbook

Sheet Оценка накоп эффекта
A1: time_period | B1: real_treatment | C1: excluded_Говядина бескостная, кг | D1: excluded_Свинина (кроме бескостного мяса), кг | E1: excluded_Свинина бескостная, кг | F1: excluded_Баранина (кроме бескостного мяса), кг | G1: excluded_Куры охлажденные и мороженые, кг | H1: excluded_Окорочка куриные, кг | I1: excluded_Мясо индейки,кг | J1: excluded_Печень говяжья, свиная, кг | K1: excluded_Фарш мясной, кг | L1: excluded_Пельмени, манты, равиоли, кг | M1: excluded_Сосиски, сардельки, кг | N1: excluded_Колбаса полукопченая и варено-копченая, кг | O1: excluded_Колбаса сырокопченая, кг | P1: excluded_Колбаса вареная, кг | Q1: excluded_Кулинарные изделия из птицы, кг | R1: excluded_Консервы мясные, кг | S1: excluded_Консервы мясные для детского питания, кг | T1: excluded_Рыба живая и охлажденная, кг | U1: excluded_Рыба соленая, маринованная, копченая, кг | V1: excluded_Рыба мороженая разделанная (кроме лососевых пород), кг | W1: excluded_Рыба мороженая неразделанная, кг | X1: excluded_Филе рыбное, кг | Y1: excluded_Креветки мороженые неразделанные, кг | Z1: excluded_Кальмары мороженые,кг | AA1: excluded_Сельдь соленая, кг | AB1: excluded_Филе сельди соленое, кг | AC1: excluded_Консервы рыбные натуральные и с добавлением масла, кг | AD1: excluded_Консервы рыбные в томатном соусе, кг | AE1: excluded_Масло сливочное, кг | AF1: excluded_Масло подсолнечное, л | AG1: excluded_Масло оливковое, л | AH1: excluded_Маргарин, кг | AI1: excluded_Молоко питьевое цельное пастеризованное 2,5-3,2% жирности, л | AJ1: excluded_Молоко питьевое цельное пастеризованное более 3,2% жирности, л | AK1: excluded_Сметана, кг | AL1: excluded_Кисломолочные продукты, кг | AM1: excluded_Йогурт, кг | AN1: excluded_Сливки питьевые, л | AO1: excluded_Творог, кг | AP1: excluded_Молоко сгущенное с сахаром, кг | AQ1: excluded_Молоко для детей, л | AR1: excluded_Творожок детский, кг | AS1: excluded_Смеси сухие молочные для детского питания, кг | AT1: excluded_Национальные сыры и брынза, кг | AU1: excluded_Консервы овощные для детского питания, кг | AV1: excluded_Соки фруктовые, л | AW1: excluded_Консервы фруктово-ягодные для детского питания, кг | AX1: excluded_Соль поваренная пищевая, кг | AY1: excluded_Мука пшеничная, кг | AZ1: excluded_Хлеб из ржаной муки и из смеси муки ржаной и пшеничной, кг | BA1: excluded_Хлеб и булочные изделия из пшеничной муки различных сортов, кг | BB1: excluded_Булочные изделия сдобные из муки высшего сорта штучные, кг | BC1: excluded_Бараночные изделия, кг | BD1: excluded_Хлопья из злаков (сухие завтраки), кг | BE1: excluded_Крупа манная, кг | BF1: excluded_Горох и фасоль, кг | BG1: excluded_Крупы овсяная и перловая, кг | BH1: excluded_Овсяные хлопья "Геркулес", кг | BI1: excluded_Вермишель, кг | BJ1: excluded_Макаронные изделия из пшеничной муки высшего сорта, кг | BK1: excluded_Ягоды замороженные, кг | BL1: excluded_Мороженое сливочное, кг | BM1: excluded_Куртка для детей школьного возраста с верхом из плащевых тканей утепленная, шт. | BN1: excluded_Брюки для детей школьного возраста из полушерстяных тканей, шт. | BO1: excluded_Брюки для детей школьного возраста из джинсовой ткани, шт. | BP1: excluded_Рубашка верхняя для мальчиков школьного возраста, шт. | BQ1: excluded_Платье (платье-костюм, сарафан) для девочек школьного возраста, шт. | BR1: excluded_Блузка для девочек школьного возраста, шт. | BS1: excluded_Юбка для девочек школьного возраста, шт. | BT1: excluded_Куртка для детей дошкольного возраста с верхом из плащевых тканей утепленная, шт. | BU1: excluded_Комбинезон (костюм) утепленный для детей дошкольного возраста, шт. | BV1: excluded_Рубашка верхняя для мальчиков дошкольного возраста, шт. | BW1: excluded_Платье (сарафан) летнее для девочек дошкольного возраста, шт. | BX1: excluded_Комбинезон утепленный для детей до одного года, шт. | BY1: excluded_Пеленки для новорожденных, шт. | BZ1: excluded_Ползунки из хлопчатобумажного трикотажного полотна, шт. | CA1: excluded_Белье для новорожденных и детей ясельного возраста, шт. | CB1: excluded_Джемпер для детей школьного возраста, шт. | CC1: excluded_Костюм спортивный для детей школьного возраста, шт. | CD1: excluded_Костюм трикотажный для детей ясельного возраста, шт. | CE1: excluded_Трикотажная шапочка детская, шт. | CF1: excluded_Варежки (перчатки) детские, пара | CG1: excluded_Футболка детская, шт. | CH1: excluded_Трусы детские, шт. | CI1: excluded_Колготки детские, шт. | CJ1: excluded_Носки, гольфы детские, пара | CK1: excluded_Ботинки, полуботинки для детей школьного возраста, пара | CL1: excluded_Ботинки, полуботинки для детей дошкольного возраста, пара | CM1: excluded_Туфли детские летние (сандалеты), пара | CN1: excluded_Обувь домашняя с текстильным верхом для детей, пара | CO1: excluded_Сапоги цельнорезиновые для детей, пара | CP1: excluded_Коляска для новорожденного, шт. | CQ1: excluded_Матрас детский, шт. | CR1: excluded_Кровать для новорожденных,шт. | CS1: excluded_Тетрадь школьная, шт. | CT1: excluded_Альбом для рисования, шт. | CU1: excluded_Подгузники детские бумажные, 10 шт. | CV1: excluded_Набор фломастеров, набор | CW1: excluded_Газета в розницу, шт. | CX1: excluded_Книга художественная, шт. | CY1: excluded_Учебник, учебное пособие, дидактический материал для общеобразовательной школы, шт. | CZ1: excluded_Игрушки пластмассовые для детей ясельного возраста, шт. | DA1: excluded_Игрушки мягкие, шт. | DB1: excluded_Конструктор детский пластмассовый, набор | DC1: excluded_Корригирующие очки, шт. | DD1: excluded_Термометр медицинский электронный стандартный,шт. | DE1: excluded_Аппарат для измерения артериального давления электронный, шт. | DF1: excluded_Шприцы одноразовые, шт. | DG1: excluded_Термометр медицинский безртутный (галинстановый), шт. | DH1: excluded_Метамизол натрия, 10 таблеток | DI1: excluded_Нимесулид, 10 таблеток | DJ1: excluded_Активированный уголь, 250 мг, 10 таблеток | DK1: excluded_Нафазолин, 0,1%, 15 мл | DL1: excluded_Ренгалин, 20 таблеток | DM1: excluded_Йод, 10 мл | DN1: excluded_Левомеколь, мазь, 40 г | DO1: excluded_Мирамистин, 0,01%, 150 мл | DP1: excluded_Валерианы экстракт, 10 таблеток | DQ1: excluded_Валидол, 60 мг, 10 таблеток | DR1: excluded_Корвалол, 25 мл | DS1: excluded_Троксерутин, 2% гель, 40 г | DT1: excluded_Таурин, 4%, 5мл | DU1: excluded_Метилурацил, 10% мазь, 25 г | DV1: excluded_Бинт, шт. | DW1: excluded_Изготовление гроба, шт. | DX1: excluded_Аренда однокомнатной квартиры у частных лиц, месяц | DY1: excluded_Аренда двухкомнатной квартиры у частных лиц, месяц | DZ1: excluded_Проживание в студенческом общежитии, месяц | EA1: excluded_Посещение детского ясли-сада, день | EB1: excluded_Обучение в негосударственных общеобразовательных организациях, месяц | EC1: excluded_Дополнительные занятия в государственных и муниципальных общеобразовательных организациях очной формы обучения, академический час | ED1: excluded_Обучение в образовательных организациях среднего профессионального образования, семестр | EE1: excluded_Кинотеатры, билет | EF1: excluded_Театры, билет | EG1: excluded_Музеи и выставки, билет | EH1: excluded_Первичный консультативный прием у врача специалиста, посещение | EI1: excluded_Ультразвуковое исследование брюшной полости, исследование | EJ1: excluded_Диагностика на магнитно-резонансном или компьютерном томографе, услуга | EK1: excluded_Гастроскопия (ФГДС, ЭГДС), услуга | EL1: excluded_Физиотерапевтическое лечение, процедура | EM1: excluded_Общий анализ крови, анализ | EN1: excluded_Пребывание пациента в круглосуточном стационаре,койко день | EO1: excluded_Первичный консультативный осмотр больного у стоматолога, посещение | EP1: excluded_Удаление зуба под местным обезболиванием, удаление | EQ1: excluded_Изготовление съёмного протеза, протез | ER1: excluded_Изготовление коронки, шт. | ES1: excluded_Лечебный массаж, сеанс | ET1: excluded_Услуги сиделок, час | EU1: excluded_Плата за пользование потребительским кредитом (процентная ставка в стоимостном выражении), руб. | EV1: excluded_Годовая стоимость полиса добровольного страхования жилья от стандартных рисков, полис | EW1: excluded_Годовая стоимость полиса добровольного страхования легкового автомобиля от стандартных рисков, полис | EX1: excluded_Занятия в плавательных бассейнах, месяц | EY1: excluded_Клубная карта в фитнес-клуб, месяц
A2: 33 | C2: =(SC!$B34-SC!C34)/SC!C34*100 -> 1.8416269e-09 | D2: =(SC!$B34-SC!D34)/SC!D34*100 -> 1.6707857e-09 | E2: =(SC!$B34-SC!E34)/SC!E34*100 -> 1.7216006e-09 | F2: =(SC!$B34-SC!F34)/SC!F34*100 -> 1.9841573e-09 | G2: =(SC!$B34-SC!G34)/SC!G34*100 -> 2.0912716e-09 | H2: =(SC!$B34-SC!H34)/SC!H34*100 -> 1.7456259e-09 | I2: =(SC!$B34-SC!I34)/SC!I34*100 -> 2.3988145e-09 | J2: =(SC!$B34-SC!J34)/SC!J34*100 -> 1.9810598e-09 | ... EY2: =(SC!$B34-SC!EY34)/SC!EY34*100 -> 1.7577717e-09
A3: 34 | C3: =(SC!$B35-SC!C35)/SC!C35*100 -> 0.19276446 | D3: =(SC!$B35-SC!D35)/SC!D35*100 -> 0.2174756 | E3: =(SC!$B35-SC!E35)/SC!E35*100 -> 0.18458427 | F3: =(SC!$B35-SC!F35)/SC!F35*100 -> 0.15810044 | G3: =(SC!$B35-SC!G35)/SC!G35*100 -> 0.21272422 | H3: =(SC!$B35-SC!H35)/SC!H35*100 -> 0.18395805 | I3: =(SC!$B35-SC!I35)/SC!I35*100 -> 0.24701578 | J3: =(SC!$B35-SC!J35)/SC!J35*100 -> 0.19696196 | ... EY3: =(SC!$B35-SC!EY35)/SC!EY35*100 -> 0.19263364
A4: 35 | C4: =(SC!$B36-SC!C36)/SC!C36*100 -> 0.2857462 | D4: =(SC!$B36-SC!D36)/SC!D36*100 -> 0.32379337 | E4: =(SC!$B36-SC!E36)/SC!E36*100 -> 0.27269174 | F4: =(SC!$B36-SC!F36)/SC!F36*100 -> 0.23302792 | G4: =(SC!$B36-SC!G36)/SC!G36*100 -> 0.30643002 | H4: =(SC!$B36-SC!H36)/SC!H36*100 -> 0.2682194 | I4: =(SC!$B36-SC!I36)/SC!I36*100 -> 0.54375419 | J4: =(SC!$B36-SC!J36)/SC!J36*100 -> 0.29106809 | ... EY4: =(SC!$B36-SC!EY36)/SC!EY36*100 -> 0.28423957
A5: 36 | C5: =(SC!$B37-SC!C37)/SC!C37*100 -> 0.42371271 | D5: =(SC!$B37-SC!D37)/SC!D37*100 -> 0.46998727 | E5: =(SC!$B37-SC!E37)/SC!E37*100 -> 0.40521362 | F5: =(SC!$B37-SC!F37)/SC!F37*100 -> 0.355213 | G5: =(SC!$B37-SC!G37)/SC!G37*100 -> 0.45287865 | H5: =(SC!$B37-SC!H37)/SC!H37*100 -> 0.39582367 | I5: =(SC!$B37-SC!I37)/SC!I37*100 -> 0.7717989 | J5: =(SC!$B37-SC!J37)/SC!J37*100 -> 0.4303469 | ... EY5: =(SC!$B37-SC!EY37)/SC!EY37*100 -> 0.42008179
A6: 37 | C6: =(SC!$B38-SC!C38)/SC!C38*100 -> 0.83505724 | D6: =(SC!$B38-SC!D38)/SC!D38*100 -> 0.8963698 | E6: =(SC!$B38-SC!E38)/SC!E38*100 -> 0.81645801 | F6: =(SC!$B38-SC!F38)/SC!F38*100 -> 0.73341684 | G6: =(SC!$B38-SC!G38)/SC!G38*100 -> 0.87892241 | H6: =(SC!$B38-SC!H38)/SC!H38*100 -> 0.80508432 | I6: =(SC!$B38-SC!I38)/SC!I38*100 -> 1.3224033 | J6: =(SC!$B38-SC!J38)/SC!J38*100 -> 0.84539839 | ... EY6: =(SC!$B38-SC!EY38)/SC!EY38*100 -> 0.83083066
A7: 38 | C7: =(SC!$B39-SC!C39)/SC!C39*100 -> 1.1421336 | D7: =(SC!$B39-SC!D39)/SC!D39*100 -> 1.2133832 | E7: =(SC!$B39-SC!E39)/SC!E39*100 -> 1.1156175 | F7: =(SC!$B39-SC!F39)/SC!F39*100 -> 1.0760161 | G7: =(SC!$B39-SC!G39)/SC!G39*100 -> 1.193545 | H7: =(SC!$B39-SC!H39)/SC!H39*100 -> 1.1060482 | I7: =(SC!$B39-SC!I39)/SC!I39*100 -> 1.7412476 | J7: =(SC!$B39-SC!J39)/SC!J39*100 -> 1.1533319 | ... EY7: =(SC!$B39-SC!EY39)/SC!EY39*100 -> 1.1346774
A8: 39 | C8: =(SC!$B40-SC!C40)/SC!C40*100 -> 1.2848648 | D8: =(SC!$B40-SC!D40)/SC!D40*100 -> 1.3853412 | E8: =(SC!$B40-SC!E40)/SC!E40*100 -> 1.2521092 | F8: =(SC!$B40-SC!F40)/SC!F40*100 -> 1.1819421 | G8: =(SC!$B40-SC!G40)/SC!G40*100 -> 1.3525471 | H8: =(SC!$B40-SC!H40)/SC!H40*100 -> 1.2483692 | I8: =(SC!$B40-SC!I40)/SC!I40*100 -> 2.0179926 | J8: =(SC!$B40-SC!J40)/SC!J40*100 -> 1.3004 | ... EY8: =(SC!$B40-SC!EY40)/SC!EY40*100 -> 1.2779198
A9: 40 | C9: =(SC!$B41-SC!C41)/SC!C41*100 -> 1.3980783 | D9: =(SC!$B41-SC!D41)/SC!D41*100 -> 1.505777 | E9: =(SC!$B41-SC!E41)/SC!E41*100 -> 1.3608003 | F9: =(SC!$B41-SC!F41)/SC!F41*100 -> 1.3032578 | G9: =(SC!$B41-SC!G41)/SC!G41*100 -> 1.4689764 | H9: =(SC!$B41-SC!H41)/SC!H41*100 -> 1.3593054 | I9: =(SC!$B41-SC!I41)/SC!I41*100 -> 2.1361554 | J9: =(SC!$B41-SC!J41)/SC!J41*100 -> 1.4140442 | ... EY9: =(SC!$B41-SC!EY41)/SC!EY41*100 -> 1.3870152
A11: Для накоп эффекта | K11: Эффект из статистик накоп эффекта
B12: МЕДИАНА | C12: СРЕДНЕЕ | D12: 2,5% процентиль | E12: 97,5% процентиль | F12: 1% процентиль | G12: 99% процентиль | H12: МИН | I12: МАКС | L12: МЕДИАНА | M12: СРЕДНЕЕ | N12: 2,5% процентиль | O12: 97,5% процентиль | P12: 1% процентиль | Q12: 99% процентиль | R12: МИН | S12: МАКС
A13: 34 | B13: =MEDIAN(C3:EY3) -> 0.19332441 | C13: =AVERAGE(C3:EY3) -> 0.1948161 | D13: =_xlfn.PERCENTILE.EXC(C3:EY3, 0.025) -> 0.15514758 | E13: =_xlfn.PERCENTILE.EXC(C3:EY3, 0.975) -> 0.23389644 | F13: =_xlfn.PERCENTILE.EXC(C3:EY3, 0.01) -> 0.11594839 | G13: =_xlfn.PERCENTILE.EXC(C3:EY3, 0.99) -> 0.25982181 | H13: =MIN(C3:EY3) -> 0.11335781 | I13: =MAX(C3:EY3) -> 0.26520925 | K13: 34 | L13: =B13 -> 0.19332441 | M13: =C13 -> 0.1948161 | N13: =D13 -> 0.15514758 | O13: =E13 -> 0.23389644 | P13: =F13 -> 0.11594839 | Q13: =G13 -> 0.25982181 | R13: =H13 -> 0.11335781 | S13: =I13 -> 0.26520925
A14: 35 | B14: =MEDIAN(C4:EY4) -> 0.28545894 | C14: =AVERAGE(C4:EY4) -> 0.28917119 | D14: =_xlfn.PERCENTILE.EXC(C4:EY4, 0.025) -> 0.20133928 | E14: =_xlfn.PERCENTILE.EXC(C4:EY4, 0.975) -> 0.36932585 | F14: =_xlfn.PERCENTILE.EXC(C4:EY4, 0.01) -> 0.17531921 | G14: =_xlfn.PERCENTILE.EXC(C4:EY4, 0.99) -> 0.50272627 | H14: =MIN(C4:EY4) -> 0.16299817 | I14: =MAX(C4:EY4) -> 0.54375419 | K14: 35 | L14: =B14-B13 -> 0.092134527 | M14: =C14-C13 -> 0.094355087 | N14: =D14-D13 -> 0.0461917 | O14: =E14-E13 -> 0.1354294 | P14: =F14-F13 -> 0.059370815 | Q14: =G14-G13 -> 0.24290446 | R14: =H14-H13 -> 0.049640362 | S14: =I14-I13 -> 0.27854494
A15: 36 | B15: =MEDIAN(C5:EY5) -> 0.42220395 | C15: =AVERAGE(C5:EY5) -> 0.4285326 | D15: =_xlfn.PERCENTILE.EXC(C5:EY5, 0.025) -> 0.34726908 | E15: =_xlfn.PERCENTILE.EXC(C5:EY5, 0.975) -> 0.55417478 | F15: =_xlfn.PERCENTILE.EXC(C5:EY5, 0.01) -> 0.29858339 | G15: =_xlfn.PERCENTILE.EXC(C5:EY5, 0.99) -> 0.70702145 | H15: =MIN(C5:EY5) -> 0.28329773 | I15: =MAX(C5:EY5) -> 0.7717989 | K15: 36 | L15: =B15-B14 -> 0.13674501 | M15: =C15-C14 -> 0.13936141 | N15: =D15-D14 -> 0.14592981 | O15: =E15-E14 -> 0.18484894 | P15: =F15-F14 -> 0.12326419 | Q15: =G15-G14 -> 0.20429519 | R15: =H15-H14 -> 0.12029956 | S15: =I15-I14 -> 0.22804471
A16: 37 | B16: =MEDIAN(C6:EY6) -> 0.83405848 | C16: =AVERAGE(C6:EY6) -> 0.84283583 | D16: =_xlfn.PERCENTILE.EXC(C6:EY6, 0.025) -> 0.73421869 | E16: =_xlfn.PERCENTILE.EXC(C6:EY6, 0.975) -> 1.0084061 | F16: =_xlfn.PERCENTILE.EXC(C6:EY6, 0.01) -> 0.67826672 | G16: =_xlfn.PERCENTILE.EXC(C6:EY6, 0.99) -> 1.2028519 | H16: =MIN(C6:EY6) -> 0.66372519 | I16: =MAX(C6:EY6) -> 1.3224033 | K16: 37 | L16: =B16-B15 -> 0.41185453 | M16: =C16-C15 -> 0.41430322 | N16: =D16-D15 -> 0.38694961 | O16: =E16-E15 -> 0.4542313 | P16: =F16-F15 -> 0.37968332 | Q16: =G16-G15 -> 0.49583044 | R16: =H16-H15 -> 0.38042745 | S16: =I16-I15 -> 0.55060441
A17: 38 | B17: =MEDIAN(C7:EY7) -> 1.1405496 | C17: =AVERAGE(C7:EY7) -> 1.153322 | D17: =_xlfn.PERCENTILE.EXC(C7:EY7, 0.025) -> 1.0749952 | E17: =_xlfn.PERCENTILE.EXC(C7:EY7, 0.975) -> 1.3697686 | F17: =_xlfn.PERCENTILE.EXC(C7:EY7, 0.01) -> 1.0018247 | G17: =_xlfn.PERCENTILE.EXC(C7:EY7, 0.99) -> 1.5808064 | H17: =MIN(C7:EY7) -> 0.99039875 | I17: =MAX(C7:EY7) -> 1.7412476 | K17: 38 | L17: =B17-B16 -> 0.30649108 | M17: =C17-C16 -> 0.31048619 | N17: =D17-D16 -> 0.34077651 | O17: =E17-E16 -> 0.36136248 | P17: =F17-F16 -> 0.32355799 | Q17: =G17-G16 -> 0.37795447 | R17: =H17-H16 -> 0.32667357 | S17: =I17-I16 -> 0.41884428
A18: 39 | B18: =MEDIAN(C8:EY8) -> 1.2839241 | C18: =AVERAGE(C8:EY8) -> 1.3006512 | D18: =_xlfn.PERCENTILE.EXC(C8:EY8, 0.025) -> 1.1841625 | E18: =_xlfn.PERCENTILE.EXC(C8:EY8, 0.975) -> 1.5686394 | F18: =_xlfn.PERCENTILE.EXC(C8:EY8, 0.01) -> 1.1039123 | G18: =_xlfn.PERCENTILE.EXC(C8:EY8, 0.99) -> 1.8419559 | H18: =MIN(C8:EY8) -> 1.0145891 | I18: =MAX(C8:EY8) -> 2.0179926 | K18: 39 | L18: =B18-B17 -> 0.14337455 | M18: =C18-C17 -> 0.14732919 | N18: =D18-D17 -> 0.10916733 | O18: =E18-E17 -> 0.19887085 | P18: =F18-F17 -> 0.10208757 | Q18: =G18-G17 -> 0.26114952 | R18: =H18-H17 -> 0.024190325 | S18: =I18-I17 -> 0.27674504
A19: 40 | B19: =MEDIAN(C9:EY9) -> 1.3957846 | C19: =AVERAGE(C9:EY9) -> 1.4131469 | D19: =_xlfn.PERCENTILE.EXC(C9:EY9, 0.025) -> 1.3206936 | E19: =_xlfn.PERCENTILE.EXC(C9:EY9, 0.975) -> 1.6953952 | F19: =_xlfn.PERCENTILE.EXC(C9:EY9, 0.01) -> 1.1840691 | G19: =_xlfn.PERCENTILE.EXC(C9:EY9, 0.99) -> 1.9961969 | H19: =MIN(C9:EY9) -> 1.0658297 | I19: =MAX(C9:EY9) -> 2.1361554 | K19: 40 | L19: =B19-B18 -> 0.11186054 | M19: =C19-C18 -> 0.11249566 | N19: =D19-D18 -> 0.13653108 | O19: =E19-E18 -> 0.1267558 | P19: =F19-F18 -> 0.080156839 | Q19: =G19-G18 -> 0.15424098 | R19: =H19-H18 -> 0.051240632 | S19: =I19-I18 -> 0.11816273
A22: time_period | B22: real_treatment | C22: excluded_Говядина бескостная, кг | D22: excluded_Свинина (кроме бескостного мяса), кг | E22: excluded_Свинина бескостная, кг | F22: excluded_Баранина (кроме бескостного мяса), кг | G22: excluded_Куры охлажденные и мороженые, кг | H22: excluded_Окорочка куриные, кг | I22: excluded_Мясо индейки,кг | J22: excluded_Печень говяжья, свиная, кг | K22: excluded_Фарш мясной, кг | L22: excluded_Пельмени, манты, равиоли, кг | M22: excluded_Сосиски, сардельки, кг | N22: excluded_Колбаса полукопченая и варено-копченая, кг | O22: excluded_Колбаса сырокопченая, кг | P22: excluded_Колбаса вареная, кг | Q22: excluded_Кулинарные изделия из птицы, кг | R22: excluded_Консервы мясные, кг | S22: excluded_Консервы мясные для детского питания, кг | T22: excluded_Рыба живая и охлажденная, кг | U22: excluded_Рыба соленая, маринованная, копченая, кг | V22: excluded_Рыба мороженая разделанная (кроме лососевых пород), кг | W22: excluded_Рыба мороженая неразделанная, кг | X22: excluded_Филе рыбное, кг | Y22: excluded_Креветки мороженые неразделанные, кг | Z22: excluded_Кальмары мороженые,кг | AA22: excluded_Сельдь соленая, кг | AB22: excluded_Филе сельди соленое, кг | AC22: excluded_Консервы рыбные натуральные и с добавлением масла, кг | AD22: excluded_Консервы рыбные в томатном соусе, кг | AE22: excluded_Масло сливочное, кг | AF22: excluded_Масло подсолнечное, л | AG22: excluded_Масло оливковое, л | AH22: excluded_Маргарин, кг | AI22: excluded_Молоко питьевое цельное пастеризованное 2,5-3,2% жирности, л | AJ22: excluded_Молоко питьевое цельное пастеризованное более 3,2% жирности, л | AK22: excluded_Сметана, кг | AL22: excluded_Кисломолочные продукты, кг | AM22: excluded_Йогурт, кг | AN22: excluded_Сливки питьевые, л | AO22: excluded_Творог, кг | AP22: excluded_Молоко сгущенное с сахаром, кг | AQ22: excluded_Молоко для детей, л | AR22: excluded_Творожок детский, кг | AS22: excluded_Смеси сухие молочные для детского питания, кг | AT22: excluded_Национальные сыры и брынза, кг | AU22: excluded_Консервы овощные для детского питания, кг | AV22: excluded_Соки фруктовые, л | AW22: excluded_Консервы фруктово-ягодные для детского питания, кг | AX22: excluded_Соль поваренная пищевая, кг | AY22: excluded_Мука пшеничная, кг | AZ22: excluded_Хлеб из ржаной муки и из смеси муки ржаной и пшеничной, кг | BA22: excluded_Хлеб и булочные изделия из пшеничной муки различных сортов, кг | BB22: excluded_Булочные изделия сдобные из муки высшего сорта штучные, кг | BC22: excluded_Бараночные изделия, кг | BD22: excluded_Хлопья из злаков (сухие завтраки), кг | BE22: excluded_Крупа манная, кг | BF22: excluded_Горох и фасоль, кг | BG22: excluded_Крупы овсяная и перловая, кг | BH22: excluded_Овсяные хлопья "Геркулес", кг | BI22: excluded_Вермишель, кг | BJ22: excluded_Макаронные изделия из пшеничной муки высшего сорта, кг | BK22: excluded_Ягоды замороженные, кг | BL22: excluded_Мороженое сливочное, кг | BM22: excluded_Куртка для детей школьного возраста с верхом из плащевых тканей утепленная, шт. | BN22: excluded_Брюки для детей школьного возраста из полушерстяных тканей, шт. | BO22: excluded_Брюки для детей школьного возраста из джинсовой ткани, шт. | BP22: excluded_Рубашка верхняя для мальчиков школьного возраста, шт. | BQ22: excluded_Платье (платье-костюм, сарафан) для девочек школьного возраста, шт. | BR22: excluded_Блузка для девочек школьного возраста, шт. | BS22: excluded_Юбка для девочек школьного возраста, шт. | BT22: excluded_Куртка для детей дошкольного возраста с верхом из плащевых тканей утепленная, шт. | BU22: excluded_Комбинезон (костюм) утепленный для детей дошкольного возраста, шт. | BV22: excluded_Рубашка верхняя для мальчиков дошкольного возраста, шт. | BW22: excluded_Платье (сарафан) летнее для девочек дошкольного возраста, шт. | BX22: excluded_Комбинезон утепленный для детей до одного года, шт. | BY22: excluded_Пеленки для новорожденных, шт. | BZ22: excluded_Ползунки из хлопчатобумажного трикотажного полотна, шт. | CA22: excluded_Белье для новорожденных и детей ясельного возраста, шт. | CB22: excluded_Джемпер для детей школьного возраста, шт. | CC22: excluded_Костюм спортивный для детей школьного возраста, шт. | CD22: excluded_Костюм трикотажный для детей ясельного возраста, шт. | CE22: excluded_Трикотажная шапочка детская, шт. | CF22: excluded_Варежки (перчатки) детские, пара | CG22: excluded_Футболка детская, шт. | CH22: excluded_Трусы детские, шт. | CI22: excluded_Колготки детские, шт. | CJ22: excluded_Носки, гольфы детские, пара | CK22: excluded_Ботинки, полуботинки для детей школьного возраста, пара | CL22: excluded_Ботинки, полуботинки для детей дошкольного возраста, пара | CM22: excluded_Туфли детские летние (сандалеты), пара | CN22: excluded_Обувь домашняя с текстильным верхом для детей, пара | CO22: excluded_Сапоги цельнорезиновые для детей, пара | CP22: excluded_Коляска для новорожденного, шт. | CQ22: excluded_Матрас детский, шт. | CR22: excluded_Кровать для новорожденных,шт. | CS22: excluded_Тетрадь школьная, шт. | CT22: excluded_Альбом для рисования, шт. | CU22: excluded_Подгузники детские бумажные, 10 шт. | CV22: excluded_Набор фломастеров, набор | CW22: excluded_Газета в розницу, шт. | CX22: excluded_Книга художественная, шт. | CY22: excluded_Учебник, учебное пособие, дидактический материал для общеобразовательной школы, шт. | CZ22: excluded_Игрушки пластмассовые для детей ясельного возраста, шт. | DA22: excluded_Игрушки мягкие, шт. | DB22: excluded_Конструктор детский пластмассовый, набор | DC22: excluded_Корригирующие очки, шт. | DD22: excluded_Термометр медицинский электронный стандартный,шт. | DE22: excluded_Аппарат для измерения артериального давления электронный, шт. | DF22: excluded_Шприцы одноразовые, шт. | DG22: excluded_Термометр медицинский безртутный (галинстановый), шт. | DH22: excluded_Метамизол натрия, 10 таблеток | DI22: excluded_Нимесулид, 10 таблеток | DJ22: excluded_Активированный уголь, 250 мг, 10 таблеток | DK22: excluded_Нафазолин, 0,1%, 15 мл | DL22: excluded_Ренгалин, 20 таблеток | DM22: excluded_Йод, 10 мл | DN22: excluded_Левомеколь, мазь, 40 г | DO22: excluded_Мирамистин, 0,01%, 150 мл | DP22: excluded_Валерианы экстракт, 10 таблеток | DQ22: excluded_Валидол, 60 мг, 10 таблеток | DR22: excluded_Корвалол, 25 мл | DS22: excluded_Троксерутин, 2% гель, 40 г | DT22: excluded_Таурин, 4%, 5мл | DU22: excluded_Метилурацил, 10% мазь, 25 г | DV22: excluded_Бинт, шт. | DW22: excluded_Изготовление гроба, шт. | DX22: excluded_Аренда однокомнатной квартиры у частных лиц, месяц | DY22: excluded_Аренда двухкомнатной квартиры у частных лиц, месяц | DZ22: excluded_Проживание в студенческом общежитии, месяц | EA22: excluded_Посещение детского ясли-сада, день | EB22: excluded_Обучение в негосударственных общеобразовательных организациях, месяц | EC22: excluded_Дополнительные занятия в государственных и муниципальных общеобразовательных организациях очной формы обучения, академический час | ED22: excluded_Обучение в образовательных организациях среднего профессионального образования, семестр | EE22: excluded_Кинотеатры, билет | EF22: excluded_Театры, билет | EG22: excluded_Музеи и выставки, билет | EH22: excluded_Первичный консультативный прием у врача специалиста, посещение | EI22: excluded_Ультразвуковое исследование брюшной полости, исследование | EJ22: excluded_Диагностика на магнитно-резонансном или компьютерном томографе, услуга | EK22: excluded_Гастроскопия (ФГДС, ЭГДС), услуга | EL22: excluded_Физиотерапевтическое лечение, процедура | EM22: excluded_Общий анализ крови, анализ | EN22: excluded_Пребывание пациента в круглосуточном стационаре,койко день | EO22: excluded_Первичный консультативный осмотр больного у стоматолога, посещение | EP22: excluded_Удаление зуба под местным обезболиванием, удаление | EQ22: excluded_Изготовление съёмного протеза, протез | ER22: excluded_Изготовление коронки, шт. | ES22: excluded_Лечебный массаж, сеанс | ET22: excluded_Услуги сиделок, час | EU22: excluded_Плата за пользование потребительским кредитом (процентная ставка в стоимостном выражении), руб. | EV22: excluded_Годовая стоимость полиса добровольного страхования жилья от стандартных рисков, полис | EW22: excluded_Годовая стоимость полиса добровольного страхования легкового автомобиля от стандартных рисков, полис | EX22: excluded_Занятия в плавательных бассейнах, месяц | EY22: excluded_Клубная карта в фитнес-клуб, месяц
A23: 33 | C23: =C2 -> 1.8416269e-09 | D23: =D2 -> 1.6707857e-09 | E23: =E2 -> 1.7216006e-09 | F23: =F2 -> 1.9841573e-09 | G23: =G2 -> 2.0912716e-09 | H23: =H2 -> 1.7456259e-09 | I23: =I2 -> 2.3988145e-09 | J23: =J2 -> 1.9810598e-09 | ... EY23: =EY2 -> 1.7577717e-09
A24: 34 | C24: =C3-C2 -> 0.19276446 | D24: =D3-D2 -> 0.2174756 | E24: =E3-E2 -> 0.18458427 | F24: =F3-F2 -> 0.15810044 | G24: =G3-G2 -> 0.21272422 | H24: =H3-H2 -> 0.18395805 | I24: =I3-I2 -> 0.24701578 | J24: =J3-J2 -> 0.19696196 | ... EY24: =EY3-EY2 -> 0.19263364
A25: 35 | C25: =C4-C3 -> 0.092981732 | D25: =D4-D3 -> 0.10631777 | E25: =E4-E3 -> 0.088107471 | F25: =F4-F3 -> 0.074927477 | G25: =G4-G3 -> 0.093705793 | H25: =H4-H3 -> 0.084261357 | I25: =I4-I3 -> 0.29673841 | J25: =J4-J3 -> 0.094106134 | ... EY25: =EY4-EY3 -> 0.091605927
A26: 36 | C26: =C5-C4 -> 0.13796651 | D26: =D5-D4 -> 0.14619389 | E26: =E5-E4 -> 0.13252188 | F26: =F5-F4 -> 0.12218508 | G26: =G5-G4 -> 0.14644864 | H26: =H5-H4 -> 0.12760426 | I26: =I5-I4 -> 0.22804471 | J26: =J5-J4 -> 0.1392788 | ... EY26: =EY5-EY4 -> 0.13584222
A27: 37 | C27: =C6-C5 -> 0.41134453 | D27: =D6-D5 -> 0.42638254 | E27: =E6-E5 -> 0.41124438 | F27: =F6-F5 -> 0.37820383 | G27: =G6-G5 -> 0.42604376 | H27: =H6-H5 -> 0.40926065 | I27: =I6-I5 -> 0.55060441 | J27: =J6-J5 -> 0.4150515 | ... EY27: =EY6-EY5 -> 0.41074887
A28: 38 | C28: =C7-C6 -> 0.3070764 | D28: =D7-D6 -> 0.31701336 | E28: =E7-E6 -> 0.29915951 | F28: =F7-F6 -> 0.3425993 | G28: =G7-G6 -> 0.31462257 | H28: =H7-H6 -> 0.30096387 | I28: =I7-I6 -> 0.41884428 | J28: =J7-J6 -> 0.30793352 | ... EY28: =EY7-EY6 -> 0.30384673
A29: 39 | C29: =C8-C7 -> 0.14273121 | D29: =D8-D7 -> 0.17195808 | E29: =E8-E7 -> 0.13649165 | F29: =F8-F7 -> 0.10592593 | G29: =G8-G7 -> 0.15900208 | H29: =H8-H7 -> 0.14232099 | I29: =I8-I7 -> 0.27674504 | J29: =J8-J7 -> 0.14706805 | ... EY29: =EY8-EY7 -> 0.14324239
A30: 40 | C30: =C9-C8 -> 0.11321344 | D30: =D9-D8 -> 0.12043579 | E30: =E9-E8 -> 0.10869109 | F30: =F9-F8 -> 0.12131572 | G30: =G9-G8 -> 0.11642933 | H30: =H9-H8 -> 0.11093623 | I30: =I9-I8 -> 0.11816273 | J30: =J9-J8 -> 0.11364427 | ... EY30: =EY9-EY8 -> 0.10909544
B33: МЕДИАНА | C33: Среднее | D33: 2,5-й процентиль | E33: 97,5-й процентиль | F33: 1% процентиль | G33: 99% процентиль | H33: МИН | I33: МАКС
A34: 34 | B34: =MEDIAN(C24:EY24) -> 0.19332441 | C34: =AVERAGE(C24:EY24) -> 0.1948161 | D34: =_xlfn.PERCENTILE.EXC(C24:EY24, 0.025) -> 0.15514757 | E34: =_xlfn.PERCENTILE.EXC(C24:EY24, 0.975) -> 0.23389644 | F34: =_xlfn.PERCENTILE.EXC(C24:EY24, 0.01) -> 0.11594839 | G34: =_xlfn.PERCENTILE.EXC(C24:EY24, 0.99) -> 0.25982181 | H34: =MIN(C24:EY24) -> 0.11335781 | I34: =MAX(C24:EY24) -> 0.26520925 | J34: 45931
A35: 35 | B35: =MEDIAN(C25:EY25) -> 0.092562438 | C35: =AVERAGE(C25:EY25) -> 0.094355087 | D35: =_xlfn.PERCENTILE.EXC(C25:EY25, 0.025) -> 0.064956817 | E35: =_xlfn.PERCENTILE.EXC(C25:EY25, 0.975) -> 0.14274421 | F35: =_xlfn.PERCENTILE.EXC(C25:EY25, 0.01) -> 0.031310396 | G35: =_xlfn.PERCENTILE.EXC(C25:EY25, 0.99) -> 0.24588601 | H35: =MIN(C25:EY25) -> 0.011983237 | I35: =MAX(C25:EY25) -> 0.29673841 | J35: 45962
A36: 36 | B36: =MEDIAN(C26:EY26) -> 0.13663639 | C36: =AVERAGE(C26:EY26) -> 0.13936141 | D36: =_xlfn.PERCENTILE.EXC(C26:EY26, 0.025) -> 0.12629989 | E36: =_xlfn.PERCENTILE.EXC(C26:EY26, 0.975) -> 0.18477265 | F36: =_xlfn.PERCENTILE.EXC(C26:EY26, 0.01) -> 0.12131774 | G36: =_xlfn.PERCENTILE.EXC(C26:EY26, 0.99) -> 0.2063569 | H36: =MIN(C26:EY26) -> 0.12029956 | I36: =MAX(C26:EY26) -> 0.22804471 | J36: 45992
A37: 37 | B37: =MEDIAN(C27:EY27) -> 0.41238742 | C37: =AVERAGE(C27:EY27) -> 0.41430322 | D37: =_xlfn.PERCENTILE.EXC(C27:EY27, 0.025) -> 0.38610752 | E37: =_xlfn.PERCENTILE.EXC(C27:EY27, 0.975) -> 0.45115057 | F37: =_xlfn.PERCENTILE.EXC(C27:EY27, 0.01) -> 0.36203635 | G37: =_xlfn.PERCENTILE.EXC(C27:EY27, 0.99) -> 0.50580163 | H37: =MIN(C27:EY27) -> 0.34305713 | I37: =MAX(C27:EY27) -> 0.55060441 | J37: 46023
A38: 38 | B38: =MEDIAN(C28:EY28) -> 0.30651261 | C38: =AVERAGE(C28:EY28) -> 0.31048619 | D38: =_xlfn.PERCENTILE.EXC(C28:EY28, 0.025) -> 0.29451916 | E38: =_xlfn.PERCENTILE.EXC(C28:EY28, 0.975) -> 0.36261136 | F38: =_xlfn.PERCENTILE.EXC(C28:EY28, 0.01) -> 0.28710249 | G38: =_xlfn.PERCENTILE.EXC(C28:EY28, 0.99) -> 0.42116938 | H38: =MIN(C28:EY28) -> 0.28615287 | I38: =MAX(C28:EY28) -> 0.42389885 | J38: 46054
A39: 39 | B39: =MEDIAN(C29:EY29) -> 0.14433178 | C39: =AVERAGE(C29:EY29) -> 0.14732919 | D39: =_xlfn.PERCENTILE.EXC(C29:EY29, 0.025) -> 0.11393164 | E39: =_xlfn.PERCENTILE.EXC(C29:EY29, 0.975) -> 0.20189124 | F39: =_xlfn.PERCENTILE.EXC(C29:EY29, 0.01) -> 0.055247386 | G39: =_xlfn.PERCENTILE.EXC(C29:EY29, 0.99) -> 0.26114952 | H39: =MIN(C29:EY29) -> 0.024190325 | I39: =MAX(C29:EY29) -> 0.27674504 | J39: 46082
A40: 40 | B40: =MEDIAN(C30:EY30) -> 0.11245042 | C40: =AVERAGE(C30:EY30) -> 0.11249566 | D40: =_xlfn.PERCENTILE.EXC(C30:EY30, 0.025) -> 0.086872645 | E40: =_xlfn.PERCENTILE.EXC(C30:EY30, 0.975) -> 0.1382944 | F40: =_xlfn.PERCENTILE.EXC(C30:EY30, 0.01) -> 0.065130334 | G40: =_xlfn.PERCENTILE.EXC(C30:EY30, 0.99) -> 0.16664243 | H40: =MIN(C30:EY30) -> 0.051240632 | I40: =MAX(C30:EY30) -> 0.18497431 | J40: 46113

Sheet SC
A1: time_period | B1: real_treatment | C1: excluded_Говядина бескостная, кг | D1: excluded_Свинина (кроме бескостного мяса), кг | E1: excluded_Свинина бескостная, кг | F1: excluded_Баранина (кроме бескостного мяса), кг | G1: excluded_Куры охлажденные и мороженые, кг | H1: excluded_Окорочка куриные, кг | I1: excluded_Мясо индейки,кг | J1: excluded_Печень говяжья, свиная, кг | K1: excluded_Фарш мясной, кг | L1: excluded_Пельмени, манты, равиоли, кг | M1: excluded_Сосиски, сардельки, кг | N1: excluded_Колбаса полукопченая и варено-копченая, кг | O1: excluded_Колбаса сырокопченая, кг | P1: excluded_Колбаса вареная, кг | Q1: excluded_Кулинарные изделия из птицы, кг | R1: excluded_Консервы мясные, кг | S1: excluded_Консервы мясные для детского питания, кг | T1: excluded_Рыба живая и охлажденная, кг | U1: excluded_Рыба соленая, маринованная, копченая, кг | V1: excluded_Рыба мороженая разделанная (кроме лососевых пород), кг | W1: excluded_Рыба мороженая неразделанная, кг | X1: excluded_Филе рыбное, кг | Y1: excluded_Креветки мороженые неразделанные, кг | Z1: excluded_Кальмары мороженые,кг | AA1: excluded_Сельдь соленая, кг | AB1: excluded_Филе сельди соленое, кг | AC1: excluded_Консервы рыбные натуральные и с добавлением масла, кг | AD1: excluded_Консервы рыбные в томатном соусе, кг | AE1: excluded_Масло сливочное, кг | AF1: excluded_Масло подсолнечное, л | AG1: excluded_Масло оливковое, л | AH1: excluded_Маргарин, кг | AI1: excluded_Молоко питьевое цельное пастеризованное 2,5-3,2% жирности, л | AJ1: excluded_Молоко питьевое цельное пастеризованное более 3,2% жирности, л | AK1: excluded_Сметана, кг | AL1: excluded_Кисломолочные продукты, кг | AM1: excluded_Йогурт, кг | AN1: excluded_Сливки питьевые, л | AO1: excluded_Творог, кг | AP1: excluded_Молоко сгущенное с сахаром, кг | AQ1: excluded_Молоко для детей, л | AR1: excluded_Творожок детский, кг | AS1: excluded_Смеси сухие молочные для детского питания, кг | AT1: excluded_Национальные сыры и брынза, кг | AU1: excluded_Консервы овощные для детского питания, кг | AV1: excluded_Соки фруктовые, л | AW1: excluded_Консервы фруктово-ягодные для детского питания, кг | AX1: excluded_Соль поваренная пищевая, кг | AY1: excluded_Мука пшеничная, кг | AZ1: excluded_Хлеб из ржаной муки и из смеси муки ржаной и пшеничной, кг | BA1: excluded_Хлеб и булочные изделия из пшеничной муки различных сортов, кг | BB1: excluded_Булочные изделия сдобные из муки высшего сорта штучные, кг | BC1: excluded_Бараночные изделия, кг | BD1: excluded_Хлопья из злаков (сухие завтраки), кг | BE1: excluded_Крупа манная, кг | BF1: excluded_Горох и фасоль, кг | BG1: excluded_Крупы овсяная и перловая, кг | BH1: excluded_Овсяные хлопья "Геркулес", кг | BI1: excluded_Вермишель, кг | BJ1: excluded_Макаронные изделия из пшеничной муки высшего сорта, кг | BK1: excluded_Ягоды замороженные, кг | BL1: excluded_Мороженое сливочное, кг | BM1: excluded_Куртка для детей школьного возраста с верхом из плащевых тканей утепленная, шт. | BN1: excluded_Брюки для детей школьного возраста из полушерстяных тканей, шт. | BO1: excluded_Брюки для детей школьного возраста из джинсовой ткани, шт. | BP1: excluded_Рубашка верхняя для мальчиков школьного возраста, шт. | BQ1: excluded_Платье (платье-костюм, сарафан) для девочек школьного возраста, шт. | BR1: excluded_Блузка для девочек школьного возраста, шт. | BS1: excluded_Юбка для девочек школьного возраста, шт. | BT1: excluded_Куртка для детей дошкольного возраста с верхом из плащевых тканей утепленная, шт. | BU1: excluded_Комбинезон (костюм) утепленный для детей дошкольного возраста, шт. | BV1: excluded_Рубашка верхняя для мальчиков дошкольного возраста, шт. | BW1: excluded_Платье (сарафан) летнее для девочек дошкольного возраста, шт. | BX1: excluded_Комбинезон утепленный для детей до одного года, шт. | BY1: excluded_Пеленки для новорожденных, шт. | BZ1: excluded_Ползунки из хлопчатобумажного трикотажного полотна, шт. | CA1: excluded_Белье для новорожденных и детей ясельного возраста, шт. | CB1: excluded_Джемпер для детей школьного возраста, шт. | CC1: excluded_Костюм спортивный для детей школьного возраста, шт. | CD1: excluded_Костюм трикотажный для детей ясельного возраста, шт. | CE1: excluded_Трикотажная шапочка детская, шт. | CF1: excluded_Варежки (перчатки) детские, пара | CG1: excluded_Футболка детская, шт. | CH1: excluded_Трусы детские, шт. | CI1: excluded_Колготки детские, шт. | CJ1: excluded_Носки, гольфы детские, пара | CK1: excluded_Ботинки, полуботинки для детей школьного возраста, пара | CL1: excluded_Ботинки, полуботинки для детей дошкольного возраста, пара | CM1: excluded_Туфли детские летние (сандалеты), пара | CN1: excluded_Обувь домашняя с текстильным верхом для детей, пара | CO1: excluded_Сапоги цельнорезиновые для детей, пара | CP1: excluded_Коляска для новорожденного, шт. | CQ1: excluded_Матрас детский, шт. | CR1: excluded_Кровать для новорожденных,шт. | CS1: excluded_Тетрадь школьная, шт. | CT1: excluded_Альбом для рисования, шт. | CU1: excluded_Подгузники детские бумажные, 10 шт. | CV1: excluded_Набор фломастеров, набор | CW1: excluded_Газета в розницу, шт. | CX1: excluded_Книга художественная, шт. | CY1: excluded_Учебник, учебное пособие, дидактический материал для общеобразовательной школы, шт. | CZ1: excluded_Игрушки пластмассовые для детей ясельного возраста, шт. | DA1: excluded_Игрушки мягкие, шт. | DB1: excluded_Конструктор детский пластмассовый, набор | DC1: excluded_Корригирующие очки, шт. | DD1: excluded_Термометр медицинский электронный стандартный,шт. | DE1: excluded_Аппарат для измерения артериального давления электронный, шт. | DF1: excluded_Шприцы одноразовые, шт. | DG1: excluded_Термометр медицинский безртутный (галинстановый), шт. | DH1: excluded_Метамизол натрия, 10 таблеток | DI1: excluded_Нимесулид, 10 таблеток | DJ1: excluded_Активированный уголь, 250 мг, 10 таблеток | DK1: excluded_Нафазолин, 0,1%, 15 мл | DL1: excluded_Ренгалин, 20 таблеток | DM1: excluded_Йод, 10 мл | DN1: excluded_Левомеколь, мазь, 40 г | DO1: excluded_Мирамистин, 0,01%, 150 мл | DP1: excluded_Валерианы экстракт, 10 таблеток | DQ1: excluded_Валидол, 60 мг, 10 таблеток | DR1: excluded_Корвалол, 25 мл | DS1: excluded_Троксерутин, 2% гель, 40 г | DT1: excluded_Таурин, 4%, 5мл | DU1: excluded_Метилурацил, 10% мазь, 25 г | DV1: excluded_Бинт, шт. | DW1: excluded_Изготовление гроба, шт. | DX1: excluded_Аренда однокомнатной квартиры у частных лиц, месяц | DY1: excluded_Аренда двухкомнатной квартиры у частных лиц, месяц | DZ1: excluded_Проживание в студенческом общежитии, месяц | EA1: excluded_Посещение детского ясли-сада, день | EB1: excluded_Обучение в негосударственных общеобразовательных организациях, месяц | EC1: excluded_Дополнительные занятия в государственных и муниципальных общеобразовательных организациях очной формы обучения, академический час | ED1: excluded_Обучение в образовательных организациях среднего профессионального образования, семестр | EE1: excluded_Кинотеатры, билет | EF1: excluded_Театры, билет | EG1: excluded_Музеи и выставки, билет | EH1: excluded_Первичный консультативный прием у врача специалиста, посещение | EI1: excluded_Ультразвуковое исследование брюшной полости, исследование | EJ1: excluded_Диагностика на магнитно-резонансном или компьютерном томографе, услуга | EK1: excluded_Гастроскопия (ФГДС, ЭГДС), услуга | EL1: excluded_Физиотерапевтическое лечение, процедура | EM1: excluded_Общий анализ крови, анализ | EN1: excluded_Пребывание пациента в круглосуточном стационаре,койко день | EO1: excluded_Первичный консультативный осмотр больного у стоматолога, посещение | EP1: excluded_Удаление зуба под местным обезболиванием, удаление | EQ1: excluded_Изготовление съёмного протеза, протез | ER1: excluded_Изготовление коронки, шт. | ES1: excluded_Лечебный массаж, сеанс | ET1: excluded_Услуги сиделок, час | EU1: excluded_Плата за пользование потребительским кредитом (процентная ставка в стоимостном выражении), руб. | EV1: excluded_Годовая стоимость полиса добровольного страхования жилья от стандартных рисков, полис | EW1: excluded_Годовая стоимость полиса добровольного страхования легкового автомобиля от стандартных рисков, полис | EX1: excluded_Занятия в плавательных бассейнах, месяц | EY1: excluded_Клубная карта в фитнес-клуб, месяц
A2: 1 | B2: 0.8723376 | C2: 0.87230809 | D2: 0.87230758 | E2: 0.87230746 | F2: 0.87229584 | G2: 0.87230985 | H2: 0.8723079 | I2: 0.87232828 | J2: 0.87230877 | K2: 0.87230794 | L2: 0.87230976 | M2: 0.87230713 | N2: 0.87230583 | O2: 0.87230859 | P2: 0.87230793 | Q2: 0.87230813 | R2: 0.87230852 | S2: 0.87230872 | T2: 0.87231081 | U2: 0.87230665 | V2: 0.87230725 | W2: 0.87230657 | X2: 0.87230729 | Y2: 0.8723082 | Z2: 0.87227735 | AA2: 0.87230479 | AB2: 0.87230857 | AC2: 0.87230856 | AD2: 0.87230876 | AE2: 0.87230033 | AF2: 0.87230556 | AG2: 0.87230658 | AH2: 0.87230811 | AI2: 0.87230671 | AJ2: 0.87230926 | AK2: 0.8723059 | AL2: 0.87230787 | AM2: 0.87230886 | AN2: 0.8722893 | AO2: 0.872306 | AP2: 0.8723075 | AQ2: 0.8723097 | AR2: 0.87230649 | AS2: 0.87230707 | AT2: 0.87230754 | AU2: 0.87230893 | AV2: 0.87230805 | AW2: 0.87230753 | AX2: 0.87230619 | AY2: 0.87230785 | AZ2: 0.87230828 | BA2: 0.87230975 | BB2: 0.87230714 | BC2: 0.87230825 | BD2: 0.87231237 | BE2: 0.87229802 | BF2: 0.87230546 | BG2: 0.87228754 | BH2: 0.8723076 | BI2: 0.87230832 | BJ2: 0.87230766 | BK2: 0.87230696 | BL2: 0.87230878 | BM2: 0.87230564 | BN2: 0.87230902 | BO2: 0.87231325 | BP2: 0.87230963 | BQ2: 0.87230873 | BR2: 0.87231069 | BS2: 0.87230935 | BT2: 0.87230884 | BU2: 0.8723059 | BV2: 0.87230881 | BW2: 0.87230863 | BX2: 0.8723052 | BY2: 0.87230804 | BZ2: 0.8723082 | CA2: 0.87230725 | CB2: 0.87230728 | CC2: 0.87230892 | CD2: 0.87229046 | CE2: 0.87230993 | CF2: 0.87230826 | CG2: 0.87230814 | CH2: 0.87230626 | CI2: 0.87230843 | CJ2: 0.87230754 | CK2: 0.87230771 | CL2: 0.87230617 | CM2: 0.87230409 | CN2: 0.8723132 | CO2: 0.87230542 | CP2: 0.87228468 | CQ2: 0.87230808 | CR2: 0.87230859 | CS2: 0.87230723 | CT2: 0.87230822 | CU2: 0.87228194 | CV2: 0.87230813 | CW2: 0.87230685 | CX2: 0.87224582 | CY2: 0.8723092 | CZ2: 0.87230891 | DA2: 0.87232209 | DB2: 0.87230742 | DC2: 0.87231066 | DD2: 0.87231406 | DE2: 0.87230933 | DF2: 0.87230715 | DG2: 0.87232067 | DH2: 0.87230704 | DI2: 0.87231533 | DJ2: 0.87230899 | DK2: 0.87230971 | DL2: 0.87230681 | DM2: 0.87230911 | DN2: 0.87230692 | DO2: 0.8723098 | DP2: 0.87230762 | DQ2: 0.8723079 | DR2: 0.87230771 | DS2: 0.87230487 | DT2: 0.87230765 | DU2: 0.87230937 | DV2: 0.8723081 | DW2: 0.87230918 | DX2: 0.87231019 | DY2: 0.87230765 | DZ2: 0.87230645 | EA2: 0.87230625 | EB2: 0.87230733 | EC2: 0.87230811 | ED2: 0.87230753 | EE2: 0.87231144 | EF2: 0.8723072 | EG2: 0.87230774 | EH2: 0.87230902 | EI2: 0.87230905 | EJ2: 0.87230893 | EK2: 0.87230847 | EL2: 0.87230829 | EM2: 0.8723088 | EN2: 0.87230925 | EO2: 0.87230878 | EP2: 0.87230883 | EQ2: 0.8723062 | ER2: 0.87230793 | ES2: 0.87230775 | ET2: 0.87230861 | EU2: 0.87229748 | EV2: 0.87230884 | EW2: 0.87230887 | EX2: 0.87230862 | EY2: 0.87230876
A3: 2 | B3: 0.8710011 | C3: 0.87108266 | D3: 0.87108359 | E3: 0.87108438 | F3: 0.87108257 | G3: 0.8710843 | H3: 0.87107798 | I3: 0.8710672 | J3: 0.871083 | K3: 0.87108451 | L3: 0.87108121 | M3: 0.87108337 | N3: 0.87108369 | O3: 0.87108142 | P3: 0.87108196 | Q3: 0.87108302 | R3: 0.87108011 | S3: 0.87107967 | T3: 0.87107593 | U3: 0.87108144 | V3: 0.87108345 | W3: 0.87108232 | X3: 0.87108294 | Y3: 0.8710814 | Z3: 0.87110753 | AA3: 0.87108594 | AB3: 0.87108171 | AC3: 0.87109042 | AD3: 0.87108175 | AE3: 0.87109509 | AF3: 0.8710903 | AG3: 0.87108386 | AH3: 0.87108271 | AI3: 0.87108439 | AJ3: 0.87108592 | AK3: 0.87108118 | AL3: 0.87108371 | AM3: 0.87108114 | AN3: 0.87111872 | AO3: 0.87108374 | AP3: 0.87108476 | AQ3: 0.87107934 | AR3: 0.87108401 | AS3: 0.87107932 | AT3: 0.87108408 | AU3: 0.87108139 | AV3: 0.8710846 | AW3: 0.87108243 | AX3: 0.87108267 | AY3: 0.87108681 | AZ3: 0.87108222 | BA3: 0.87108412 | BB3: 0.87108359 | BC3: 0.87108534 | BD3: 0.87106762 | BE3: 0.87108282 | BF3: 0.87108448 | BG3: 0.87110345 | BH3: 0.87108245 | BI3: 0.87108418 | BJ3: 0.87108159 | BK3: 0.87108209 | BL3: 0.8710833 | BM3: 0.87108355 | BN3: 0.87108198 | BO3: 0.87107207 | BP3: 0.87108053 | BQ3: 0.87107999 | BR3: 0.87108063 | BS3: 0.87107966 | BT3: 0.8710816 | BU3: 0.87108435 | BV3: 0.87108147 | BW3: 0.8710798 | BX3: 0.87108776 | BY3: 0.87108101 | BZ3: 0.87108203 | CA3: 0.87108114 | CB3: 0.87108249 | CC3: 0.87108258 | CD3: 0.87111441 | CE3: 0.87107943 | CF3: 0.87107742 | CG3: 0.87108181 | CH3: 0.87108115 | CI3: 0.87108209 | CJ3: 0.87108173 | CK3: 0.87108282 | CL3: 0.87108191 | CM3: 0.87111668 | CN3: 0.87108183 | CO3: 0.87108452 | CP3: 0.87110384 | CQ3: 0.87108313 | CR3: 0.87108359 | CS3: 0.87108329 | CT3: 0.87108347 | CU3: 0.87113278 | CV3: 0.87108149 | CW3: 0.87108219 | CX3: 0.87119495 | CY3: 0.87108114 | CZ3: 0.87107991 | DA3: 0.87106959 | DB3: 0.87108417 | DC3: 0.87107954 | DD3: 0.87107429 | DE3: 0.87108207 | DF3: 0.87108286 | DG3: 0.87106927 | DH3: 0.8710831 | DI3: 0.8710866 | DJ3: 0.87108243 | DK3: 0.8710818 | DL3: 0.87108236 | DM3: 0.87107989 | DN3: 0.87107493 | DO3: 0.87107929 | DP3: 0.87108247 | DQ3: 0.87108147 | DR3: 0.87107959 | DS3: 0.87108449 | DT3: 0.87108288 | DU3: 0.87108372 | DV3: 0.87107926 | DW3: 0.87108261 | DX3: 0.87107961 | DY3: 0.87108403 | DZ3: 0.87108083 | EA3: 0.87108247 | EB3: 0.87108498 | EC3: 0.87107922 | ED3: 0.87107903 | EE3: 0.87108921 | EF3: 0.87108257 | EG3: 0.87108253 | EH3: 0.87108282 | EI3: 0.87108108 | EJ3: 0.87108069 | EK3: 0.87108206 | EL3: 0.87108263 | EM3: 0.87108166 | EN3: 0.87108292 | EO3: 0.87108065 | EP3: 0.87108212 | EQ3: 0.87108602 | ER3: 0.87108333 | ES3: 0.8710792 | ET3: 0.87108006 | EU3: 0.87109937 | EV3: 0.87107976 | EW3: 0.87107689 | EX3: 0.87108062 | EY3: 0.87108232
A4: 3 | B4: 0.87166895 | C4: 0.87173172 | D4: 0.87173593 | E4: 0.87172881 | F4: 0.87173433 | G4: 0.87173016 | H4: 0.87173607 | I4: 0.871689 | J4: 0.87172949 | K4: 0.87172823 | L4: 0.87172935 | M4: 0.87173203 | N4: 0.87173356 | O4: 0.87173253 | P4: 0.87173179 | Q4: 0.87172985 | R4: 0.87173258 | S4: 0.87173337 | T4: 0.87173705 | U4: 0.87173137 | V4: 0.87173282 | W4: 0.87173238 | X4: 0.87173186 | Y4: 0.87173214 | Z4: 0.8717447 | AA4: 0.87173539 | AB4: 0.87173287 | AC4: 0.8717327 | AD4: 0.87172695 | AE4: 0.87173114 | AF4: 0.87173117 | AG4: 0.87173159 | AH4: 0.87173289 | AI4: 0.87173149 | AJ4: 0.87172495 | AK4: 0.87173209 | AL4: 0.87173137 | AM4: 0.87173882 | AN4: 0.87177299 | AO4: 0.87173291 | AP4: 0.87172771 | AQ4: 0.87173286 | AR4: 0.871733 | AS4: 0.87172834 | AT4: 0.87173738 | AU4: 0.87173084 | AV4: 0.8717345 | AW4: 0.87173498 | AX4: 0.87173521 | AY4: 0.87172585 | AZ4: 0.87173192 | BA4: 0.87173231 | BB4: 0.87173343 | BC4: 0.8717321 | BD4: 0.87174738 | BE4: 0.8717373 | BF4: 0.87173339 | BG4: 0.87174642 | BH4: 0.87173168 | BI4: 0.87172993 | BJ4: 0.8717328 | BK4: 0.87173503 | BL4: 0.87173211 | BM4: 0.87173621 | BN4: 0.8717308 | BO4: 0.87173136 | BP4: 0.87173068 | BQ4: 0.87173161 | BR4: 0.87170715 | BS4: 0.8717307 | BT4: 0.87173166 | BU4: 0.87173251 | BV4: 0.8717305 | BW4: 0.87173261 | BX4: 0.87173394 | BY4: 0.87173424 | BZ4: 0.87173188 | CA4: 0.87173282 | CB4: 0.8717353 | CC4: 0.87172793 | CD4: 0.87171768 | CE4: 0.87173057 | CF4: 0.87173599 | CG4: 0.87173169 | CH4: 0.87173823 | CI4: 0.87173115 | CJ4: 0.87173075 | CK4: 0.87173442 | CL4: 0.87173425 | CM4: 0.87171701 | CN4: 0.87171837 | CO4: 0.87173347 | CP4: 0.87173552 | CQ4: 0.87173449 | CR4: 0.87172963 | CS4: 0.8717309 | CT4: 0.8717305 | CU4: 0.87172734 | CV4: 0.8717318 | CW4: 0.87173311 | CX4: 0.87172771 | CY4: 0.87173165 | CZ4: 0.87173448 | DA4: 0.87172395 | DB4: 0.8717322 | DC4: 0.87173302 | DD4: 0.87172802 | DE4: 0.87173265 | DF4: 0.87173408 | DG4: 0.87166546 | DH4: 0.87173172 | DI4: 0.87170805 | DJ4: 0.87172838 | DK4: 0.87172837 | DL4: 0.87173434 | DM4: 0.87173318 | DN4: 0.871733 | DO4: 0.87173171 | DP4: 0.87173137 | DQ4: 0.87173266 | DR4: 0.87173117 | DS4: 0.87172875 | DT4: 0.87173202 | DU4: 0.8717261 | DV4: 0.87173153 | DW4: 0.87173017 | DX4: 0.87172998 | DY4: 0.87172974 | DZ4: 0.87173096 | EA4: 0.87173278 | EB4: 0.87173265 | EC4: 0.87172567 | ED4: 0.87173008 | EE4: 0.87173285 | EF4: 0.8717294 | EG4: 0.87173139 | EH4: 0.8717308 | EI4: 0.87173012 | EJ4: 0.87173239 | EK4: 0.8717319 | EL4: 0.87173024 | EM4: 0.87173121 | EN4: 0.87172887 | EO4: 0.87173107 | EP4: 0.87173009 | EQ4: 0.87173618 | ER4: 0.87173227 | ES4: 0.87173829 | ET4: 0.87173222 | EU4: 0.87172845 | EV4: 0.87173129 | EW4: 0.87173096 | EX4: 0.87173212 | EY4: 0.87173074
A5: 4 | B5: 0.87252008 | C5: 0.87227116 | D5: 0.8722548 | E5: 0.87226977 | F5: 0.87231659 | G5: 0.87225838 | H5: 0.87226776 | I5: 0.8723093 | J5: 0.87226402 | K5: 0.87226256 | L5: 0.8722671 | M5: 0.8722629 | N5: 0.87226461 | O5: 0.87226743 | P5: 0.87226622 | Q5: 0.87226481 | R5: 0.87226477 | S5: 0.8722704 | T5: 0.87226134 | U5: 0.87226903 | V5: 0.87226665 | W5: 0.87226691 | X5: 0.87226282 | Y5: 0.87226624 | Z5: 0.87227761 | AA5: 0.87226287 | AB5: 0.87226471 | AC5: 0.87226269 | AD5: 0.87227297 | AE5: 0.87225291 | AF5: 0.87226048 | AG5: 0.87226494 | AH5: 0.87226718 | AI5: 0.8722634 | AJ5: 0.87226184 | AK5: 0.8722609 | AL5: 0.87226361 | AM5: 0.87225777 | AN5: 0.87220748 | AO5: 0.87226249 | AP5: 0.8722654 | AQ5: 0.87226548 | AR5: 0.87226318 | AS5: 0.87226624 | AT5: 0.87228228 | AU5: 0.87226434 | AV5: 0.87228555 | AW5: 0.87226545 | AX5: 0.87226628 | AY5: 0.87225822 | AZ5: 0.8722643 | BA5: 0.87226352 | BB5: 0.87226269 | BC5: 0.87226398 | BD5: 0.87226358 | BE5: 0.87227304 | BF5: 0.87226359 | BG5: 0.87224466 | BH5: 0.87226132 | BI5: 0.87226446 | BJ5: 0.87226709 | BK5: 0.87226398 | BL5: 0.8722643 | BM5: 0.87226611 | BN5: 0.87227151 | BO5: 0.8722803 | BP5: 0.87226696 | BQ5: 0.87226679 | BR5: 0.8722889 | BS5: 0.8722744 | BT5: 0.87226265 | BU5: 0.87226634 | BV5: 0.87226557 | BW5: 0.87226517 | BX5: 0.87225349 | BY5: 0.87226857 | BZ5: 0.87226451 | CA5: 0.87226809 | CB5: 0.8722609 | CC5: 0.87226724 | CD5: 0.87227716 | CE5: 0.87227036 | CF5: 0.87226394 | CG5: 0.87226591 | CH5: 0.87226014 | CI5: 0.87226666 | CJ5: 0.87226882 | CK5: 0.87226539 | CL5: 0.87226786 | CM5: 0.87226927 | CN5: 0.87226669 | CO5: 0.87225288 | CP5: 0.87228454 | CQ5: 0.87226274 | CR5: 0.87226251 | CS5: 0.87226567 | CT5: 0.87227306 | CU5: 0.87221104 | CV5: 0.87226666 | CW5: 0.87226621 | CX5: 0.87217421 | CY5: 0.87226523 | CZ5: 0.8722707 | DA5: 0.87227087 | DB5: 0.8722617 | DC5: 0.87226311 | DD5: 0.87227536 | DE5: 0.87226627 | DF5: 0.87226091 | DG5: 0.8722775 | DH5: 0.87226535 | DI5: 0.87227569 | DJ5: 0.87226915 | DK5: 0.87226563 | DL5: 0.87226824 | DM5: 0.87226479 | DN5: 0.87227149 | DO5: 0.87226961 | DP5: 0.87226794 | DQ5: 0.87226626 | DR5: 0.8722647 | DS5: 0.87227559 | DT5: 0.87226817 | DU5: 0.87226693 | DV5: 0.87227547 | DW5: 0.87226093 | DX5: 0.87226753 | DY5: 0.8722645 | DZ5: 0.87226492 | EA5: 0.8722628 | EB5: 0.87225904 | EC5: 0.87228254 | ED5: 0.87226802 | EE5: 0.87226725 | EF5: 0.87226424 | EG5: 0.87226941 | EH5: 0.87226267 | EI5: 0.87226737 | EJ5: 0.87227195 | EK5: 0.87226436 | EL5: 0.87226619 | EM5: 0.87226455 | EN5: 0.87226698 | EO5: 0.8722665 | EP5: 0.87226735 | EQ5: 0.87224892 | ER5: 0.87226339 | ES5: 0.87226617 | ET5: 0.8722663 | EU5: 0.8722628 | EV5: 0.8722657 | EW5: 0.8722603 | EX5: 0.87227837 | EY5: 0.87226557
A6: 5 | B6: 0.87286487 | C6: 0.87291989 | D6: 0.87291501 | E6: 0.87291454 | F6: 0.87287452 | G6: 0.87292427 | H6: 0.8729139 | I6: 0.87283764 | J6: 0.87291573 | K6: 0.87291561 | L6: 0.87291678 | M6: 0.87291536 | N6: 0.87291601 | O6: 0.87291885 | P6: 0.87291523 | Q6: 0.87291488 | R6: 0.87291458 | S6: 0.87291962 | T6: 0.87291637 | U6: 0.87291512 | V6: 0.87291851 | W6: 0.87292035 | X6: 0.87291781 | Y6: 0.87292126 | Z6: 0.87287583 | AA6: 0.87291956 | AB6: 0.8729227 | AC6: 0.8729195 | AD6: 0.87292417 | AE6: 0.87292615 | AF6: 0.87292735 | AG6: 0.87291622 | AH6: 0.87292077 | AI6: 0.87292308 | AJ6: 0.87291865 | AK6: 0.87292096 | AL6: 0.87292171 | AM6: 0.87292797 | AN6: 0.87289759 | AO6: 0.87291998 | AP6: 0.87291765 | AQ6: 0.87291707 | AR6: 0.87291682 | AS6: 0.87291778 | AT6: 0.87292123 | AU6: 0.87291604 | AV6: 0.87291863 | AW6: 0.8729198 | AX6: 0.8729226 | AY6: 0.87292064 | AZ6: 0.872918 | BA6: 0.87291989 | BB6: 0.87291977 | BC6: 0.87291822 | BD6: 0.87292112 | BE6: 0.87292664 | BF6: 0.87291844 | BG6: 0.87287231 | BH6: 0.8729176 | BI6: 0.87291701 | BJ6: 0.87291926 | BK6: 0.87291769 | BL6: 0.8729185 | BM6: 0.87292226 | BN6: 0.87291503 | BO6: 0.87291103 | BP6: 0.8729124 | BQ6: 0.87291222 | BR6: 0.87291552 | BS6: 0.87290959 | BT6: 0.87292252 | BU6: 0.87291829 | BV6: 0.87291589 | BW6: 0.87291486 | BX6: 0.87291938 | BY6: 0.87291561 | BZ6: 0.87291826 | CA6: 0.87291233 | CB6: 0.87291423 | CC6: 0.87291087 | CD6: 0.872904 | CE6: 0.87291613 | CF6: 0.87291893 | CG6: 0.87291681 | CH6: 0.8729188 | CI6: 0.87291532 | CJ6: 0.87291568 | CK6: 0.87291794 | CL6: 0.8729177 | CM6: 0.87283008 | CN6: 0.87291576 | CO6: 0.87291992 | CP6: 0.87289871 | CQ6: 0.87292105 | CR6: 0.87291407 | CS6: 0.87291534 | CT6: 0.87291739 | CU6: 0.87292296 | CV6: 0.87291602 | CW6: 0.87291485 | CX6: 0.87295426 | CY6: 0.872917 | CZ6: 0.87291782 | DA6: 0.87289757 | DB6: 0.87291714 | DC6: 0.8729176 | DD6: 0.87290922 | DE6: 0.87291896 | DF6: 0.87291829 | DG6: 0.87299927 | DH6: 0.87291611 | DI6: 0.87289492 | DJ6: 0.87291345 | DK6: 0.87291342 | DL6: 0.87291948 | DM6: 0.87291684 | DN6: 0.87291271 | DO6: 0.87291527 | DP6: 0.87291419 | DQ6: 0.87291547 | DR6: 0.87291898 | DS6: 0.87291129 | DT6: 0.87291638 | DU6: 0.87291333 | DV6: 0.87291458 | DW6: 0.87291672 | DX6: 0.87291352 | DY6: 0.87291776 | DZ6: 0.87291532 | EA6: 0.87291507 | EB6: 0.87291559 | EC6: 0.87290603 | ED6: 0.87291694 | EE6: 0.87291725 | EF6: 0.87291562 | EG6: 0.8729173 | EH6: 0.87291548 | EI6: 0.8729139 | EJ6: 0.87291706 | EK6: 0.87291674 | EL6: 0.87291534 | EM6: 0.87291614 | EN6: 0.8729136 | EO6: 0.872915 | EP6: 0.87291505 | EQ6: 0.87292446 | ER6: 0.87291351 | ES6: 0.87291922 | ET6: 0.87291503 | EU6: 0.87289235 | EV6: 0.87291431 | EW6: 0.87290933 | EX6: 0.87291695 | EY6: 0.87291475
A7: 6 | B7: 0.8731306 | C7: 0.87348935 | D7: 0.87346492 | E7: 0.87348955 | F7: 0.87350643 | G7: 0.87347782 | H7: 0.87348373 | I7: 0.87362288 | J7: 0.87349273 | K7: 0.87348892 | L7: 0.87348228 | M7: 0.87346923 | N7: 0.87348026 | O7: 0.87348396 | P7: 0.87348208 | Q7: 0.87348883 | R7: 0.87348006 | S7: 0.87348072 | T7: 0.87348417 | U7: 0.87347529 | V7: 0.87348073 | W7: 0.87347396 | X7: 0.87348668 | Y7: 0.8734735 | Z7: 0.87353587 | AA7: 0.87347919 | AB7: 0.87347755 | AC7: 0.87349432 | AD7: 0.87349063 | AE7: 0.87348918 | AF7: 0.87346834 | AG7: 0.87348063 | AH7: 0.87347848 | AI7: 0.87348339 | AJ7: 0.87348911 | AK7: 0.8734766 | AL7: 0.87347648 | AM7: 0.87349291 | AN7: 0.87352288 | AO7: 0.87348285 | AP7: 0.87348945 | AQ7: 0.87348225 | AR7: 0.87348046 | AS7: 0.87348469 | AT7: 0.8734903 | AU7: 0.87348035 | AV7: 0.87349406 | AW7: 0.87347251 | AX7: 0.87348737 | AY7: 0.87347934 | AZ7: 0.87348566 | BA7: 0.87348625 | BB7: 0.87348246 | BC7: 0.87348028 | BD7: 0.8734683 | BE7: 0.87346901 | BF7: 0.8734783 | BG7: 0.87355461 | BH7: 0.87348778 | BI7: 0.87348339 | BJ7: 0.8734784 | BK7: 0.87346252 | BL7: 0.87348292 | BM7: 0.87347274 | BN7: 0.87348406 | BO7: 0.87348172 | BP7: 0.87347538 | BQ7: 0.87348374 | BR7: 0.87352905 | BS7: 0.8734759 | BT7: 0.87347864 | BU7: 0.87347739 | BV7: 0.87348578 | BW7: 0.87347917 | BX7: 0.87348888 | BY7: 0.8734755 | BZ7: 0.87348626 | CA7: 0.87347945 | CB7: 0.87348227 | CC7: 0.87348968 | CD7: 0.87347355 | CE7: 0.87348278 | CF7: 0.87346957 | CG7: 0.87348194 | CH7: 0.87348951 | CI7: 0.87347892 | CJ7: 0.87347753 | CK7: 0.87348241 | CL7: 0.87349641 | CM7: 0.87354608 | CN7: 0.87348034 | CO7: 0.87347751 | CP7: 0.87353267 | CQ7: 0.87348502 | CR7: 0.87346846 | CS7: 0.87348267 | CT7: 0.87348865 | CU7: 0.87357654 | CV7: 0.87348208 | CW7: 0.87348174 | CX7: 0.87351281 | CY7: 0.87348519 | CZ7: 0.87348537 | DA7: 0.87347776 | DB7: 0.8734829 | DC7: 0.87347598 | DD7: 0.87348202 | DE7: 0.87348032 | DF7: 0.87346975 | DG7: 0.87350192 | DH7: 0.87348321 | DI7: 0.8735181 | DJ7: 0.8734838 | DK7: 0.8734892 | DL7: 0.87348592 | DM7: 0.87348257 | DN7: 0.87347865 | DO7: 0.87348676 | DP7: 0.87348279 | DQ7: 0.87348284 | DR7: 0.87347774 | DS7: 0.87347879 | DT7: 0.87347952 | DU7: 0.8734899 | DV7: 0.87348399 | DW7: 0.87348326 | DX7: 0.87348325 | DY7: 0.87349065 | DZ7: 0.87347715 | EA7: 0.87348529 | EB7: 0.87350094 | EC7: 0.87348468 | ED7: 0.87346773 | EE7: 0.87347352 | EF7: 0.87347916 | EG7: 0.87348213 | EH7: 0.87349163 | EI7: 0.87348844 | EJ7: 0.87348712 | EK7: 0.87348725 | EL7: 0.87347883 | EM7: 0.87348409 | EN7: 0.87349094 | EO7: 0.87347946 | EP7: 0.87348983 | EQ7: 0.87349075 | ER7: 0.87346635 | ES7: 0.87346655 | ET7: 0.87348803 | EU7: 0.87353115 | EV7: 0.87347761 | EW7: 0.87348293 | EX7: 0.87347698 | EY7: 0.87347823
A8: 7 | B8: 0.87651773 | C8: 0.87631527 | D8: 0.87631201 | E8: 0.87631471 | F8: 0.87628099 | G8: 0.87631684 | H8: 0.8763108 | I8: 0.87622862 | J8: 0.87631253 | K8: 0.87630936 | L8: 0.8763155 | M8: 0.87631178 | N8: 0.87631525 | O8: 0.87631356 | P8: 0.87630972 | Q8: 0.87631354 | R8: 0.87631552 | S8: 0.87631569 | T8: 0.87630915 | U8: 0.87631438 | V8: 0.87631503 | W8: 0.87631533 | X8: 0.87631768 | Y8: 0.87631477 | Z8: 0.87627747 | AA8: 0.87631881 | AB8: 0.87631718 | AC8: 0.87631681 | AD8: 0.87632607 | AE8: 0.87630904 | AF8: 0.87632408 | AG8: 0.87632666 | AH8: 0.87631546 | AI8: 0.87632037 | AJ8: 0.87631687 | AK8: 0.87631504 | AL8: 0.87631839 | AM8: 0.87631022 | AN8: 0.87625294 | AO8: 0.87631759 | AP8: 0.87631117 | AQ8: 0.87631789 | AR8: 0.87631479 | AS8: 0.87631257 | AT8: 0.87631785 | AU8: 0.87631407 | AV8: 0.87631432 | AW8: 0.87631651 | AX8: 0.87631692 | AY8: 0.87631973 | AZ8: 0.87632351 | BA8: 0.87632571 | BB8: 0.87631603 | BC8: 0.87631626 | BD8: 0.87630093 | BE8: 0.87631285 | BF8: 0.87632326 | BG8: 0.87628935 | BH8: 0.87631928 | BI8: 0.87631959 | BJ8: 0.87632308 | BK8: 0.87631213 | BL8: 0.87631807 | BM8: 0.87631613 | BN8: 0.8763153 | BO8: 0.87632628 | BP8: 0.87631543 | BQ8: 0.87631963 | BR8: 0.87625108 | BS8: 0.87632101 | BT8: 0.87633099 | BU8: 0.87631717 | BV8: 0.87631612 | BW8: 0.87632274 | BX8: 0.87631814 | BY8: 0.87631759 | BZ8: 0.87632147 | CA8: 0.87631718 | CB8: 0.87633609 | CC8: 0.87631491 | CD8: 0.87629565 | CE8: 0.87630797 | CF8: 0.87631797 | CG8: 0.87631769 | CH8: 0.87631205 | CI8: 0.87631827 | CJ8: 0.87631569 | CK8: 0.87631661 | CL8: 0.8763239 | CM8: 0.87634343 | CN8: 0.87631178 | CO8: 0.87631871 | CP8: 0.87625148 | CQ8: 0.87631742 | CR8: 0.87630495 | CS8: 0.87631669 | CT8: 0.87631416 | CU8: 0.87626579 | CV8: 0.8763175 | CW8: 0.87631633 | CX8: 0.87625646 | CY8: 0.8763148 | CZ8: 0.87631643 | DA8: 0.87628736 | DB8: 0.87631451 | DC8: 0.87631242 | DD8: 0.87633077 | DE8: 0.87631693 | DF8: 0.87631258 | DG8: 0.87627951 | DH8: 0.87631732 | DI8: 0.87632038 | DJ8: 0.8763125 | DK8: 0.87631578 | DL8: 0.87631989 | DM8: 0.87631494 | DN8: 0.8763185 | DO8: 0.87631808 | DP8: 0.87631639 | DQ8: 0.87631575 | DR8: 0.87631179 | DS8: 0.87631331 | DT8: 0.87631941 | DU8: 0.87631086 | DV8: 0.87631284 | DW8: 0.87631077 | DX8: 0.87631564 | DY8: 0.87631714 | DZ8: 0.87633553 | EA8: 0.87631328 | EB8: 0.87631115 | EC8: 0.87630396 | ED8: 0.8763208 | EE8: 0.87632805 | EF8: 0.87631705 | EG8: 0.87631408 | EH8: 0.87631416 | EI8: 0.87631541 | EJ8: 0.87631414 | EK8: 0.87631427 | EL8: 0.87631396 | EM8: 0.87631391 | EN8: 0.87631626 | EO8: 0.87631469 | EP8: 0.87631531 | EQ8: 0.87631552 | ER8: 0.87631033 | ES8: 0.87631738 | ET8: 0.87631562 | EU8: 0.87629345 | EV8: 0.8763145 | EW8: 0.87631696 | EX8: 0.87631449 | EY8: 0.87631305
